Workbook

Sheet Results
B1: Relative quantification of total fatty acids profil
B4: Matrix: | C4: Fluid
B5: Normalize: | C5: Volume
B7: ='Raw Datas'!A53 -> Relative abundance/µL of fluid | C7: ='Raw Datas'!C1 -> JV-015-RAN-IC-M2 | D7: ='Raw Datas'!D1 -> BS-007-RAN-01-M3 | E7: ='Raw Datas'!E1 -> BS-007-RAN-02-M3 | F7: ='Raw Datas'!F1 -> KT-004-SOC-16-M1 | G7: ='Raw Datas'!G1 -> BS-135-RAN-IC-M3 | H7: ='Raw Datas'!H1 -> JV-070-DAV-07-M3 | I7: ='Raw Datas'!I1 -> BS-129-RAT-10-M5 | J7: ='Raw Datas'!J1 -> JV-036-SOC-10-M2 | ... V7: ='Raw Datas'!V1 -> BS-172-RAT-10-M3
A9: SAFA | B9: L_C8_0 | C9: ='Raw Datas'!C55 -> 0 | D9: ='Raw Datas'!D55 -> 0 | E9: ='Raw Datas'!E55 -> 0 | F9: ='Raw Datas'!F55 -> 0 | G9: ='Raw Datas'!G55 -> 0 | H9: ='Raw Datas'!H55 -> 0 | I9: ='Raw Datas'!I55 -> 0 | J9: ='Raw Datas'!J55 -> 0 | ... V9: ='Raw Datas'!V55 -> 0
B10: L_C10_0 | C10: ='Raw Datas'!C56 -> 0 | D10: ='Raw Datas'!D56 -> 0 | E10: ='Raw Datas'!E56 -> 0 | F10: ='Raw Datas'!F56 -> 0 | G10: ='Raw Datas'!G56 -> 0 | H10: ='Raw Datas'!H56 -> 0 | I10: ='Raw Datas'!I56 -> 0 | J10: ='Raw Datas'!J56 -> 0 | ... V10: ='Raw Datas'!V56 -> 0
B11: L_C11_0 | C11: ='Raw Datas'!C57 -> 0 | D11: ='Raw Datas'!D57 -> 0 | E11: ='Raw Datas'!E57 -> 0 | F11: ='Raw Datas'!F57 -> 0 | G11: ='Raw Datas'!G57 -> 0 | H11: ='Raw Datas'!H57 -> 0 | I11: ='Raw Datas'!I57 -> 0 | J11: ='Raw Datas'!J57 -> 0 | ... V11: ='Raw Datas'!V57 -> 0
B12: L_C12_0 | C12: ='Raw Datas'!C58 -> 0 | D12: ='Raw Datas'!D58 -> 0 | E12: ='Raw Datas'!E58 -> 0 | F12: ='Raw Datas'!F58 -> 0 | G12: ='Raw Datas'!G58 -> 0 | H12: ='Raw Datas'!H58 -> 0 | I12: ='Raw Datas'!I58 -> 0 | J12: ='Raw Datas'!J58 -> 0 | ... V12: ='Raw Datas'!V58 -> 0
B13: L_C13_0 | C13: ='Raw Datas'!C59 -> 0 | D13: ='Raw Datas'!D59 -> 0 | E13: ='Raw Datas'!E59 -> 0 | F13: ='Raw Datas'!F59 -> 0 | G13: ='Raw Datas'!G59 -> 0 | H13: ='Raw Datas'!H59 -> 0 | I13: ='Raw Datas'!I59 -> 0 | J13: ='Raw Datas'!J59 -> 0 | ... V13: ='Raw Datas'!V59 -> 0
B14: L_C14_0 | C14: ='Raw Datas'!C60 -> 0 | D14: ='Raw Datas'!D60 -> 0 | E14: ='Raw Datas'!E60 -> 0 | F14: ='Raw Datas'!F60 -> 0 | G14: ='Raw Datas'!G60 -> 0 | H14: ='Raw Datas'!H60 -> 0 | I14: ='Raw Datas'!I60 -> 0 | J14: ='Raw Datas'!J60 -> 0 | ... V14: ='Raw Datas'!V60 -> 0
B15: L_C15_0 | C15: ='Raw Datas'!C61 -> 0 | D15: ='Raw Datas'!D61 -> 0 | E15: ='Raw Datas'!E61 -> 0 | F15: ='Raw Datas'!F61 -> 0 | G15: ='Raw Datas'!G61 -> 0 | H15: ='Raw Datas'!H61 -> 0 | I15: ='Raw Datas'!I61 -> 0 | J15: ='Raw Datas'!J61 -> 0 | ... V15: ='Raw Datas'!V61 -> 0
B16: L_C16_0 | C16: ='Raw Datas'!C62 -> 1.0224435 | D16: ='Raw Datas'!D62 -> 1.7818262 | E16: ='Raw Datas'!E62 -> 1.3584524 | F16: ='Raw Datas'!F62 -> 0.92480912 | G16: ='Raw Datas'!G62 -> 1.4075237 | H16: ='Raw Datas'!H62 -> 1.2741509 | I16: ='Raw Datas'!I62 -> 0.93472467 | J16: ='Raw Datas'!J62 -> 1.0449621 | ... V16: ='Raw Datas'!V62 -> 1.4611696
B17: L_C18_0 | C17: ='Raw Datas'!C64 -> 0.48084558 | D17: ='Raw Datas'!D64 -> 0.35913831 | E17: ='Raw Datas'!E64 -> 0.59508403 | F17: ='Raw Datas'!F64 -> 0.48738895 | G17: ='Raw Datas'!G64 -> 0.53519076 | H17: ='Raw Datas'!H64 -> 0.5110065 | I17: ='Raw Datas'!I64 -> 0.42405702 | J17: ='Raw Datas'!J64 -> 0.3644264 | ... V17: ='Raw Datas'!V64 -> 0.531345
B18: L_C20_0 | C18: ='Raw Datas'!C65 -> 0 | D18: ='Raw Datas'!D65 -> 0 | E18: ='Raw Datas'!E65 -> 0 | F18: ='Raw Datas'!F65 -> 0 | G18: ='Raw Datas'!G65 -> 0 | H18: ='Raw Datas'!H65 -> 0 | I18: ='Raw Datas'!I65 -> 0 | J18: ='Raw Datas'!J65 -> 0 | ... V18: ='Raw Datas'!V65 -> 0
B19: L_C21_0 | C19: ='Raw Datas'!C66 -> 0 | D19: ='Raw Datas'!D66 -> 0 | E19: ='Raw Datas'!E66 -> 0 | F19: ='Raw Datas'!F66 -> 0 | G19: ='Raw Datas'!G66 -> 0 | H19: ='Raw Datas'!H66 -> 0 | I19: ='Raw Datas'!I66 -> 0 | J19: ='Raw Datas'!J66 -> 0 | ... V19: ='Raw Datas'!V66 -> 0
B20: L_C22_0 | C20: ='Raw Datas'!C67 -> 0 | D20: ='Raw Datas'!D67 -> 0 | E20: ='Raw Datas'!E67 -> 0 | F20: ='Raw Datas'!F67 -> 0 | G20: ='Raw Datas'!G67 -> 0 | H20: ='Raw Datas'!H67 -> 0 | I20: ='Raw Datas'!I67 -> 0 | J20: ='Raw Datas'!J67 -> 0 | ... V20: ='Raw Datas'!V67 -> 0
B21: L_C23_0 | C21: ='Raw Datas'!C68 -> 0 | D21: ='Raw Datas'!D68 -> 0 | E21: ='Raw Datas'!E68 -> 0 | F21: ='Raw Datas'!F68 -> 0 | G21: ='Raw Datas'!G68 -> 0 | H21: ='Raw Datas'!H68 -> 0 | I21: ='Raw Datas'!I68 -> 0 | J21: ='Raw Datas'!J68 -> 0 | ... V21: ='Raw Datas'!V68 -> 0
B22: L_C24_0 | C22: ='Raw Datas'!C69 -> 0.075739336 | D22: ='Raw Datas'!D69 -> 0.051609879 | E22: ='Raw Datas'!E69 -> 0.068083452 | F22: ='Raw Datas'!F69 -> 0.075508868 | G22: ='Raw Datas'!G69 -> 0.068129785 | H22: ='Raw Datas'!H69 -> 0.084061044 | I22: ='Raw Datas'!I69 -> 0.034706843 | J22: ='Raw Datas'!J69 -> 0.02590618 | ... V22: ='Raw Datas'!V69 -> 0.040520939
A24: MAFA | B24: L_C14_1w7 | C24: ='Raw Datas'!C70 -> 0 | D24: ='Raw Datas'!D70 -> 0 | E24: ='Raw Datas'!E70 -> 0 | F24: ='Raw Datas'!F70 -> 0 | G24: ='Raw Datas'!G70 -> 0 | H24: ='Raw Datas'!H70 -> 0 | I24: ='Raw Datas'!I70 -> 0 | J24: ='Raw Datas'!J70 -> 0 | ... V24: ='Raw Datas'!V70 -> 0
B25: L_C15_1w7 | C25: ='Raw Datas'!C71 -> 0 | D25: ='Raw Datas'!D71 -> 0 | E25: ='Raw Datas'!E71 -> 0 | F25: ='Raw Datas'!F71 -> 0 | G25: ='Raw Datas'!G71 -> 0 | H25: ='Raw Datas'!H71 -> 0 | I25: ='Raw Datas'!I71 -> 0 | J25: ='Raw Datas'!J71 -> 0 | ... V25: ='Raw Datas'!V71 -> 0
B26: L_C16_1w9 | C26: ='Raw Datas'!C72 -> 0 | D26: ='Raw Datas'!D72 -> 0 | E26: ='Raw Datas'!E72 -> 0 | F26: ='Raw Datas'!F72 -> 0 | G26: ='Raw Datas'!G72 -> 0 | H26: ='Raw Datas'!H72 -> 0 | I26: ='Raw Datas'!I72 -> 0 | J26: ='Raw Datas'!J72 -> 0 | ... V26: ='Raw Datas'!V72 -> 0
B27: L_C16_1w7 | C27: ='Raw Datas'!C73 -> 0.060495746 | D27: ='Raw Datas'!D73 -> 0.22466308 | E27: ='Raw Datas'!E73 -> 0.11573739 | F27: ='Raw Datas'!F73 -> 0.053168396 | G27: ='Raw Datas'!G73 -> 0.13326446 | H27: ='Raw Datas'!H73 -> 0.073042754 | I27: ='Raw Datas'!I73 -> 0.051357104 | J27: ='Raw Datas'!J73 -> 0.11496413 | ... V27: ='Raw Datas'!V73 -> 0.097784475
B28: L_C17_1 | C28: ='Raw Datas'!C74 -> 0 | D28: ='Raw Datas'!D74 -> 0 | E28: ='Raw Datas'!E74 -> 0 | F28: ='Raw Datas'!F74 -> 0 | G28: ='Raw Datas'!G74 -> 0 | H28: ='Raw Datas'!H74 -> 0 | I28: ='Raw Datas'!I74 -> 0 | J28: ='Raw Datas'!J74 -> 0 | ... V28: ='Raw Datas'!V74 -> 0
B29: L_C18_1w9c | C29: ='Raw Datas'!C75 -> 0.075712612 | D29: ='Raw Datas'!D75 -> 0.17121687 | E29: ='Raw Datas'!E75 -> 0.096857843 | F29: ='Raw Datas'!F75 -> 0.087790506 | G29: ='Raw Datas'!G75 -> 0.087064234 | H29: ='Raw Datas'!H75 -> 0.098398477 | I29: ='Raw Datas'!I75 -> 0.074641657 | J29: ='Raw Datas'!J75 -> 0.056995944 | ... V29: ='Raw Datas'!V75 -> 0.10628683
B30: L_C18_1w9t | C30: ='Raw Datas'!C76 -> 0 | D30: ='Raw Datas'!D76 -> 0 | E30: ='Raw Datas'!E76 -> 0 | F30: ='Raw Datas'!F76 -> 0 | G30: ='Raw Datas'!G76 -> 0 | H30: ='Raw Datas'!H76 -> 0 | I30: ='Raw Datas'!I76 -> 0 | J30: ='Raw Datas'!J76 -> 0 | ... V30: ='Raw Datas'!V76 -> 0
B31: L_C18_1w7c | C31: ='Raw Datas'!C77 -> 0.93951636 | D31: ='Raw Datas'!D77 -> 1.471125 | E31: ='Raw Datas'!E77 -> 1.5800342 | F31: ='Raw Datas'!F77 -> 0.80715019 | G31: ='Raw Datas'!G77 -> 1.311136 | H31: ='Raw Datas'!H77 -> 1.2154351 | I31: ='Raw Datas'!I77 -> 1.1151259 | J31: ='Raw Datas'!J77 -> 1.0671206 | ... V31: ='Raw Datas'!V77 -> 1.7916386
B32: L_C20_1w9 | C32: ='Raw Datas'!C78 -> 0 | D32: ='Raw Datas'!D78 -> 0 | E32: ='Raw Datas'!E78 -> 0 | F32: ='Raw Datas'!F78 -> 0 | G32: ='Raw Datas'!G78 -> 0 | H32: ='Raw Datas'!H78 -> 0 | I32: ='Raw Datas'!I78 -> 0 | J32: ='Raw Datas'!J78 -> 0 | ... V32: ='Raw Datas'!V78 -> 0
B33: L_C22_1w9 | C33: ='Raw Datas'!C79 -> 0 | D33: ='Raw Datas'!D79 -> 0 | E33: ='Raw Datas'!E79 -> 0 | F33: ='Raw Datas'!F79 -> 0 | G33: ='Raw Datas'!G79 -> 0 | H33: ='Raw Datas'!H79 -> 0 | I33: ='Raw Datas'!I79 -> 0 | J33: ='Raw Datas'!J79 -> 0 | ... V33: ='Raw Datas'!V79 -> 0
B34: L_C24_1 | C34: ='Raw Datas'!C80 -> 0 | D34: ='Raw Datas'!D80 -> 0 | E34: ='Raw Datas'!E80 -> 0 | F34: ='Raw Datas'!F80 -> 0 | G34: ='Raw Datas'!G80 -> 0 | H34: ='Raw Datas'!H80 -> 0 | I34: ='Raw Datas'!I80 -> 0 | J34: ='Raw Datas'!J80 -> 0 | ... V34: ='Raw Datas'!V80 -> 0
A36: PUFA | B36: L_C16_2w6 | C36: ='Raw Datas'!C81 -> 0 | D36: ='Raw Datas'!D81 -> 0 | E36: ='Raw Datas'!E81 -> 0 | F36: ='Raw Datas'!F81 -> 0 | G36: ='Raw Datas'!G81 -> 0 | H36: ='Raw Datas'!H81 -> 0 | I36: ='Raw Datas'!I81 -> 0 | J36: ='Raw Datas'!J81 -> 0 | ... V36: ='Raw Datas'!V81 -> 0
B37: L_C16_2w4 | C37: ='Raw Datas'!C82 -> 0 | D37: ='Raw Datas'!D82 -> 0 | E37: ='Raw Datas'!E82 -> 0 | F37: ='Raw Datas'!F82 -> 0 | G37: ='Raw Datas'!G82 -> 0 | H37: ='Raw Datas'!H82 -> 0 | I37: ='Raw Datas'!I82 -> 0 | J37: ='Raw Datas'!J82 -> 0 | ... V37: ='Raw Datas'!V82 -> 0
B38: L_C16_3 | C38: ='Raw Datas'!C83 -> 0 | D38: ='Raw Datas'!D83 -> 0 | E38: ='Raw Datas'!E83 -> 0 | F38: ='Raw Datas'!F83 -> 0 | G38: ='Raw Datas'!G83 -> 0 | H38: ='Raw Datas'!H83 -> 0 | I38: ='Raw Datas'!I83 -> 0 | J38: ='Raw Datas'!J83 -> 0 | ... V38: ='Raw Datas'!V83 -> 0
B39: L_C16_4w3 | C39: ='Raw Datas'!C84 -> 0 | D39: ='Raw Datas'!D84 -> 0 | E39: ='Raw Datas'!E84 -> 0 | F39: ='Raw Datas'!F84 -> 0 | G39: ='Raw Datas'!G84 -> 0 | H39: ='Raw Datas'!H84 -> 0 | I39: ='Raw Datas'!I84 -> 0 | J39: ='Raw Datas'!J84 -> 0 | ... V39: ='Raw Datas'!V84 -> 0
B40: L_C18_2w6c | C40: ='Raw Datas'!C85 -> 1.1555306 | D40: ='Raw Datas'!D85 -> 1.1711562 | E40: ='Raw Datas'!E85 -> 1.184031 | F40: ='Raw Datas'!F85 -> 1.0501976 | G40: ='Raw Datas'!G85 -> 1.0317721 | H40: ='Raw Datas'!H85 -> 1.5069489 | I40: ='Raw Datas'!I85 -> 0.94551126 | J40: ='Raw Datas'!J85 -> 0.79221572 | ... V40: ='Raw Datas'!V85 -> 1.1790384
B41: L_C18_2w6t | C41: ='Raw Datas'!C86 -> 0 | D41: ='Raw Datas'!D86 -> 0 | E41: ='Raw Datas'!E86 -> 0 | F41: ='Raw Datas'!F86 -> 0 | G41: ='Raw Datas'!G86 -> 0 | H41: ='Raw Datas'!H86 -> 0 | I41: ='Raw Datas'!I86 -> 0 | J41: ='Raw Datas'!J86 -> 0 | ... V41: ='Raw Datas'!V86 -> 0
B42: L_C18_3w6 | C42: ='Raw Datas'!C87 -> 0 | D42: ='Raw Datas'!D87 -> 0 | E42: ='Raw Datas'!E87 -> 0 | F42: ='Raw Datas'!F87 -> 0 | G42: ='Raw Datas'!G87 -> 0 | H42: ='Raw Datas'!H87 -> 0 | I42: ='Raw Datas'!I87 -> 0 | J42: ='Raw Datas'!J87 -> 0 | ... V42: ='Raw Datas'!V87 -> 0
B43: L_C18_3w3 | C43: ='Raw Datas'!C88 -> 0 | D43: ='Raw Datas'!D88 -> 0 | E43: ='Raw Datas'!E88 -> 0 | F43: ='Raw Datas'!F88 -> 0 | G43: ='Raw Datas'!G88 -> 0 | H43: ='Raw Datas'!H88 -> 0 | I43: ='Raw Datas'!I88 -> 0 | J43: ='Raw Datas'!J88 -> 0 | ... V43: ='Raw Datas'!V88 -> 0
B44: L_C18_4w3 | C44: ='Raw Datas'!C89 -> 0 | D44: ='Raw Datas'!D89 -> 0 | E44: ='Raw Datas'!E89 -> 0 | F44: ='Raw Datas'!F89 -> 0 | G44: ='Raw Datas'!G89 -> 0 | H44: ='Raw Datas'!H89 -> 0 | I44: ='Raw Datas'!I89 -> 0 | J44: ='Raw Datas'!J89 -> 0 | ... V44: ='Raw Datas'!V89 -> 0
B45: L_C20_2w6 | C45: ='Raw Datas'!C90 -> 0.018473221 | D45: ='Raw Datas'!D90 -> 0.034422372 | E45: ='Raw Datas'!E90 -> 0.02202344 | F45: ='Raw Datas'!F90 -> 0.015856965 | G45: ='Raw Datas'!G90 -> 0.028409484 | H45: ='Raw Datas'!H90 -> 0.017635769 | I45: ='Raw Datas'!I90 -> 0.016234654 | J45: ='Raw Datas'!J90 -> 0.013376505 | ... V45: ='Raw Datas'!V90 -> 0.020404773
B46: L_C20_3w3 | C46: ='Raw Datas'!C91 -> 0 | D46: ='Raw Datas'!D91 -> 0 | E46: ='Raw Datas'!E91 -> 0 | F46: ='Raw Datas'!F91 -> 0 | G46: ='Raw Datas'!G91 -> 0 | H46: ='Raw Datas'!H91 -> 0 | I46: ='Raw Datas'!I91 -> 0 | J46: ='Raw Datas'!J91 -> 0 | ... V46: ='Raw Datas'!V91 -> 0
...

Sheet Raw Datas
A1: Sample name (list) | C1: JV-015-RAN-IC-M2 | D1: BS-007-RAN-01-M3 | E1: BS-007-RAN-02-M3 | F1: KT-004-SOC-16-M1 | G1: BS-135-RAN-IC-M3 | H1: JV-070-DAV-07-M3 | I1: BS-129-RAT-10-M5 | J1: JV-036-SOC-10-M2 | K1: BS-126-RAT-05-M2 | L1: JV-017-RAN-10-M3 | M1: JV-070-DAV-04-M1 | N1: BS-356-RAN-03-M4 | O1: JV-090-MIN-IC-M4 | P1: BS-391-RAN-06-M2 | Q1: JV-061-MIN-03-M5 | R1: JV-070-MIN-01-M1 | S1: KT-004-SOC-14-M1 | T1: JV-089-SOC-04-M1 | U1: BS-472-RAT-01-M1 | V1: BS-172-RAT-10-M3
A2: Sample name (analysis) | C2: 250528DMI_AGT_ 1 | D2: 250528DMI_AGT_ 2 | E2: 250528DMI_AGT_ 3 | F2: 250528DMI_AGT_ 4 | G2: 250528DMI_AGT_ 5 | H2: 250528DMI_AGT_ 6 | I2: 250528DMI_AGT_ 7 | J2: 250528DMI_AGT_ 8 | K2: 250528DMI_AGT_ 9 | L2: 250528DMI_AGT_ 10 | M2: 250528DMI_AGT_ 11 | N2: 250528DMI_AGT_ 12 | O2: 250528DMI_AGT_ 13 | P2: 250528DMI_AGT_ 14 | Q2: 250528DMI_AGT_ 15 | R2: 250528DMI_AGT_ 16 | S2: 250528DMI_AGT_ 17 | T2: 250528DMI_AGT_ 18 | U2: 250528DMI_AGT_ 19 | V2: 250528DMI_AGT_ 20
A3: L_C17_0 | C3: 0.1755044 | D3: 0.19152891 | E3: 0.17026601 | F3: 0.14258109 | G3: 0.193753 | H3: 0.2978127 | I3: 0.26662024 | J3: 0.19931434 | K3: 0.25353875 | L3: 0.21858032 | M3: 0.18749276 | N3: 0.24308562 | O3: 0.1896513 | P3: 0.10512871 | Q3: 0.26024185 | R3: 0.25003898 | S3: 0.25586135 | T3: 0.21407768 | U3: 0.18282958 | V3: 0.23358931
A4: L_C8_0 | C4: 0 | D4: 0 | E4: 0 | F4: 0 | G4: 0 | H4: 0 | I4: 0 | J4: 0 | K4: 0 | L4: 0 | M4: 0 | N4: 0 | O4: 0 | P4: 0 | Q4: 0 | R4: 0 | S4: 0 | T4: 0 | U4: 0 | V4: 0
A5: L_C10_0 | C5: 0 | D5: 0 | E5: 0 | F5: 0 | G5: 0 | H5: 0 | I5: 0 | J5: 0 | K5: 0 | L5: 0 | M5: 0 | N5: 0 | O5: 0 | P5: 0 | Q5: 0 | R5: 0 | S5: 0 | T5: 0 | U5: 0 | V5: 0
A6: L_C11_0 | C6: 0 | D6: 0 | E6: 0 | F6: 0 | G6: 0 | H6: 0 | I6: 0 | J6: 0 | K6: 0 | L6: 0 | M6: 0 | N6: 0 | O6: 0 | P6: 0 | Q6: 0 | R6: 0 | S6: 0 | T6: 0 | U6: 0 | V6: 0
A7: L_C12_0 | C7: 0 | D7: 0 | E7: 0 | F7: 0 | G7: 0 | H7: 0 | I7: 0 | J7: 0 | K7: 0 | L7: 0 | M7: 0 | N7: 0 | O7: 0 | P7: 0 | Q7: 0 | R7: 0 | S7: 0 | T7: 0 | U7: 0 | V7: 0
A8: L_C13_0 | C8: 0 | D8: 0 | E8: 0 | F8: 0 | G8: 0 | H8: 0 | I8: 0 | J8: 0 | K8: 0 | L8: 0 | M8: 0 | N8: 0 | O8: 0 | P8: 0 | Q8: 0 | R8: 0 | S8: 0 | T8: 0 | U8: 0 | V8: 0
A9: L_C14_0 | C9: 0 | D9: 0 | E9: 0 | F9: 0 | G9: 0 | H9: 0 | I9: 0 | J9: 0 | K9: 0 | L9: 0 | M9: 0 | N9: 0 | O9: 0 | P9: 0 | Q9: 0 | R9: 0 | S9: 0 | T9: 0 | U9: 0 | V9: 0
A10: L_C15_0 | C10: 0 | D10: 0 | E10: 0 | F10: 0 | G10: 0 | H10: 0 | I10: 0 | J10: 0 | K10: 0 | L10: 0 | M10: 0 | N10: 0 | O10: 0 | P10: 0 | Q10: 0 | R10: 0 | S10: 0 | T10: 0 | U10: 0 | V10: 0
A11: L_C16_0 | C11: 1.7944334 | D11: 3.4127124 | E11: 2.3129828 | F11: 1.318603 | G11: 2.7271195 | H11: 3.7945831 | I11: 2.4921652 | J11: 2.0827593 | K11: 2.7005075 | L11: 2.9265773 | M11: 1.5554938 | N11: 2.100955 | O11: 2.7987893 | P11: 3.5253172 | Q11: 4.041876 | R11: 2.2282404 | S11: 3.1599926 | T11: 2.8232468 | U11: 5.9534308 | V11: 3.4131359
A12: L_C19_0 | C12: - | D12: - | E12: - | F12: - | G12: - | H12: - | I12: - | J12: - | K12: - | L12: - | M12: - | N12: - | O12: - | P12: - | Q12: - | R12: - | S12: - | T12: - | U12: - | V12: -
A13: L_C18_0 | C13: 0.84390516 | D13: 0.68785369 | E13: 1.0132259 | F13: 0.69492449 | G13: 1.0369482 | H13: 1.5218422 | I13: 1.1306218 | J13: 0.72635407 | K13: 1.0591487 | L13: 0.9471656 | M13: 0.87851704 | N13: 1.024002 | O13: 0.97021608 | P13: 1.2313523 | Q13: 1.1449002 | R13: 0.96785037 | S13: 1.5580986 | T13: 1.3090383 | U13: 2.1914172 | V13: 1.2411651
A14: L_C20_0 | C14: 0 | D14: 0 | E14: 0 | F14: 0 | G14: 0 | H14: 0 | I14: 0 | J14: 0 | K14: 0 | L14: 0 | M14: 0 | N14: 0 | O14: 0 | P14: 0 | Q14: 0 | R14: 0 | S14: 0 | T14: 0 | U14: 0 | V14: 0
A15: L_C21_0 | C15: 0 | D15: 0 | E15: 0 | F15: 0 | G15: 0 | H15: 0 | I15: 0 | J15: 0 | K15: 0 | L15: 0 | M15: 0 | N15: 0 | O15: 0 | P15: 0 | Q15: 0 | R15: 0 | S15: 0 | T15: 0 | U15: 0 | V15: 0
A16: L_C22_0 | C16: 0 | D16: 0 | E16: 0 | F16: 0 | G16: 0 | H16: 0 | I16: 0 | J16: 0 | K16: 0 | L16: 0 | M16: 0 | N16: 0 | O16: 0 | P16: 0 | Q16: 0 | R16: 0 | S16: 0 | T16: 0 | U16: 0 | V16: 0
A17: L_C23_0 | C17: 0 | D17: 0 | E17: 0 | F17: 0 | G17: 0 | H17: 0 | I17: 0 | J17: 0 | K17: 0 | L17: 0 | M17: 0 | N17: 0 | O17: 0 | P17: 0 | Q17: 0 | R17: 0 | S17: 0 | T17: 0 | U17: 0 | V17: 0
A18: L_C24_0 | C18: 0.13292587 | D18: 0.098847837 | E18: 0.11592298 | F18: 0.10766137 | G18: 0.13200351 | H18: 0.25034446 | I18: 0.092535467 | J18: 0.051634732 | K18: 0.078837831 | L18: 0.096352392 | M18: 0.16524056 | N18: 0.083996638 | O18: 0.098741745 | P18: 0.094240657 | Q18: 0.071697533 | R18: 0.12161553 | S18: 0.17236159 | T18: 0.16269703 | U18: 0.17404899 | V18: 0.094652582
A19: L_C14_1w7 | C19: 0 | D19: 0 | E19: 0 | F19: 0 | G19: 0 | H19: 0 | I19: 0 | J19: 0 | K19: 0 | L19: 0 | M19: 0 | N19: 0 | O19: 0 | P19: 0 | Q19: 0 | R19: 0 | S19: 0 | T19: 0 | U19: 0 | V19: 0
A20: L_C15_1w7 | C20: 0 | D20: 0 | E20: 0 | F20: 0 | G20: 0 | H20: 0 | I20: 0 | J20: 0 | K20: 0 | L20: 0 | M20: 0 | N20: 0 | O20: 0 | P20: 0 | Q20: 0 | R20: 0 | S20: 0 | T20: 0 | U20: 0 | V20: 0
A21: L_C16_1w9 | C21: 0 | D21: 0 | E21: 0 | F21: 0 | G21: 0 | H21: 0 | I21: 0 | J21: 0 | K21: 0 | L21: 0 | M21: 0 | N21: 0 | O21: 0 | P21: 0 | Q21: 0 | R21: 0 | S21: 0 | T21: 0 | U21: 0 | V21: 0
A22: L_C16_1w7 | C22: 0.1061727 | D22: 0.43029475 | E22: 0.19706145 | F22: 0.075808081 | G22: 0.2582039 | H22: 0.2175306 | I22: 0.13692843 | J22: 0.22913999 | K22: 0.14681935 | L22: 0.27907118 | M22: 0.065387383 | N22: 0.15395928 | O22: 0.2466976 | P22: 0.17192323 | Q22: 0.28249468 | R22: 0.11440138 | S22: 0.21641675 | T22: 0.19830147 | U22: 0.42241381 | V22: 0.22841408
A23: L_C17_1 | C23: 0 | D23: 0 | E23: 0 | F23: 0 | G23: 0 | H23: 0 | I23: 0 | J23: 0 | K23: 0 | L23: 0 | M23: 0 | N23: 0 | O23: 0 | P23: 0 | Q23: 0 | R23: 0 | S23: 0 | T23: 0 | U23: 0 | V23: 0
A24: L_C18_1w9c | C24: 0.13287897 | D24: 0.3279298 | E24: 0.16491599 | F24: 0.12517266 | G24: 0.16868957 | H24: 0.29304316 | I24: 0.19900977 | J24: 0.11360109 | K24: 0.26155871 | L24: 0.270667 | M24: 0.15697498 | N24: 0.13968811 | O24: 0.21139416 | P24: 0.15734987 | Q24: 0.17454989 | R24: 0.1700685 | S24: 0.2143191 | T24: 0.23502683 | U24: 0.29218585 | V24: 0.24827468
... A48: L_C22_6w3 | C48: 0 | D48: 0 | E48: 0 | F48: 0 | G48: 0 | H48: 0 | I48: 0 | J48: 0 | K48: 0 | L48: 0 | M48: 0 | N48: 0 | O48: 0 | P48: 0 | Q48: 0 | R48: 0 | S48: 0 | T48: 0 | U48: 0 | V48: 0
A50: Tissue weight / Cells number | B50: million
A51: Protein weight | B51: µg
A52: Fluid volume | B52: µl | C52: 10 | D52: 10 | E52: 10 | F52: 10 | G52: 10 | H52: 10 | I52: 10 | J52: 10 | K52: 10 | L52: 10 | M52: 10 | N52: 10 | O52: 10 | P52: 10 | Q52: 10 | R52: 10 | S52: 10 | T52: 10 | U52: 10 | V52: 10
A53: =IF(AND(OR(Results!C4="Tissue",Results!C4="Cells"),Results!C5="Protein",C51>0,B51="mg"),"Relative abundance/mg of protein",IF(AND(OR(Results!C4="Tissue",Results!C4="Cells"),Results!C5="Protein",C51>0,B51="µg"),"Relative abundance/µg of protein",IF(AND(Results!C4="Tissue",Results!C5="Weight",C50>0,B50="mg"),"Relative abundance/mg of tissue",IF(AND(Results!C4="Tissue",Results!C5="Weight",C50>0,B50="g"),"Relative abundance/g of tissue",IF(AND(Results!C4="Fluid",Results!C5="Volume",C52>0,B52="µl"),"Relative abundance/µL of fluid",IF(AND(Results!C4="Fluid",Results!C5="Volume",C52>0,B52="ml"),"Relative abundance/mL of fluid",IF(AND(Results!C4="Cells",Results!C5="Million",C50>0,B50="million"),"Relative abundance/million of cells","-"))))))) -> Relative abundance/µL of fluid
A54: =A3 -> L_C17_0 | C54: =IF(C3=0,"0",IF(AND(Results!$C$5="Protein",C$51>0,OR(Results!$C$4="Tissue",Results!$C$4="Cells")),((C3)/(C$3*C$51)),IF(AND(Results!$C$5="Weight",C$50>0,Results!$C$4="Tissue"),((C3)/(C$3*C$50)),IF(AND(Results!$C$5="Volume",C$52>0,Results!$C$4="Fluid"),((C3)/(C$3*C$52)),IF(AND(Results!$C$4="Cells",Results!$C$5="Million"),((C3)/(C$3*C$50)),"-"))))) -> 0.1 | D54: =IF(D3=0,"0",IF(AND(Results!$C$5="Protein",D$51>0,OR(Results!$C$4="Tissue",Results!$C$4="Cells")),((D3)/(D$3*D$51)),IF(AND(Results!$C$5="Weight",D$50>0,Results!$C$4="Tissue"),((D3)/(D$3*D$50)),IF(AND(Results!$C$5="Volume",D$52>0,Results!$C$4="Fluid"),((D3)/(D$3*D$52)),IF(AND(Results!$C$4="Cells",Results!$C$5="Million"),((D3)/(D$3*D$50)),"-"))))) -> 0.1 | E54: =IF(E3=0,"0",IF(AND(Results!$C$5="Protein",E$51>0,OR(Results!$C$4="Tissue",Results!$C$4="Cells")),((E3)/(E$3*E$51)),IF(AND(Results!$C$5="Weight",E$50>0,Results!$C$4="Tissue"),((E3)/(E$3*E$50)),IF(AND(Results!$C$5="Volume",E$52>0,Results!$C$4="Fluid"),((E3)/(E$3*E$52)),IF(AND(Results!$C$4="Cells",Results!$C$5="Million"),((E3)/(E$3*E$50)),"-"))))) -> 0.1 | F54: =IF(F3=0,"0",IF(AND(Results!$C$5="Protein",F$51>0,OR(Results!$C$4="Tissue",Results!$C$4="Cells")),((F3)/(F$3*F$51)),IF(AND(Results!$C$5="Weight",F$50>0,Results!$C$4="Tissue"),((F3)/(F$3*F$50)),IF(AND(Results!$C$5="Volume",F$52>0,Results!$C$4="Fluid"),((F3)/(F$3*F$52)),IF(AND(Results!$C$4="Cells",Results!$C$5="Million"),((F3)/(F$3*F$50)),"-"))))) -> 0.1 | G54: =IF(G3=0,"0",IF(AND(Results!$C$5="Protein",G$51>0,OR(Results!$C$4="Tissue",Results!$C$4="Cells")),((G3)/(G$3*G$51)),IF(AND(Results!$C$5="Weight",G$50>0,Results!$C$4="Tissue"),((G3)/(G$3*G$50)),IF(AND(Results!$C$5="Volume",G$52>0,Results!$C$4="Fluid"),((G3)/(G$3*G$52)),IF(AND(Results!$C$4="Cells",Results!$C$5="Million"),((G3)/(G$3*G$50)),"-"))))) -> 0.1 | H54: =IF(H3=0,"0",IF(AND(Results!$C$5="Protein",H$51>0,OR(Results!$C$4="Tissue",Results!$C$4="Cells")),((H3)/(H$3*H$51)),IF(AND(Results!$C$5="Weight",H$50>0,Results!$C$4="Tissue"),((H3)/(H$3*H$50)),IF(AND(Results!$C$5="Volume",H$52>0,Results!$C$4="Fluid"),((H3)/(H$3*H$52)),IF(AND(Results!$C$4="Cells",Results!$C$5="Million"),((H3)/(H$3*H$50)),"-"))))) -> 0.1 | I54: =IF(I3=0,"0",IF(AND(Results!$C$5="Protein",I$51>0,OR(Results!$C$4="Tissue",Results!$C$4="Cells")),((I3)/(I$3*I$51)),IF(AND(Results!$C$5="Weight",I$50>0,Results!$C$4="Tissue"),((I3)/(I$3*I$50)),IF(AND(Results!$C$5="Volume",I$52>0,Results!$C$4="Fluid"),((I3)/(I$3*I$52)),IF(AND(Results!$C$4="Cells",Results!$C$5="Million"),((I3)/(I$3*I$50)),"-"))))) -> 0.1 | J54: =IF(J3=0,"0",IF(AND(Results!$C$5="Protein",J$51>0,OR(Results!$C$4="Tissue",Results!$C$4="Cells")),((J3)/(J$3*J$51)),IF(AND(Results!$C$5="Weight",J$50>0,Results!$C$4="Tissue"),((J3)/(J$3*J$50)),IF(AND(Results!$C$5="Volume",J$52>0,Results!$C$4="Fluid"),((J3)/(J$3*J$52)),IF(AND(Results!$C$4="Cells",Results!$C$5="Million"),((J3)/(J$3*J$50)),"-"))))) -> 0.1 | ... V54: =IF(V3=0,"0",IF(AND(Results!$C$5="Protein",V$51>0,OR(Results!$C$4="Tissue",Results!$C$4="Cells")),((V3)/(V$3*V$51)),IF(AND(Results!$C$5="Weight",V$50>0,Results!$C$4="Tissue"),((V3)/(V$3*V$50)),IF(AND(Results!$C$5="Volume",V$52>0,Results!$C$4="Fluid"),((V3)/(V$3*V$52)),IF(AND(Results!$C$4="Cells",Results!$C$5="Million"),((V3)/(V$3*V$50)),"-"))))) -> 0.1
A55: =A4 -> L_C8_0 | C55: =IF(C4=0,"0",IF(AND(Results!$C$5="Protein",C$51>0,OR(Results!$C$4="Tissue",Results!$C$4="Cells")),((C4)/(C$3*C$51)),IF(AND(Results!$C$5="Weight",C$50>0,Results!$C$4="Tissue"),((C4)/(C$3*C$50)),IF(AND(Results!$C$5="Volume",C$52>0,Results!$C$4="Fluid"),((C4)/(C$3*C$52)),IF(AND(Results!$C$4="Cells",Results!$C$5="Million"),((C4)/(C$3*C$50)),"-"))))) -> 0 | D55: =IF(D4=0,"0",IF(AND(Results!$C$5="Protein",D$51>0,OR(Results!$C$4="Tissue",Results!$C$4="Cells")),((D4)/(D$3*D$51)),IF(AND(Results!$C$5="Weight",D$50>0,Results!$C$4="Tissue"),((D4)/(D$3*D$50)),IF(AND(Results!$C$5="Volume",D$52>0,Results!$C$4="Fluid"),((D4)/(D$3*D$52)),IF(AND(Results!$C$4="Cells",Results!$C$5="Million"),((D4)/(D$3*D$50)),"-"))))) -> 0 | E55: =IF(E4=0,"0",IF(AND(Results!$C$5="Protein",E$51>0,OR(Results!$C$4="Tissue",Results!$C$4="Cells")),((E4)/(E$3*E$51)),IF(AND(Results!$C$5="Weight",E$50>0,Results!$C$4="Tissue"),((E4)/(E$3*E$50)),IF(AND(Results!$C$5="Volume",E$52>0,Results!$C$4="Fluid"),((E4)/(E$3*E$52)),IF(AND(Results!$C$4="Cells",Results!$C$5="Million"),((E4)/(E$3*E$50)),"-"))))) -> 0 | F55: =IF(F4=0,"0",IF(AND(Results!$C$5="Protein",F$51>0,OR(Results!$C$4="Tissue",Results!$C$4="Cells")),((F4)/(F$3*F$51)),IF(AND(Results!$C$5="Weight",F$50>0,Results!$C$4="Tissue"),((F4)/(F$3*F$50)),IF(AND(Results!$C$5="Volume",F$52>0,Results!$C$4="Fluid"),((F4)/(F$3*F$52)),IF(AND(Results!$C$4="Cells",Results!$C$5="Million"),((F4)/(F$3*F$50)),"-"))))) -> 0 | G55: =IF(G4=0,"0",IF(AND(Results!$C$5="Protein",G$51>0,OR(Results!$C$4="Tissue",Results!$C$4="Cells")),((G4)/(G$3*G$51)),IF(AND(Results!$C$5="Weight",G$50>0,Results!$C$4="Tissue"),((G4)/(G$3*G$50)),IF(AND(Results!$C$5="Volume",G$52>0,Results!$C$4="Fluid"),((G4)/(G$3*G$52)),IF(AND(Results!$C$4="Cells",Results!$C$5="Million"),((G4)/(G$3*G$50)),"-"))))) -> 0 | H55: =IF(H4=0,"0",IF(AND(Results!$C$5="Protein",H$51>0,OR(Results!$C$4="Tissue",Results!$C$4="Cells")),((H4)/(H$3*H$51)),IF(AND(Results!$C$5="Weight",H$50>0,Results!$C$4="Tissue"),((H4)/(H$3*H$50)),IF(AND(Results!$C$5="Volume",H$52>0,Results!$C$4="Fluid"),((H4)/(H$3*H$52)),IF(AND(Results!$C$4="Cells",Results!$C$5="Million"),((H4)/(H$3*H$50)),"-"))))) -> 0 | I55: =IF(I4=0,"0",IF(AND(Results!$C$5="Protein",I$51>0,OR(Results!$C$4="Tissue",Results!$C$4="Cells")),((I4)/(I$3*I$51)),IF(AND(Results!$C$5="Weight",I$50>0,Results!$C$4="Tissue"),((I4)/(I$3*I$50)),IF(AND(Results!$C$5="Volume",I$52>0,Results!$C$4="Fluid"),((I4)/(I$3*I$52)),IF(AND(Results!$C$4="Cells",Results!$C$5="Million"),((I4)/(I$3*I$50)),"-"))))) -> 0 | J55: =IF(J4=0,"0",IF(AND(Results!$C$5="Protein",J$51>0,OR(Results!$C$4="Tissue",Results!$C$4="Cells")),((J4)/(J$3*J$51)),IF(AND(Results!$C$5="Weight",J$50>0,Results!$C$4="Tissue"),((J4)/(J$3*J$50)),IF(AND(Results!$C$5="Volume",J$52>0,Results!$C$4="Fluid"),((J4)/(J$3*J$52)),IF(AND(Results!$C$4="Cells",Results!$C$5="Million"),((J4)/(J$3*J$50)),"-"))))) -> 0 | ... V55: =IF(V4=0,"0",IF(AND(Results!$C$5="Protein",V$51>0,OR(Results!$C$4="Tissue",Results!$C$4="Cells")),((V4)/(V$3*V$51)),IF(AND(Results!$C$5="Weight",V$50>0,Results!$C$4="Tissue"),((V4)/(V$3*V$50)),IF(AND(Results!$C$5="Volume",V$52>0,Results!$C$4="Fluid"),((V4)/(V$3*V$52)),IF(AND(Results!$C$4="Cells",Results!$C$5="Million"),((V4)/(V$3*V$50)),"-"))))) -> 0
A56: =A5 -> L_C10_0 | C56: =IF(C5=0,"0",IF(AND(Results!$C$5="Protein",C$51>0,OR(Results!$C$4="Tissue",Results!$C$4="Cells")),((C5)/(C$3*C$51)),IF(AND(Results!$C$5="Weight",C$50>0,Results!$C$4="Tissue"),((C5)/(C$3*C$50)),IF(AND(Results!$C$5="Volume",C$52>0,Results!$C$4="Fluid"),((C5)/(C$3*C$52)),IF(AND(Results!$C$4="Cells",Results!$C$5="Million"),((C5)/(C$3*C$50)),"-"))))) -> 0 | D56: =IF(D5=0,"0",IF(AND(Results!$C$5="Protein",D$51>0,OR(Results!$C$4="Tissue",Results!$C$4="Cells")),((D5)/(D$3*D$51)),IF(AND(Results!$C$5="Weight",D$50>0,Results!$C$4="Tissue"),((D5)/(D$3*D$50)),IF(AND(Results!$C$5="Volume",D$52>0,Results!$C$4="Fluid"),((D5)/(D$3*D$52)),IF(AND(Results!$C$4="Cells",Results!$C$5="Million"),((D5)/(D$3*D$50)),"-"))))) -> 0 | E56: =IF(E5=0,"0",IF(AND(Results!$C$5="Protein",E$51>0,OR(Results!$C$4="Tissue",Results!$C$4="Cells")),((E5)/(E$3*E$51)),IF(AND(Results!$C$5="Weight",E$50>0,Results!$C$4="Tissue"),((E5)/(E$3*E$50)),IF(AND(Results!$C$5="Volume",E$52>0,Results!$C$4="Fluid"),((E5)/(E$3*E$52)),IF(AND(Results!$C$4="Cells",Results!$C$5="Million"),((E5)/(E$3*E$50)),"-"))))) -> 0 | F56: =IF(F5=0,"0",IF(AND(Results!$C$5="Protein",F$51>0,OR(Results!$C$4="Tissue",Results!$C$4="Cells")),((F5)/(F$3*F$51)),IF(AND(Results!$C$5="Weight",F$50>0,Results!$C$4="Tissue"),((F5)/(F$3*F$50)),IF(AND(Results!$C$5="Volume",F$52>0,Results!$C$4="Fluid"),((F5)/(F$3*F$52)),IF(AND(Results!$C$4="Cells",Results!$C$5="Million"),((F5)/(F$3*F$50)),"-"))))) -> 0 | G56: =IF(G5=0,"0",IF(AND(Results!$C$5="Protein",G$51>0,OR(Results!$C$4="Tissue",Results!$C$4="Cells")),((G5)/(G$3*G$51)),IF(AND(Results!$C$5="Weight",G$50>0,Results!$C$4="Tissue"),((G5)/(G$3*G$50)),IF(AND(Results!$C$5="Volume",G$52>0,Results!$C$4="Fluid"),((G5)/(G$3*G$52)),IF(AND(Results!$C$4="Cells",Results!$C$5="Million"),((G5)/(G$3*G$50)),"-"))))) -> 0 | H56: =IF(H5=0,"0",IF(AND(Results!$C$5="Protein",H$51>0,OR(Results!$C$4="Tissue",Results!$C$4="Cells")),((H5)/(H$3*H$51)),IF(AND(Results!$C$5="Weight",H$50>0,Results!$C$4="Tissue"),((H5)/(H$3*H$50)),IF(AND(Results!$C$5="Volume",H$52>0,Results!$C$4="Fluid"),((H5)/(H$3*H$52)),IF(AND(Results!$C$4="Cells",Results!$C$5="Million"),((H5)/(H$3*H$50)),"-"))))) -> 0 | I56: =IF(I5=0,"0",IF(AND(Results!$C$5="Protein",I$51>0,OR(Results!$C$4="Tissue",Results!$C$4="Cells")),((I5)/(I$3*I$51)),IF(AND(Results!$C$5="Weight",I$50>0,Results!$C$4="Tissue"),((I5)/(I$3*I$50)),IF(AND(Results!$C$5="Volume",I$52>0,Results!$C$4="Fluid"),((I5)/(I$3*I$52)),IF(AND(Results!$C$4="Cells",Results!$C$5="Million"),((I5)/(I$3*I$50)),"-"))))) -> 0 | J56: =IF(J5=0,"0",IF(AND(Results!$C$5="Protein",J$51>0,OR(Results!$C$4="Tissue",Results!$C$4="Cells")),((J5)/(J$3*J$51)),IF(AND(Results!$C$5="Weight",J$50>0,Results!$C$4="Tissue"),((J5)/(J$3*J$50)),IF(AND(Results!$C$5="Volume",J$52>0,Results!$C$4="Fluid"),((J5)/(J$3*J$52)),IF(AND(Results!$C$4="Cells",Results!$C$5="Million"),((J5)/(J$3*J$50)),"-"))))) -> 0 | ... V56: =IF(V5=0,"0",IF(AND(Results!$C$5="Protein",V$51>0,OR(Results!$C$4="Tissue",Results!$C$4="Cells")),((V5)/(V$3*V$51)),IF(AND(Results!$C$5="Weight",V$50>0,Results!$C$4="Tissue"),((V5)/(V$3*V$50)),IF(AND(Results!$C$5="Volume",V$52>0,Results!$C$4="Fluid"),((V5)/(V$3*V$52)),IF(AND(Results!$C$4="Cells",Results!$C$5="Million"),((V5)/(V$3*V$50)),"-"))))) -> 0
A57: =A6 -> L_C11_0 | C57: =IF(C6=0,"0",IF(AND(Results!$C$5="Protein",C$51>0,OR(Results!$C$4="Tissue",Results!$C$4="Cells")),((C6)/(C$3*C$51)),IF(AND(Results!$C$5="Weight",C$50>0,Results!$C$4="Tissue"),((C6)/(C$3*C$50)),IF(AND(Results!$C$5="Volume",C$52>0,Results!$C$4="Fluid"),((C6)/(C$3*C$52)),IF(AND(Results!$C$4="Cells",Results!$C$5="Million"),((C6)/(C$3*C$50)),"-"))))) -> 0 | D57: =IF(D6=0,"0",IF(AND(Results!$C$5="Protein",D$51>0,OR(Results!$C$4="Tissue",Results!$C$4="Cells")),((D6)/(D$3*D$51)),IF(AND(Results!$C$5="Weight",D$50>0,Results!$C$4="Tissue"),((D6)/(D$3*D$50)),IF(AND(Results!$C$5="Volume",D$52>0,Results!$C$4="Fluid"),((D6)/(D$3*D$52)),IF(AND(Results!$C$4="Cells",Results!$C$5="Million"),((D6)/(D$3*D$50)),"-"))))) -> 0 | E57: =IF(E6=0,"0",IF(AND(Results!$C$5="Protein",E$51>0,OR(Results!$C$4="Tissue",Results!$C$4="Cells")),((E6)/(E$3*E$51)),IF(AND(Results!$C$5="Weight",E$50>0,Results!$C$4="Tissue"),((E6)/(E$3*E$50)),IF(AND(Results!$C$5="Volume",E$52>0,Results!$C$4="Fluid"),((E6)/(E$3*E$52)),IF(AND(Results!$C$4="Cells",Results!$C$5="Million"),((E6)/(E$3*E$50)),"-"))))) -> 0 | F57: =IF(F6=0,"0",IF(AND(Results!$C$5="Protein",F$51>0,OR(Results!$C$4="Tissue",Results!$C$4="Cells")),((F6)/(F$3*F$51)),IF(AND(Results!$C$5="Weight",F$50>0,Results!$C$4="Tissue"),((F6)/(F$3*F$50)),IF(AND(Results!$C$5="Volume",F$52>0,Results!$C$4="Fluid"),((F6)/(F$3*F$52)),IF(AND(Results!$C$4="Cells",Results!$C$5="Million"),((F6)/(F$3*F$50)),"-"))))) -> 0 | G57: =IF(G6=0,"0",IF(AND(Results!$C$5="Protein",G$51>0,OR(Results!$C$4="Tissue",Results!$C$4="Cells")),((G6)/(G$3*G$51)),IF(AND(Results!$C$5="Weight",G$50>0,Results!$C$4="Tissue"),((G6)/(G$3*G$50)),IF(AND(Results!$C$5="Volume",G$52>0,Results!$C$4="Fluid"),((G6)/(G$3*G$52)),IF(AND(Results!$C$4="Cells",Results!$C$5="Million"),((G6)/(G$3*G$50)),"-"))))) -> 0 | H57: =IF(H6=0,"0",IF(AND(Results!$C$5="Protein",H$51>0,OR(Results!$C$4="Tissue",Results!$C$4="Cells")),((H6)/(H$3*H$51)),IF(AND(Results!$C$5="Weight",H$50>0,Results!$C$4="Tissue"),((H6)/(H$3*H$50)),IF(AND(Results!$C$5="Volume",H$52>0,Results!$C$4="Fluid"),((H6)/(H$3*H$52)),IF(AND(Results!$C$4="Cells",Results!$C$5="Million"),((H6)/(H$3*H$50)),"-"))))) -> 0 | I57: =IF(I6=0,"0",IF(AND(Results!$C$5="Protein",I$51>0,OR(Results!$C$4="Tissue",Results!$C$4="Cells")),((I6)/(I$3*I$51)),IF(AND(Results!$C$5="Weight",I$50>0,Results!$C$4="Tissue"),((I6)/(I$3*I$50)),IF(AND(Results!$C$5="Volume",I$52>0,Results!$C$4="Fluid"),((I6)/(I$3*I$52)),IF(AND(Results!$C$4="Cells",Results!$C$5="Million"),((I6)/(I$3*I$50)),"-"))))) -> 0 | J57: =IF(J6=0,"0",IF(AND(Results!$C$5="Protein",J$51>0,OR(Results!$C$4="Tissue",Results!$C$4="Cells")),((J6)/(J$3*J$51)),IF(AND(Results!$C$5="Weight",J$50>0,Results!$C$4="Tissue"),((J6)/(J$3*J$50)),IF(AND(Results!$C$5="Volume",J$52>0,Results!$C$4="Fluid"),((J6)/(J$3*J$52)),IF(AND(Results!$C$4="Cells",Results!$C$5="Million"),((J6)/(J$3*J$50)),"-"))))) -> 0 | ... V57: =IF(V6=0,"0",IF(AND(Results!$C$5="Protein",V$51>0,OR(Results!$C$4="Tissue",Results!$C$4="Cells")),((V6)/(V$3*V$51)),IF(AND(Results!$C$5="Weight",V$50>0,Results!$C$4="Tissue"),((V6)/(V$3*V$50)),IF(AND(Results!$C$5="Volume",V$52>0,Results!$C$4="Fluid"),((V6)/(V$3*V$52)),IF(AND(Results!$C$4="Cells",Results!$C$5="Million"),((V6)/(V$3*V$50)),"-"))))) -> 0
A58: =A7 -> L_C12_0 | C58: =IF(C7=0,"0",IF(AND(Results!$C$5="Protein",C$51>0,OR(Results!$C$4="Tissue",Results!$C$4="Cells")),((C7)/(C$3*C$51)),IF(AND(Results!$C$5="Weight",C$50>0,Results!$C$4="Tissue"),((C7)/(C$3*C$50)),IF(AND(Results!$C$5="Volume",C$52>0,Results!$C$4="Fluid"),((C7)/(C$3*C$52)),IF(AND(Results!$C$4="Cells",Results!$C$5="Million"),((C7)/(C$3*C$50)),"-"))))) -> 0 | D58: =IF(D7=0,"0",IF(AND(Results!$C$5="Protein",D$51>0,OR(Results!$C$4="Tissue",Results!$C$4="Cells")),((D7)/(D$3*D$51)),IF(AND(Results!$C$5="Weight",D$50>0,Results!$C$4="Tissue"),((D7)/(D$3*D$50)),IF(AND(Results!$C$5="Volume",D$52>0,Results!$C$4="Fluid"),((D7)/(D$3*D$52)),IF(AND(Results!$C$4="Cells",Results!$C$5="Million"),((D7)/(D$3*D$50)),"-"))))) -> 0 | E58: =IF(E7=0,"0",IF(AND(Results!$C$5="Protein",E$51>0,OR(Results!$C$4="Tissue",Results!$C$4="Cells")),((E7)/(E$3*E$51)),IF(AND(Results!$C$5="Weight",E$50>0,Results!$C$4="Tissue"),((E7)/(E$3*E$50)),IF(AND(Results!$C$5="Volume",E$52>0,Results!$C$4="Fluid"),((E7)/(E$3*E$52)),IF(AND(Results!$C$4="Cells",Results!$C$5="Million"),((E7)/(E$3*E$50)),"-"))))) -> 0 | F58: =IF(F7=0,"0",IF(AND(Results!$C$5="Protein",F$51>0,OR(Results!$C$4="Tissue",Results!$C$4="Cells")),((F7)/(F$3*F$51)),IF(AND(Results!$C$5="Weight",F$50>0,Results!$C$4="Tissue"),((F7)/(F$3*F$50)),IF(AND(Results!$C$5="Volume",F$52>0,Results!$C$4="Fluid"),((F7)/(F$3*F$52)),IF(AND(Results!$C$4="Cells",Results!$C$5="Million"),((F7)/(F$3*F$50)),"-"))))) -> 0 | G58: =IF(G7=0,"0",IF(AND(Results!$C$5="Protein",G$51>0,OR(Results!$C$4="Tissue",Results!$C$4="Cells")),((G7)/(G$3*G$51)),IF(AND(Results!$C$5="Weight",G$50>0,Results!$C$4="Tissue"),((G7)/(G$3*G$50)),IF(AND(Results!$C$5="Volume",G$52>0,Results!$C$4="Fluid"),((G7)/(G$3*G$52)),IF(AND(Results!$C$4="Cells",Results!$C$5="Million"),((G7)/(G$3*G$50)),"-"))))) -> 0 | H58: =IF(H7=0,"0",IF(AND(Results!$C$5="Protein",H$51>0,OR(Results!$C$4="Tissue",Results!$C$4="Cells")),((H7)/(H$3*H$51)),IF(AND(Results!$C$5="Weight",H$50>0,Results!$C$4="Tissue"),((H7)/(H$3*H$50)),IF(AND(Results!$C$5="Volume",H$52>0,Results!$C$4="Fluid"),((H7)/(H$3*H$52)),IF(AND(Results!$C$4="Cells",Results!$C$5="Million"),((H7)/(H$3*H$50)),"-"))))) -> 0 | I58: =IF(I7=0,"0",IF(AND(Results!$C$5="Protein",I$51>0,OR(Results!$C$4="Tissue",Results!$C$4="Cells")),((I7)/(I$3*I$51)),IF(AND(Results!$C$5="Weight",I$50>0,Results!$C$4="Tissue"),((I7)/(I$3*I$50)),IF(AND(Results!$C$5="Volume",I$52>0,Results!$C$4="Fluid"),((I7)/(I$3*I$52)),IF(AND(Results!$C$4="Cells",Results!$C$5="Million"),((I7)/(I$3*I$50)),"-"))))) -> 0 | J58: =IF(J7=0,"0",IF(AND(Results!$C$5="Protein",J$51>0,OR(Results!$C$4="Tissue",Results!$C$4="Cells")),((J7)/(J$3*J$51)),IF(AND(Results!$C$5="Weight",J$50>0,Results!$C$4="Tissue"),((J7)/(J$3*J$50)),IF(AND(Results!$C$5="Volume",J$52>0,Results!$C$4="Fluid"),((J7)/(J$3*J$52)),IF(AND(Results!$C$4="Cells",Results!$C$5="Million"),((J7)/(J$3*J$50)),"-"))))) -> 0 | ... V58: =IF(V7=0,"0",IF(AND(Results!$C$5="Protein",V$51>0,OR(Results!$C$4="Tissue",Results!$C$4="Cells")),((V7)/(V$3*V$51)),IF(AND(Results!$C$5="Weight",V$50>0,Results!$C$4="Tissue"),((V7)/(V$3*V$50)),IF(AND(Results!$C$5="Volume",V$52>0,Results!$C$4="Fluid"),((V7)/(V$3*V$52)),IF(AND(Results!$C$4="Cells",Results!$C$5="Million"),((V7)/(V$3*V$50)),"-"))))) -> 0
A59: =A8 -> L_C13_0 | C59: =IF(C8=0,"0",IF(AND(Results!$C$5="Protein",C$51>0,OR(Results!$C$4="Tissue",Results!$C$4="Cells")),((C8)/(C$3*C$51)),IF(AND(Results!$C$5="Weight",C$50>0,Results!$C$4="Tissue"),((C8)/(C$3*C$50)),IF(AND(Results!$C$5="Volume",C$52>0,Results!$C$4="Fluid"),((C8)/(C$3*C$52)),IF(AND(Results!$C$4="Cells",Results!$C$5="Million"),((C8)/(C$3*C$50)),"-"))))) -> 0 | D59: =IF(D8=0,"0",IF(AND(Results!$C$5="Protein",D$51>0,OR(Results!$C$4="Tissue",Results!$C$4="Cells")),((D8)/(D$3*D$51)),IF(AND(Results!$C$5="Weight",D$50>0,Results!$C$4="Tissue"),((D8)/(D$3*D$50)),IF(AND(Results!$C$5="Volume",D$52>0,Results!$C$4="Fluid"),((D8)/(D$3*D$52)),IF(AND(Results!$C$4="Cells",Results!$C$5="Million"),((D8)/(D$3*D$50)),"-"))))) -> 0 | E59: =IF(E8=0,"0",IF(AND(Results!$C$5="Protein",E$51>0,OR(Results!$C$4="Tissue",Results!$C$4="Cells")),((E8)/(E$3*E$51)),IF(AND(Results!$C$5="Weight",E$50>0,Results!$C$4="Tissue"),((E8)/(E$3*E$50)),IF(AND(Results!$C$5="Volume",E$52>0,Results!$C$4="Fluid"),((E8)/(E$3*E$52)),IF(AND(Results!$C$4="Cells",Results!$C$5="Million"),((E8)/(E$3*E$50)),"-"))))) -> 0 | F59: =IF(F8=0,"0",IF(AND(Results!$C$5="Protein",F$51>0,OR(Results!$C$4="Tissue",Results!$C$4="Cells")),((F8)/(F$3*F$51)),IF(AND(Results!$C$5="Weight",F$50>0,Results!$C$4="Tissue"),((F8)/(F$3*F$50)),IF(AND(Results!$C$5="Volume",F$52>0,Results!$C$4="Fluid"),((F8)/(F$3*F$52)),IF(AND(Results!$C$4="Cells",Results!$C$5="Million"),((F8)/(F$3*F$50)),"-"))))) -> 0 | G59: =IF(G8=0,"0",IF(AND(Results!$C$5="Protein",G$51>0,OR(Results!$C$4="Tissue",Results!$C$4="Cells")),((G8)/(G$3*G$51)),IF(AND(Results!$C$5="Weight",G$50>0,Results!$C$4="Tissue"),((G8)/(G$3*G$50)),IF(AND(Results!$C$5="Volume",G$52>0,Results!$C$4="Fluid"),((G8)/(G$3*G$52)),IF(AND(Results!$C$4="Cells",Results!$C$5="Million"),((G8)/(G$3*G$50)),"-"))))) -> 0 | H59: =IF(H8=0,"0",IF(AND(Results!$C$5="Protein",H$51>0,OR(Results!$C$4="Tissue",Results!$C$4="Cells")),((H8)/(H$3*H$51)),IF(AND(Results!$C$5="Weight",H$50>0,Results!$C$4="Tissue"),((H8)/(H$3*H$50)),IF(AND(Results!$C$5="Volume",H$52>0,Results!$C$4="Fluid"),((H8)/(H$3*H$52)),IF(AND(Results!$C$4="Cells",Results!$C$5="Million"),((H8)/(H$3*H$50)),"-"))))) -> 0 | I59: =IF(I8=0,"0",IF(AND(Results!$C$5="Protein",I$51>0,OR(Results!$C$4="Tissue",Results!$C$4="Cells")),((I8)/(I$3*I$51)),IF(AND(Results!$C$5="Weight",I$50>0,Results!$C$4="Tissue"),((I8)/(I$3*I$50)),IF(AND(Results!$C$5="Volume",I$52>0,Results!$C$4="Fluid"),((I8)/(I$3*I$52)),IF(AND(Results!$C$4="Cells",Results!$C$5="Million"),((I8)/(I$3*I$50)),"-"))))) -> 0 | J59: =IF(J8=0,"0",IF(AND(Results!$C$5="Protein",J$51>0,OR(Results!$C$4="Tissue",Results!$C$4="Cells")),((J8)/(J$3*J$51)),IF(AND(Results!$C$5="Weight",J$50>0,Results!$C$4="Tissue"),((J8)/(J$3*J$50)),IF(AND(Results!$C$5="Volume",J$52>0,Results!$C$4="Fluid"),((J8)/(J$3*J$52)),IF(AND(Results!$C$4="Cells",Results!$C$5="Million"),((J8)/(J$3*J$50)),"-"))))) -> 0 | ... V59: =IF(V8=0,"0",IF(AND(Results!$C$5="Protein",V$51>0,OR(Results!$C$4="Tissue",Results!$C$4="Cells")),((V8)/(V$3*V$51)),IF(AND(Results!$C$5="Weight",V$50>0,Results!$C$4="Tissue"),((V8)/(V$3*V$50)),IF(AND(Results!$C$5="Volume",V$52>0,Results!$C$4="Fluid"),((V8)/(V$3*V$52)),IF(AND(Results!$C$4="Cells",Results!$C$5="Million"),((V8)/(V$3*V$50)),"-"))))) -> 0
A60: =A9 -> L_C14_0 | C60: =IF(C9=0,"0",IF(AND(Results!$C$5="Protein",C$51>0,OR(Results!$C$4="Tissue",Results!$C$4="Cells")),((C9)/(C$3*C$51)),IF(AND(Results!$C$5="Weight",C$50>0,Results!$C$4="Tissue"),((C9)/(C$3*C$50)),IF(AND(Results!$C$5="Volume",C$52>0,Results!$C$4="Fluid"),((C9)/(C$3*C$52)),IF(AND(Results!$C$4="Cells",Results!$C$5="Million"),((C9)/(C$3*C$50)),"-"))))) -> 0 | D60: =IF(D9=0,"0",IF(AND(Results!$C$5="Protein",D$51>0,OR(Results!$C$4="Tissue",Results!$C$4="Cells")),((D9)/(D$3*D$51)),IF(AND(Results!$C$5="Weight",D$50>0,Results!$C$4="Tissue"),((D9)/(D$3*D$50)),IF(AND(Results!$C$5="Volume",D$52>0,Results!$C$4="Fluid"),((D9)/(D$3*D$52)),IF(AND(Results!$C$4="Cells",Results!$C$5="Million"),((D9)/(D$3*D$50)),"-"))))) -> 0 | E60: =IF(E9=0,"0",IF(AND(Results!$C$5="Protein",E$51>0,OR(Results!$C$4="Tissue",Results!$C$4="Cells")),((E9)/(E$3*E$51)),IF(AND(Results!$C$5="Weight",E$50>0,Results!$C$4="Tissue"),((E9)/(E$3*E$50)),IF(AND(Results!$C$5="Volume",E$52>0,Results!$C$4="Fluid"),((E9)/(E$3*E$52)),IF(AND(Results!$C$4="Cells",Results!$C$5="Million"),((E9)/(E$3*E$50)),"-"))))) -> 0 | F60: =IF(F9=0,"0",IF(AND(Results!$C$5="Protein",F$51>0,OR(Results!$C$4="Tissue",Results!$C$4="Cells")),((F9)/(F$3*F$51)),IF(AND(Results!$C$5="Weight",F$50>0,Results!$C$4="Tissue"),((F9)/(F$3*F$50)),IF(AND(Results!$C$5="Volume",F$52>0,Results!$C$4="Fluid"),((F9)/(F$3*F$52)),IF(AND(Results!$C$4="Cells",Results!$C$5="Million"),((F9)/(F$3*F$50)),"-"))))) -> 0 | G60: =IF(G9=0,"0",IF(AND(Results!$C$5="Protein",G$51>0,OR(Results!$C$4="Tissue",Results!$C$4="Cells")),((G9)/(G$3*G$51)),IF(AND(Results!$C$5="Weight",G$50>0,Results!$C$4="Tissue"),((G9)/(G$3*G$50)),IF(AND(Results!$C$5="Volume",G$52>0,Results!$C$4="Fluid"),((G9)/(G$3*G$52)),IF(AND(Results!$C$4="Cells",Results!$C$5="Million"),((G9)/(G$3*G$50)),"-"))))) -> 0 | H60: =IF(H9=0,"0",IF(AND(Results!$C$5="Protein",H$51>0,OR(Results!$C$4="Tissue",Results!$C$4="Cells")),((H9)/(H$3*H$51)),IF(AND(Results!$C$5="Weight",H$50>0,Results!$C$4="Tissue"),((H9)/(H$3*H$50)),IF(AND(Results!$C$5="Volume",H$52>0,Results!$C$4="Fluid"),((H9)/(H$3*H$52)),IF(AND(Results!$C$4="Cells",Results!$C$5="Million"),((H9)/(H$3*H$50)),"-"))))) -> 0 | I60: =IF(I9=0,"0",IF(AND(Results!$C$5="Protein",I$51>0,OR(Results!$C$4="Tissue",Results!$C$4="Cells")),((I9)/(I$3*I$51)),IF(AND(Results!$C$5="Weight",I$50>0,Results!$C$4="Tissue"),((I9)/(I$3*I$50)),IF(AND(Results!$C$5="Volume",I$52>0,Results!$C$4="Fluid"),((I9)/(I$3*I$52)),IF(AND(Results!$C$4="Cells",Results!$C$5="Million"),((I9)/(I$3*I$50)),"-"))))) -> 0 | J60: =IF(J9=0,"0",IF(AND(Results!$C$5="Protein",J$51>0,OR(Results!$C$4="Tissue",Results!$C$4="Cells")),((J9)/(J$3*J$51)),IF(AND(Results!$C$5="Weight",J$50>0,Results!$C$4="Tissue"),((J9)/(J$3*J$50)),IF(AND(Results!$C$5="Volume",J$52>0,Results!$C$4="Fluid"),((J9)/(J$3*J$52)),IF(AND(Results!$C$4="Cells",Results!$C$5="Million"),((J9)/(J$3*J$50)),"-"))))) -> 0 | ... V60: =IF(V9=0,"0",IF(AND(Results!$C$5="Protein",V$51>0,OR(Results!$C$4="Tissue",Results!$C$4="Cells")),((V9)/(V$3*V$51)),IF(AND(Results!$C$5="Weight",V$50>0,Results!$C$4="Tissue"),((V9)/(V$3*V$50)),IF(AND(Results!$C$5="Volume",V$52>0,Results!$C$4="Fluid"),((V9)/(V$3*V$52)),IF(AND(Results!$C$4="Cells",Results!$C$5="Million"),((V9)/(V$3*V$50)),"-"))))) -> 0
A61: =A10 -> L_C15_0 | C61: =IF(C10=0,"0",IF(AND(Results!$C$5="Protein",C$51>0,OR(Results!$C$4="Tissue",Results!$C$4="Cells")),((C10)/(C$3*C$51)),IF(AND(Results!$C$5="Weight",C$50>0,Results!$C$4="Tissue"),((C10)/(C$3*C$50)),IF(AND(Results!$C$5="Volume",C$52>0,Results!$C$4="Fluid"),((C10)/(C$3*C$52)),IF(AND(Results!$C$4="Cells",Results!$C$5="Million"),((C10)/(C$3*C$50)),"-"))))) -> 0 | D61: =IF(D10=0,"0",IF(AND(Results!$C$5="Protein",D$51>0,OR(Results!$C$4="Tissue",Results!$C$4="Cells")),((D10)/(D$3*D$51)),IF(AND(Results!$C$5="Weight",D$50>0,Results!$C$4="Tissue"),((D10)/(D$3*D$50)),IF(AND(Results!$C$5="Volume",D$52>0,Results!$C$4="Fluid"),((D10)/(D$3*D$52)),IF(AND(Results!$C$4="Cells",Results!$C$5="Million"),((D10)/(D$3*D$50)),"-"))))) -> 0 | E61: =IF(E10=0,"0",IF(AND(Results!$C$5="Protein",E$51>0,OR(Results!$C$4="Tissue",Results!$C$4="Cells")),((E10)/(E$3*E$51)),IF(AND(Results!$C$5="Weight",E$50>0,Results!$C$4="Tissue"),((E10)/(E$3*E$50)),IF(AND(Results!$C$5="Volume",E$52>0,Results!$C$4="Fluid"),((E10)/(E$3*E$52)),IF(AND(Results!$C$4="Cells",Results!$C$5="Million"),((E10)/(E$3*E$50)),"-"))))) -> 0 | F61: =IF(F10=0,"0",IF(AND(Results!$C$5="Protein",F$51>0,OR(Results!$C$4="Tissue",Results!$C$4="Cells")),((F10)/(F$3*F$51)),IF(AND(Results!$C$5="Weight",F$50>0,Results!$C$4="Tissue"),((F10)/(F$3*F$50)),IF(AND(Results!$C$5="Volume",F$52>0,Results!$C$4="Fluid"),((F10)/(F$3*F$52)),IF(AND(Results!$C$4="Cells",Results!$C$5="Million"),((F10)/(F$3*F$50)),"-"))))) -> 0 | G61: =IF(G10=0,"0",IF(AND(Results!$C$5="Protein",G$51>0,OR(Results!$C$4="Tissue",Results!$C$4="Cells")),((G10)/(G$3*G$51)),IF(AND(Results!$C$5="Weight",G$50>0,Results!$C$4="Tissue"),((G10)/(G$3*G$50)),IF(AND(Results!$C$5="Volume",G$52>0,Results!$C$4="Fluid"),((G10)/(G$3*G$52)),IF(AND(Results!$C$4="Cells",Results!$C$5="Million"),((G10)/(G$3*G$50)),"-"))))) -> 0 | H61: =IF(H10=0,"0",IF(AND(Results!$C$5="Protein",H$51>0,OR(Results!$C$4="Tissue",Results!$C$4="Cells")),((H10)/(H$3*H$51)),IF(AND(Results!$C$5="Weight",H$50>0,Results!$C$4="Tissue"),((H10)/(H$3*H$50)),IF(AND(Results!$C$5="Volume",H$52>0,Results!$C$4="Fluid"),((H10)/(H$3*H$52)),IF(AND(Results!$C$4="Cells",Results!$C$5="Million"),((H10)/(H$3*H$50)),"-"))))) -> 0 | I61: =IF(I10=0,"0",IF(AND(Results!$C$5="Protein",I$51>0,OR(Results!$C$4="Tissue",Results!$C$4="Cells")),((I10)/(I$3*I$51)),IF(AND(Results!$C$5="Weight",I$50>0,Results!$C$4="Tissue"),((I10)/(I$3*I$50)),IF(AND(Results!$C$5="Volume",I$52>0,Results!$C$4="Fluid"),((I10)/(I$3*I$52)),IF(AND(Results!$C$4="Cells",Results!$C$5="Million"),((I10)/(I$3*I$50)),"-"))))) -> 0 | J61: =IF(J10=0,"0",IF(AND(Results!$C$5="Protein",J$51>0,OR(Results!$C$4="Tissue",Results!$C$4="Cells")),((J10)/(J$3*J$51)),IF(AND(Results!$C$5="Weight",J$50>0,Results!$C$4="Tissue"),((J10)/(J$3*J$50)),IF(AND(Results!$C$5="Volume",J$52>0,Results!$C$4="Fluid"),((J10)/(J$3*J$52)),IF(AND(Results!$C$4="Cells",Results!$C$5="Million"),((J10)/(J$3*J$50)),"-"))))) -> 0 | ... V61: =IF(V10=0,"0",IF(AND(Results!$C$5="Protein",V$51>0,OR(Results!$C$4="Tissue",Results!$C$4="Cells")),((V10)/(V$3*V$51)),IF(AND(Results!$C$5="Weight",V$50>0,Results!$C$4="Tissue"),((V10)/(V$3*V$50)),IF(AND(Results!$C$5="Volume",V$52>0,Results!$C$4="Fluid"),((V10)/(V$3*V$52)),IF(AND(Results!$C$4="Cells",Results!$C$5="Million"),((V10)/(V$3*V$50)),"-"))))) -> 0
A62: =A11 -> L_C16_0 | C62: =IF(C11=0,"0",IF(AND(Results!$C$5="Protein",C$51>0,OR(Results!$C$4="Tissue",Results!$C$4="Cells")),((C11)/(C$3*C$51)),IF(AND(Results!$C$5="Weight",C$50>0,Results!$C$4="Tissue"),((C11)/(C$3*C$50)),IF(AND(Results!$C$5="Volume",C$52>0,Results!$C$4="Fluid"),((C11)/(C$3*C$52)),IF(AND(Results!$C$4="Cells",Results!$C$5="Million"),((C11)/(C$3*C$50)),"-"))))) -> 1.0224435 | D62: =IF(D11=0,"0",IF(AND(Results!$C$5="Protein",D$51>0,OR(Results!$C$4="Tissue",Results!$C$4="Cells")),((D11)/(D$3*D$51)),IF(AND(Results!$C$5="Weight",D$50>0,Results!$C$4="Tissue"),((D11)/(D$3*D$50)),IF(AND(Results!$C$5="Volume",D$52>0,Results!$C$4="Fluid"),((D11)/(D$3*D$52)),IF(AND(Results!$C$4="Cells",Results!$C$5="Million"),((D11)/(D$3*D$50)),"-"))))) -> 1.7818262 | E62: =IF(E11=0,"0",IF(AND(Results!$C$5="Protein",E$51>0,OR(Results!$C$4="Tissue",Results!$C$4="Cells")),((E11)/(E$3*E$51)),IF(AND(Results!$C$5="Weight",E$50>0,Results!$C$4="Tissue"),((E11)/(E$3*E$50)),IF(AND(Results!$C$5="Volume",E$52>0,Results!$C$4="Fluid"),((E11)/(E$3*E$52)),IF(AND(Results!$C$4="Cells",Results!$C$5="Million"),((E11)/(E$3*E$50)),"-"))))) -> 1.3584524 | F62: =IF(F11=0,"0",IF(AND(Results!$C$5="Protein",F$51>0,OR(Results!$C$4="Tissue",Results!$C$4="Cells")),((F11)/(F$3*F$51)),IF(AND(Results!$C$5="Weight",F$50>0,Results!$C$4="Tissue"),((F11)/(F$3*F$50)),IF(AND(Results!$C$5="Volume",F$52>0,Results!$C$4="Fluid"),((F11)/(F$3*F$52)),IF(AND(Results!$C$4="Cells",Results!$C$5="Million"),((F11)/(F$3*F$50)),"-"))))) -> 0.92480912 | G62: =IF(G11=0,"0",IF(AND(Results!$C$5="Protein",G$51>0,OR(Results!$C$4="Tissue",Results!$C$4="Cells")),((G11)/(G$3*G$51)),IF(AND(Results!$C$5="Weight",G$50>0,Results!$C$4="Tissue"),((G11)/(G$3*G$50)),IF(AND(Results!$C$5="Volume",G$52>0,Results!$C$4="Fluid"),((G11)/(G$3*G$52)),IF(AND(Results!$C$4="Cells",Results!$C$5="Million"),((G11)/(G$3*G$50)),"-"))))) -> 1.4075237 | H62: =IF(H11=0,"0",IF(AND(Results!$C$5="Protein",H$51>0,OR(Results!$C$4="Tissue",Results!$C$4="Cells")),((H11)/(H$3*H$51)),IF(AND(Results!$C$5="Weight",H$50>0,Results!$C$4="Tissue"),((H11)/(H$3*H$50)),IF(AND(Results!$C$5="Volume",H$52>0,Results!$C$4="Fluid"),((H11)/(H$3*H$52)),IF(AND(Results!$C$4="Cells",Results!$C$5="Million"),((H11)/(H$3*H$50)),"-"))))) -> 1.2741509 | I62: =IF(I11=0,"0",IF(AND(Results!$C$5="Protein",I$51>0,OR(Results!$C$4="Tissue",Results!$C$4="Cells")),((I11)/(I$3*I$51)),IF(AND(Results!$C$5="Weight",I$50>0,Results!$C$4="Tissue"),((I11)/(I$3*I$50)),IF(AND(Results!$C$5="Volume",I$52>0,Results!$C$4="Fluid"),((I11)/(I$3*I$52)),IF(AND(Results!$C$4="Cells",Results!$C$5="Million"),((I11)/(I$3*I$50)),"-"))))) -> 0.93472467 | J62: =IF(J11=0,"0",IF(AND(Results!$C$5="Protein",J$51>0,OR(Results!$C$4="Tissue",Results!$C$4="Cells")),((J11)/(J$3*J$51)),IF(AND(Results!$C$5="Weight",J$50>0,Results!$C$4="Tissue"),((J11)/(J$3*J$50)),IF(AND(Results!$C$5="Volume",J$52>0,Results!$C$4="Fluid"),((J11)/(J$3*J$52)),IF(AND(Results!$C$4="Cells",Results!$C$5="Million"),((J11)/(J$3*J$50)),"-"))))) -> 1.0449621 | ... V62: =IF(V11=0,"0",IF(AND(Results!$C$5="Protein",V$51>0,OR(Results!$C$4="Tissue",Results!$C$4="Cells")),((V11)/(V$3*V$51)),IF(AND(Results!$C$5="Weight",V$50>0,Results!$C$4="Tissue"),((V11)/(V$3*V$50)),IF(AND(Results!$C$5="Volume",V$52>0,Results!$C$4="Fluid"),((V11)/(V$3*V$52)),IF(AND(Results!$C$4="Cells",Results!$C$5="Million"),((V11)/(V$3*V$50)),"-"))))) -> 1.4611696
A63: =A12 -> L_C19_0
A64: =A13 -> L_C18_0 | C64: =IF(C13=0,"0",IF(AND(Results!$C$5="Protein",C$51>0,OR(Results!$C$4="Tissue",Results!$C$4="Cells")),((C13)/(C$3*C$51)),IF(AND(Results!$C$5="Weight",C$50>0,Results!$C$4="Tissue"),((C13)/(C$3*C$50)),IF(AND(Results!$C$5="Volume",C$52>0,Results!$C$4="Fluid"),((C13)/(C$3*C$52)),IF(AND(Results!$C$4="Cells",Results!$C$5="Million"),((C13)/(C$3*C$50)),"-"))))) -> 0.48084558 | D64: =IF(D13=0,"0",IF(AND(Results!$C$5="Protein",D$51>0,OR(Results!$C$4="Tissue",Results!$C$4="Cells")),((D13)/(D$3*D$51)),IF(AND(Results!$C$5="Weight",D$50>0,Results!$C$4="Tissue"),((D13)/(D$3*D$50)),IF(AND(Results!$C$5="Volume",D$52>0,Results!$C$4="Fluid"),((D13)/(D$3*D$52)),IF(AND(Results!$C$4="Cells",Results!$C$5="Million"),((D13)/(D$3*D$50)),"-"))))) -> 0.35913831 | E64: =IF(E13=0,"0",IF(AND(Results!$C$5="Protein",E$51>0,OR(Results!$C$4="Tissue",Results!$C$4="Cells")),((E13)/(E$3*E$51)),IF(AND(Results!$C$5="Weight",E$50>0,Results!$C$4="Tissue"),((E13)/(E$3*E$50)),IF(AND(Results!$C$5="Volume",E$52>0,Results!$C$4="Fluid"),((E13)/(E$3*E$52)),IF(AND(Results!$C$4="Cells",Results!$C$5="Million"),((E13)/(E$3*E$50)),"-"))))) -> 0.59508403 | F64: =IF(F13=0,"0",IF(AND(Results!$C$5="Protein",F$51>0,OR(Results!$C$4="Tissue",Results!$C$4="Cells")),((F13)/(F$3*F$51)),IF(AND(Results!$C$5="Weight",F$50>0,Results!$C$4="Tissue"),((F13)/(F$3*F$50)),IF(AND(Results!$C$5="Volume",F$52>0,Results!$C$4="Fluid"),((F13)/(F$3*F$52)),IF(AND(Results!$C$4="Cells",Results!$C$5="Million"),((F13)/(F$3*F$50)),"-"))))) -> 0.48738895 | G64: =IF(G13=0,"0",IF(AND(Results!$C$5="Protein",G$51>0,OR(Results!$C$4="Tissue",Results!$C$4="Cells")),((G13)/(G$3*G$51)),IF(AND(Results!$C$5="Weight",G$50>0,Results!$C$4="Tissue"),((G13)/(G$3*G$50)),IF(AND(Results!$C$5="Volume",G$52>0,Results!$C$4="Fluid"),((G13)/(G$3*G$52)),IF(AND(Results!$C$4="Cells",Results!$C$5="Million"),((G13)/(G$3*G$50)),"-"))))) -> 0.53519076 | H64: =IF(H13=0,"0",IF(AND(Results!$C$5="Protein",H$51>0,OR(Results!$C$4="Tissue",Results!$C$4="Cells")),((H13)/(H$3*H$51)),IF(AND(Results!$C$5="Weight",H$50>0,Results!$C$4="Tissue"),((H13)/(H$3*H$50)),IF(AND(Results!$C$5="Volume",H$52>0,Results!$C$4="Fluid"),((H13)/(H$3*H$52)),IF(AND(Results!$C$4="Cells",Results!$C$5="Million"),((H13)/(H$3*H$50)),"-"))))) -> 0.5110065 | I64: =IF(I13=0,"0",IF(AND(Results!$C$5="Protein",I$51>0,OR(Results!$C$4="Tissue",Results!$C$4="Cells")),((I13)/(I$3*I$51)),IF(AND(Results!$C$5="Weight",I$50>0,Results!$C$4="Tissue"),((I13)/(I$3*I$50)),IF(AND(Results!$C$5="Volume",I$52>0,Results!$C$4="Fluid"),((I13)/(I$3*I$52)),IF(AND(Results!$C$4="Cells",Results!$C$5="Million"),((I13)/(I$3*I$50)),"-"))))) -> 0.42405702 | J64: =IF(J13=0,"0",IF(AND(Results!$C$5="Protein",J$51>0,OR(Results!$C$4="Tissue",Results!$C$4="Cells")),((J13)/(J$3*J$51)),IF(AND(Results!$C$5="Weight",J$50>0,Results!$C$4="Tissue"),((J13)/(J$3*J$50)),IF(AND(Results!$C$5="Volume",J$52>0,Results!$C$4="Fluid"),((J13)/(J$3*J$52)),IF(AND(Results!$C$4="Cells",Results!$C$5="Million"),((J13)/(J$3*J$50)),"-"))))) -> 0.3644264 | ... V64: =IF(V13=0,"0",IF(AND(Results!$C$5="Protein",V$51>0,OR(Results!$C$4="Tissue",Results!$C$4="Cells")),((V13)/(V$3*V$51)),IF(AND(Results!$C$5="Weight",V$50>0,Results!$C$4="Tissue"),((V13)/(V$3*V$50)),IF(AND(Results!$C$5="Volume",V$52>0,Results!$C$4="Fluid"),((V13)/(V$3*V$52)),IF(AND(Results!$C$4="Cells",Results!$C$5="Million"),((V13)/(V$3*V$50)),"-"))))) -> 0.531345
...

Sheet Identifiants
B1: CHEBI | C1: InChiKEY | D1: InChi
A2: L_C8_0 | B2: 28837 | C2: WWZKQHOCKIZLMA-UHFFFAOYSA-N | D2: InChI=1S/C8H16O2/c1-2-3-4-5-6-7-8(9)10/h2-7H2,1H3,(H,9,10)
A3: L_C10_0 | B3: 30813 | C3: GHVNFZFCNZKVNT-UHFFFAOYSA-N | D3: InChI=1S/C10H20O2/c1-2-3-4-5-6-7-8-9-10(11)12/h2-9H2,1H3,(H,11,12)
A4: L_C11_0 | B4: 32368 | C4: ZDPHROOEEOARMN-UHFFFAOYSA-N | D4: InChI=1S/C11H22O2/c1-2-3-4-5-6-7-8-9-10-11(12)13/h2-10H2,1H3,(H,12,13)
A5: L_C12_0 | B5: 30805 | C5: POULHZVOKOAJMA-UHFFFAOYSA-N | D5: InChI=1S/C12H24O2/c1-2-3-4-5-6-7-8-9-10-11-12(13)14/h2-11H2,1H3,(H,13,14)
A6: L_C13_0 | B6: 45919 | C6: SZHOJFHSIKHZHA-UHFFFAOYSA-N | D6: InChI=1S/C13H26O2/c1-2-3-4-5-6-7-8-9-10-11-12-13(14)15/h2-12H2,1H3,(H,14,15)
A7: L_C14_0 | B7: 28875 | C7: TUNFSRHWOTWDNC-UHFFFAOYSA-N | D7: InChI=1S/C14H28O2/c1-2-3-4-5-6-7-8-9-10-11-12-13-14(15)16/h2-13H2,1H3,(H,15,16)
A8: L_C15_0 | B8: 42504 | C8: WQEPLUUGTLDZJY-UHFFFAOYSA-N | D8: InChI=1S/C15H30O2/c1-2-3-4-5-6-7-8-9-10-11-12-13-14-15(16)17/h2-14H2,1H3,(H,16,17)
A9: L_C16_0 | B9: 15756 | C9: IPCSVZSSVZVIGE-UHFFFAOYSA-N | D9: InChI=1S/C16H32O2/c1-2-3-4-5-6-7-8-9-10-11-12-13-14-15-16(17)18/h2-15H2,1H3,(H,17,18)
A10: L_C17_0 | B10: 32365 | C10: KEMQGTRYUADPNZ-UHFFFAOYSA-N | D10: InChI=1S/C17H34O2/c1-2-3-4-5-6-7-8-9-10-11-12-13-14-15-16-17(18)19/h2-16H2,1H3,(H,18,19)
A11: L_C18_0 | B11: 28842 | C11: QIQXTHQIDYTFRH-UHFFFAOYSA-N | D11: InChI=1S/C18H36O2/c1-2-3-4-5-6-7-8-9-10-11-12-13-14-15-16-17-18(19)20/h2-17H2,1H3,(H,19,20)
A12: L_C19_0 | B12: 39246 | C12: ISYWECDDZWTKFF-UHFFFAOYSA-N | D12: InChI=1S/C19H38O2/c1-2-3-4-5-6-7-8-9-10-11-12-13-14-15-16-17-18-19(20)21/h2-18H2,1H3,(H,20,21)
A13: L_C20_0 | B13: 28822 | C13: VKOBVWXKNCXXDE-UHFFFAOYSA-N | D13: InChI=1S/C20H40O2/c1-2-3-4-5-6-7-8-9-10-11-12-13-14-15-16-17-18-19-20(21)22/h2-19H2,1H3,(H,21,22)
... A18: L_C14_1w7 | B18: 53206 | C18: ZVXDGKJSUPWREP-FPLPWBNLSA-N | D18: InChI=1S/C14H26O2/c1-2-3-4-5-6-7-8-9-10-11-12-13-14(15)16/h7-8H,2-6,9-13H2,1H3,(H,15,16)/b8-7-
A19: L_C15_1w7 | B19: 78634
A20: L_C16_1w9 | B20: 83030 | C20: IVTCJQZAGWTMBZ-LTKCOYKYSA-N | D20: InChI=1S/C16H24O2/c1-2-3-4-5-6-7-8-9-10-11-12-13-14-15-16(17)18/h3-4,6-7,9-10,12-13H,2,5,8,11,14-15H2,1H3,(H,17,18)/b4-3-,7-6-,10-9-,13-12-
A21: L_C16_1w7 | B21: 28716 | C21: SECPZKHBENQXJG-FPLPWBNLSA-N | D21: InChI=1S/C16H30O2/c1-2-3-4-5-6-7-8-9-10-11-12-13-14-15-16(17)18/h7-8H,2-6,9-15H2,1H3,(H,17,18)/b8-7-
A22: L_C17_1 | B22: 140946
A23: L_C18_1w9c | B23: 36021 | C23: EQPPMHVWECSIRJ-UHFFFAOYSA-N | D23: InChI=1S/C18H34O2/c1-2-3-4-5-6-7-8-9-10-11-12-13-14-15-16-17-18(19)20/h9-10H,2-8,11-17H2,1H3,(H,19,20)
A24: L_C18_1w9t | B24: 27997 | C24: EQPPMHVWECSIRJ-MDEDMXLPSA-N | D24: InChI=1S/C18H34O2/c1-2-3-4-5-6-7-8-9-10-11-12-13-14-15-16-17-18(19)20/h9-10H,2-8,11-17H2,1H3,(H,19,20)/b10-9+
A25: L_C18_1w7c | B25: 28727 | C25: UWHZIFQPPBDJPM-BQYQJAHWSA-N | D25: InChI=1S/C18H34O2/c1-2-3-4-5-6-7-8-9-10-11-12-13-14-15-16-17-18(19)20/h7-8H,2-6,9-17H2,1H3,(H,19,20)/b8-7+
A26: L_C20_1w9 | B26: 32425 | C26: BITHHVVYSMSWAG-KTKRTIGZSA-N | D26: InChI=1S/C20H38O2/c1-2-3-4-5-6-7-8-9-10-11-12-13-14-15-16-17-18-19-20(21)22/h9-10H,2-8,11-19H2,1H3,(H,21,22)/b10-9-
A27: L_C22_1w9 | B27: 28792 | C27: DPUOLQHDNGRHBS-KTKRTIGESA-N | D27: InChI=1S/C22H42O2/c1-2-3-4-5-6-7-8-9-10-11-12-13-14-15-16-17-18-19-20-21-22(23)24/h9-10H,2-8,11-21H2,1H3,(H,23,24)/b10-9-
A28: L_C24_1 | B28: 140963
A29: L_C16_2w6 | B29: 132494
A30: L_C16_2w4 | B30: 132494
A31: L_C16_3 | B31: 132499
A32: L_C16_4w3 | B32: 180361 | C32: SBEXLJDCZSJDLW-YSTUJMKBSA-N | D32: InChI=1S/C16H26O2/c1-2-3-4-5-6-7-8-9-10-11-12-13-14-15-16(17)18/h4-5,7-8,10-11H,2-3,6,9,12-15H2,1H3,(H,17,18)/b5-4-,8-7-,11-10-
A33: L_C18_2w6c | B33: 17351 | C33: OYHQOLUKZRVURQ-HZJYTTRNSA-N | D33: InChI=1S/C18H32O2/c1-2-3-4-5-6-7-8-9-10-11-12-13-14-15-16-17-18(19)20/h6-7,9-10H,2-5,8,11-17H2,1H3,(H,19,20)/b7-6-,10-9-
A34: L_C18_2w6t | B34: 44526 | C34: GKJZMAHZJGSBKD-NMMTYZSQSA-N | D34: InChI=1S/C18H32O2/c1-2-3-4-5-6-7-8-9-10-11-12-13-14-15-16-17-18(19)20/h6-9H,2-5,10-17H2,1H3,(H,19,20)/b7-6-,9-8+
A35: L_C18_3w6 | B35: 28661 | C35: VZCCETWTMQHEPK-QNEBEIHSSA-N | D35: InChI=1S/C18H30O2/c1-2-3-4-5-6-7-8-9-10-11-12-13-14-15-16-17-18(19)20/h6-7,9-10,12-13H,2-5,8,11,14-17H2,1H3,(H,19,20)/b7-6-,10-9-,13-12-
A36: L_C18_3w3 | B36: 27432 | C36: DTOSIQBPPRVQHS-PDBXOOCHSA-N | D36: InChI=1S/C18H30O2/c1-2-3-4-5-6-7-8-9-10-11-12-13-14-15-16-17-18(19)20/h3-4,6-7,9-10H,2,5,8,11-17H2,1H3,(H,19,20)/b4-3-,7-6-,10-9-
A37: L_C18_4w3 | B37: 32389 | C37: JIWBIWFOSCKQMA-LTKCOYKYSA-N | D37: InChI=1S/C18H28O2/c1-2-3-4-5-6-7-8-9-10-11-12-13-14-15-16-17-18(19)20/h3-4,6-7,9-10,12-13H,2,5,8,11,14-17H2,1H3,(H,19,20)/b4-3-,7-6-,10-9-,13-12-
A38: L_C20_2w6 | B38: 93415 | C38: XSXIVVECUAHUJO-AVQMFFATSA-N | D38: InChI=1S/C20H36O2/c1-2-3-4-5-6-7-8-9-10-11-12-13-14-15-16-17-18-19-20(21)22/h6-7,9-10H,2-5,8,11-19H2,1H3,(H,21,22)/b7-6+,10-9+
A39: L_C20_3w3 | B39: 53460 | C39: AHANXAKGNAKFSK-IUQGRGSQSA-N | D39: InChI=1S/C20H34O2/c1-2-3-4-5-6-7-8-9-10-11-12-13-14-15-16-17-18-19-20(21)22/h3-4,6-7,9-10H,2,5,8,11-19H2,1H3,(H,21,22)/b4-3+,7-6+,10-9+
A40: L_C20_3w6 | B40: 15843 | C40: YZXBAPSDXZZRGB-DOFZRALJSA-N | D40: InChI=1S/C20H32O2/c1-2-3-4-5-6-7-8-9-10-11-12-13-14-15-16-17-18-19-20(21)22/h6-7,9-10,12-13,15-16H,2-5,8,11,14,17-19H2,1H3,(H,21,22)/b7-6-,10-9-,13-12-,16-15-
A41: L_C20_4w6 | B41: 15843 | C41: YZXBAPSDXZZRGB-DOFZRALJSA-N | D41: InChI=1S/C20H32O2/c1-2-3-4-5-6-7-8-9-10-11-12-13-14-15-16-17-18-19-20(21)22/h6-7,9-10,12-13,15-16H,2-5,8,11,14,17-19H2,1H3,(H,21,22)/b7-6-,10-9-,13-12-,16-15-
A42: L_C20_5w3 | B42: 28364 | C42: JAZBEHYOTPTENJ-JLNKQSITSA-N | D42: InChI=1S/C20H30O2/c1-2-3-4-5-6-7-8-9-10-11-12-13-14-15-16-17-18-19-20(21)22/h3-4,6-7,9-10,12-13,15-16H,2,5,8,11,14,17-19H2,1H3,(H,21,22)/b4-3-,7-6-,10-9-,13-12-,16-15-
A43: L_C22_2w6 | B43: 75117 | C43: HVGREDASOHMCSK-HEJYTTRNSA-N | D43: InChI=1S/C22H40O2/c1-2-3-4-5-6-7-8-9-10-11-12-13-14-15-16-17-18-19-20-21-22(23)24/h6-7,9-10H,2-5,8,11-21H2,1H3,(H,23,24)/b7-6-,10-9-
... A47: L_C22_6w3 | B47: 28125 | C47: MBMBGCFOFBJSGT-KUBAVDMBSA-N | D47: InChI=1S/C22H32O2/c1-2-3-4-5-6-7-8-9-10-11-12-13-14-15-16-17-18-19-20-21-22(23)24/h3-4,6-7,9-10,12-13,15-16,18-19H,2,5,8,11,14,17,20-21H2,1H3,(H,23,24)/b4-3-,7-6-,10-9-,13-12-,16-15-,19-18-
