Workbook

Sheet Results
A2: Analysis reference : | B2: 250528DMI_Oxylipins | D2: ND : | E2: Not detected
A3: Matrix : | B3: plasma | D3: <LLOQ : | E3: Not quantifiable
A4: Normalization | B4: µL of plasma
B6: =CONCATENATE("pg/",Results!B4) -> pg/µL of plasma | C6: ='Raw Datas'!C1 -> JV-015-RAN-IC-M2 | D6: ='Raw Datas'!D1 -> BS-007-RAN-01-M3 | E6: ='Raw Datas'!E1 -> BS-007-RAN-02-M3 | F6: ='Raw Datas'!F1 -> KT-004-SOC-16-M1 | G6: ='Raw Datas'!G1 -> BS-135-RAN-IC-M3 | H6: ='Raw Datas'!H1 -> JV-070-DAV-07-M3 | I6: ='Raw Datas'!I1 -> BS-129-RAT-10-M5 | J6: ='Raw Datas'!J1 -> JV-036-SOC-10-M2 | ... V6: ='Raw Datas'!V1 -> BS-172-RAT-10-M3
B7: 2 | C7: =B7+1 -> 3 | D7: =C7+1 -> 4 | E7: =D7+1 -> 5 | F7: =E7+1 -> 6 | G7: =F7+1 -> 7 | H7: =G7+1 -> 8 | I7: =H7+1 -> 9 | J7: =I7+1 -> 10 | ... V7: =U7+1 -> 22
A8: Linoleic acid C18:2ꙍ6 | B8: 9-HODE | C8: =VLOOKUP($B8,'Raw Datas'!$54:$101,C$7,FALSE) -> 23.767667 | D8: =VLOOKUP($B8,'Raw Datas'!$54:$101,D$7,FALSE) -> 470.97488 | E8: =VLOOKUP($B8,'Raw Datas'!$54:$101,E$7,FALSE) -> 52.089467 | F8: =VLOOKUP($B8,'Raw Datas'!$54:$101,F$7,FALSE) -> 56.172267 | G8: =VLOOKUP($B8,'Raw Datas'!$54:$101,G$7,FALSE) -> 40.300967 | H8: =VLOOKUP($B8,'Raw Datas'!$54:$101,H$7,FALSE) -> 94.776283 | I8: =VLOOKUP($B8,'Raw Datas'!$54:$101,I$7,FALSE) -> 66.713833 | J8: =VLOOKUP($B8,'Raw Datas'!$54:$101,J$7,FALSE) -> 12.680583 | ... V8: =VLOOKUP($B8,'Raw Datas'!$54:$101,V$7,FALSE) -> 41.1596
B9: 10-HODE | C9: =VLOOKUP($B9,'Raw Datas'!$54:$101,C$7,FALSE) -> 0.49258333 | D9: =VLOOKUP($B9,'Raw Datas'!$54:$101,D$7,FALSE) -> 1.5066 | E9: =VLOOKUP($B9,'Raw Datas'!$54:$101,E$7,FALSE) -> 0.64493333 | F9: =VLOOKUP($B9,'Raw Datas'!$54:$101,F$7,FALSE) -> <LLOQ | G9: =VLOOKUP($B9,'Raw Datas'!$54:$101,G$7,FALSE) -> 1.4099 | H9: =VLOOKUP($B9,'Raw Datas'!$54:$101,H$7,FALSE) -> 1.3597167 | I9: =VLOOKUP($B9,'Raw Datas'!$54:$101,I$7,FALSE) -> 0.64701667 | J9: =VLOOKUP($B9,'Raw Datas'!$54:$101,J$7,FALSE) -> 0.57013333 | ... V9: =VLOOKUP($B9,'Raw Datas'!$54:$101,V$7,FALSE) -> 0.98965
B10: 13-HODE | C10: =VLOOKUP($B10,'Raw Datas'!$54:$101,C$7,FALSE) -> 49.344167 | D10: =VLOOKUP($B10,'Raw Datas'!$54:$101,D$7,FALSE) -> 793.39912 | E10: =VLOOKUP($B10,'Raw Datas'!$54:$101,E$7,FALSE) -> 135.64387 | F10: =VLOOKUP($B10,'Raw Datas'!$54:$101,F$7,FALSE) -> 73.57465 | G10: =VLOOKUP($B10,'Raw Datas'!$54:$101,G$7,FALSE) -> 75.6689 | H10: =VLOOKUP($B10,'Raw Datas'!$54:$101,H$7,FALSE) -> 172.18753 | I10: =VLOOKUP($B10,'Raw Datas'!$54:$101,I$7,FALSE) -> 117.66615 | J10: =VLOOKUP($B10,'Raw Datas'!$54:$101,J$7,FALSE) -> 55.648333 | ... V10: =VLOOKUP($B10,'Raw Datas'!$54:$101,V$7,FALSE) -> 94.7032
B11: 9,10-DiHOME | C11: =VLOOKUP($B11,'Raw Datas'!$54:$101,C$7,FALSE) -> 3.6321667 | D11: =VLOOKUP($B11,'Raw Datas'!$54:$101,D$7,FALSE) -> 2.3493333 | E11: =VLOOKUP($B11,'Raw Datas'!$54:$101,E$7,FALSE) -> 6.4661 | F11: =VLOOKUP($B11,'Raw Datas'!$54:$101,F$7,FALSE) -> 2.64495 | G11: =VLOOKUP($B11,'Raw Datas'!$54:$101,G$7,FALSE) -> 10.495367 | H11: =VLOOKUP($B11,'Raw Datas'!$54:$101,H$7,FALSE) -> 8.5081167 | I11: =VLOOKUP($B11,'Raw Datas'!$54:$101,I$7,FALSE) -> 4.5729167 | J11: =VLOOKUP($B11,'Raw Datas'!$54:$101,J$7,FALSE) -> 3.21285 | ... V11: =VLOOKUP($B11,'Raw Datas'!$54:$101,V$7,FALSE) -> 4.4474667
B12: 12,13-DiHOME | C12: =VLOOKUP($B12,'Raw Datas'!$54:$101,C$7,FALSE) -> 3.25425 | D12: =VLOOKUP($B12,'Raw Datas'!$54:$101,D$7,FALSE) -> 2.2259167 | E12: =VLOOKUP($B12,'Raw Datas'!$54:$101,E$7,FALSE) -> 3.6899 | F12: =VLOOKUP($B12,'Raw Datas'!$54:$101,F$7,FALSE) -> 1.5216 | G12: =VLOOKUP($B12,'Raw Datas'!$54:$101,G$7,FALSE) -> 5.69925 | H12: =VLOOKUP($B12,'Raw Datas'!$54:$101,H$7,FALSE) -> 14.611567 | I12: =VLOOKUP($B12,'Raw Datas'!$54:$101,I$7,FALSE) -> 5.0355167 | J12: =VLOOKUP($B12,'Raw Datas'!$54:$101,J$7,FALSE) -> 1.5339167 | ... V12: =VLOOKUP($B12,'Raw Datas'!$54:$101,V$7,FALSE) -> 3.72815
B13: 9-oxoODE | C13: =VLOOKUP($B13,'Raw Datas'!$54:$101,C$7,FALSE) -> 2.9042 | D13: =VLOOKUP($B13,'Raw Datas'!$54:$101,D$7,FALSE) -> 4.1485833 | E13: =VLOOKUP($B13,'Raw Datas'!$54:$101,E$7,FALSE) -> 17.857067 | F13: =VLOOKUP($B13,'Raw Datas'!$54:$101,F$7,FALSE) -> 4.4707667 | G13: =VLOOKUP($B13,'Raw Datas'!$54:$101,G$7,FALSE) -> 3.6334833 | H13: =VLOOKUP($B13,'Raw Datas'!$54:$101,H$7,FALSE) -> 22.385 | I13: =VLOOKUP($B13,'Raw Datas'!$54:$101,I$7,FALSE) -> 9.4824167 | J13: =VLOOKUP($B13,'Raw Datas'!$54:$101,J$7,FALSE) -> 1.6288333 | ... V13: =VLOOKUP($B13,'Raw Datas'!$54:$101,V$7,FALSE) -> 13.815967
B14: 13-oxoODE | C14: =VLOOKUP($B14,'Raw Datas'!$54:$101,C$7,FALSE) -> 4.3696333 | D14: =VLOOKUP($B14,'Raw Datas'!$54:$101,D$7,FALSE) -> 11.315083 | E14: =VLOOKUP($B14,'Raw Datas'!$54:$101,E$7,FALSE) -> 13.622233 | F14: =VLOOKUP($B14,'Raw Datas'!$54:$101,F$7,FALSE) -> 10.850933 | G14: =VLOOKUP($B14,'Raw Datas'!$54:$101,G$7,FALSE) -> 3.0517833 | H14: =VLOOKUP($B14,'Raw Datas'!$54:$101,H$7,FALSE) -> 19.47405 | I14: =VLOOKUP($B14,'Raw Datas'!$54:$101,I$7,FALSE) -> 8.6968333 | J14: =VLOOKUP($B14,'Raw Datas'!$54:$101,J$7,FALSE) -> 2.4885333 | ... V14: =VLOOKUP($B14,'Raw Datas'!$54:$101,V$7,FALSE) -> 10.12915
B15: 10-TriHOME | C15: =VLOOKUP($B15,'Raw Datas'!$54:$101,C$7,FALSE) -> <LLOQ | D15: =VLOOKUP($B15,'Raw Datas'!$54:$101,D$7,FALSE) -> 1.2632833 | E15: =VLOOKUP($B15,'Raw Datas'!$54:$101,E$7,FALSE) -> 1.25455 | F15: =VLOOKUP($B15,'Raw Datas'!$54:$101,F$7,FALSE) -> <LLOQ | G15: =VLOOKUP($B15,'Raw Datas'!$54:$101,G$7,FALSE) -> <LLOQ | H15: =VLOOKUP($B15,'Raw Datas'!$54:$101,H$7,FALSE) -> 1.8998333 | I15: =VLOOKUP($B15,'Raw Datas'!$54:$101,I$7,FALSE) -> 0.81541667 | J15: =VLOOKUP($B15,'Raw Datas'!$54:$101,J$7,FALSE) -> <LLOQ | ... V15: =VLOOKUP($B15,'Raw Datas'!$54:$101,V$7,FALSE) -> 1.47855
B16: 12-TriHOME | C16: =VLOOKUP($B16,'Raw Datas'!$54:$101,C$7,FALSE) -> 0.90468333 | D16: =VLOOKUP($B16,'Raw Datas'!$54:$101,D$7,FALSE) -> 4.7705667 | E16: =VLOOKUP($B16,'Raw Datas'!$54:$101,E$7,FALSE) -> 3.7612667 | F16: =VLOOKUP($B16,'Raw Datas'!$54:$101,F$7,FALSE) -> 0.59415 | G16: =VLOOKUP($B16,'Raw Datas'!$54:$101,G$7,FALSE) -> 1.6397667 | H16: =VLOOKUP($B16,'Raw Datas'!$54:$101,H$7,FALSE) -> 9.02745 | I16: =VLOOKUP($B16,'Raw Datas'!$54:$101,I$7,FALSE) -> 2.0149667 | J16: =VLOOKUP($B16,'Raw Datas'!$54:$101,J$7,FALSE) -> 1.1283 | ... V16: =VLOOKUP($B16,'Raw Datas'!$54:$101,V$7,FALSE) -> 4.3740333
A18: Dihomo-gamma-linoleic acid C20:3ꙍ6 | B18: PGA1 | C18: =VLOOKUP($B18,'Raw Datas'!$54:$101,C$7,FALSE) -> ND | D18: =VLOOKUP($B18,'Raw Datas'!$54:$101,D$7,FALSE) -> ND | E18: =VLOOKUP($B18,'Raw Datas'!$54:$101,E$7,FALSE) -> ND | F18: =VLOOKUP($B18,'Raw Datas'!$54:$101,F$7,FALSE) -> ND | G18: =VLOOKUP($B18,'Raw Datas'!$54:$101,G$7,FALSE) -> ND | H18: =VLOOKUP($B18,'Raw Datas'!$54:$101,H$7,FALSE) -> ND | I18: =VLOOKUP($B18,'Raw Datas'!$54:$101,I$7,FALSE) -> ND | J18: =VLOOKUP($B18,'Raw Datas'!$54:$101,J$7,FALSE) -> ND | ... V18: =VLOOKUP($B18,'Raw Datas'!$54:$101,V$7,FALSE) -> ND
A20: Arachidonic acid C20:4ꙍ6 | B20: 5,6-EET | C20: =VLOOKUP($B20,'Raw Datas'!$54:$101,C$7,FALSE) -> ND | D20: =VLOOKUP($B20,'Raw Datas'!$54:$101,D$7,FALSE) -> ND | E20: =VLOOKUP($B20,'Raw Datas'!$54:$101,E$7,FALSE) -> ND | F20: =VLOOKUP($B20,'Raw Datas'!$54:$101,F$7,FALSE) -> ND | G20: =VLOOKUP($B20,'Raw Datas'!$54:$101,G$7,FALSE) -> ND | H20: =VLOOKUP($B20,'Raw Datas'!$54:$101,H$7,FALSE) -> ND | I20: =VLOOKUP($B20,'Raw Datas'!$54:$101,I$7,FALSE) -> ND | J20: =VLOOKUP($B20,'Raw Datas'!$54:$101,J$7,FALSE) -> ND | ... V20: =VLOOKUP($B20,'Raw Datas'!$54:$101,V$7,FALSE) -> ND
B21: 8,9-EET | C21: =VLOOKUP($B21,'Raw Datas'!$54:$101,C$7,FALSE) -> ND | D21: =VLOOKUP($B21,'Raw Datas'!$54:$101,D$7,FALSE) -> ND | E21: =VLOOKUP($B21,'Raw Datas'!$54:$101,E$7,FALSE) -> ND | F21: =VLOOKUP($B21,'Raw Datas'!$54:$101,F$7,FALSE) -> ND | G21: =VLOOKUP($B21,'Raw Datas'!$54:$101,G$7,FALSE) -> ND | H21: =VLOOKUP($B21,'Raw Datas'!$54:$101,H$7,FALSE) -> ND | I21: =VLOOKUP($B21,'Raw Datas'!$54:$101,I$7,FALSE) -> ND | J21: =VLOOKUP($B21,'Raw Datas'!$54:$101,J$7,FALSE) -> ND | ... V21: =VLOOKUP($B21,'Raw Datas'!$54:$101,V$7,FALSE) -> ND
B22: 11,12-EET | C22: =VLOOKUP($B22,'Raw Datas'!$54:$101,C$7,FALSE) -> ND | D22: =VLOOKUP($B22,'Raw Datas'!$54:$101,D$7,FALSE) -> ND | E22: =VLOOKUP($B22,'Raw Datas'!$54:$101,E$7,FALSE) -> ND | F22: =VLOOKUP($B22,'Raw Datas'!$54:$101,F$7,FALSE) -> ND | G22: =VLOOKUP($B22,'Raw Datas'!$54:$101,G$7,FALSE) -> ND | H22: =VLOOKUP($B22,'Raw Datas'!$54:$101,H$7,FALSE) -> ND | I22: =VLOOKUP($B22,'Raw Datas'!$54:$101,I$7,FALSE) -> ND | J22: =VLOOKUP($B22,'Raw Datas'!$54:$101,J$7,FALSE) -> ND | ... V22: =VLOOKUP($B22,'Raw Datas'!$54:$101,V$7,FALSE) -> ND
B23: 14,15-EET | C23: =VLOOKUP($B23,'Raw Datas'!$54:$101,C$7,FALSE) -> ND | D23: =VLOOKUP($B23,'Raw Datas'!$54:$101,D$7,FALSE) -> ND | E23: =VLOOKUP($B23,'Raw Datas'!$54:$101,E$7,FALSE) -> ND | F23: =VLOOKUP($B23,'Raw Datas'!$54:$101,F$7,FALSE) -> ND | G23: =VLOOKUP($B23,'Raw Datas'!$54:$101,G$7,FALSE) -> ND | H23: =VLOOKUP($B23,'Raw Datas'!$54:$101,H$7,FALSE) -> ND | I23: =VLOOKUP($B23,'Raw Datas'!$54:$101,I$7,FALSE) -> ND | J23: =VLOOKUP($B23,'Raw Datas'!$54:$101,J$7,FALSE) -> ND | ... V23: =VLOOKUP($B23,'Raw Datas'!$54:$101,V$7,FALSE) -> ND
B24: 5-HETE | C24: =VLOOKUP($B24,'Raw Datas'!$54:$101,C$7,FALSE) -> 152.71015 | D24: =VLOOKUP($B24,'Raw Datas'!$54:$101,D$7,FALSE) -> 1797.9208 | E24: =VLOOKUP($B24,'Raw Datas'!$54:$101,E$7,FALSE) -> 101.77235 | F24: =VLOOKUP($B24,'Raw Datas'!$54:$101,F$7,FALSE) -> 418.5385 | G24: =VLOOKUP($B24,'Raw Datas'!$54:$101,G$7,FALSE) -> 97.386783 | H24: =VLOOKUP($B24,'Raw Datas'!$54:$101,H$7,FALSE) -> 17.393117 | I24: =VLOOKUP($B24,'Raw Datas'!$54:$101,I$7,FALSE) -> 245.20773 | J24: =VLOOKUP($B24,'Raw Datas'!$54:$101,J$7,FALSE) -> 66.736067 | ... V24: =VLOOKUP($B24,'Raw Datas'!$54:$101,V$7,FALSE) -> 93.991517
B25: 8-HETE | C25: =VLOOKUP($B25,'Raw Datas'!$54:$101,C$7,FALSE) -> 4.265 | D25: =VLOOKUP($B25,'Raw Datas'!$54:$101,D$7,FALSE) -> 157.49808 | E25: =VLOOKUP($B25,'Raw Datas'!$54:$101,E$7,FALSE) -> 5.9803333 | F25: =VLOOKUP($B25,'Raw Datas'!$54:$101,F$7,FALSE) -> 18.417767 | G25: =VLOOKUP($B25,'Raw Datas'!$54:$101,G$7,FALSE) -> 7.5383667 | H25: =VLOOKUP($B25,'Raw Datas'!$54:$101,H$7,FALSE) -> 4.9613333 | I25: =VLOOKUP($B25,'Raw Datas'!$54:$101,I$7,FALSE) -> 8.6435667 | J25: =VLOOKUP($B25,'Raw Datas'!$54:$101,J$7,FALSE) -> 3.6496833 | ... V25: =VLOOKUP($B25,'Raw Datas'!$54:$101,V$7,FALSE) -> 7.3323333
B26: 12-HETE | C26: =VLOOKUP($B26,'Raw Datas'!$54:$101,C$7,FALSE) -> 90.227317 | D26: =VLOOKUP($B26,'Raw Datas'!$54:$101,D$7,FALSE) -> 827.11072 | E26: =VLOOKUP($B26,'Raw Datas'!$54:$101,E$7,FALSE) -> 441.80365 | F26: =VLOOKUP($B26,'Raw Datas'!$54:$101,F$7,FALSE) -> 127.32325 | G26: =VLOOKUP($B26,'Raw Datas'!$54:$101,G$7,FALSE) -> 398.592 | H26: =VLOOKUP($B26,'Raw Datas'!$54:$101,H$7,FALSE) -> 434.7356 | I26: =VLOOKUP($B26,'Raw Datas'!$54:$101,I$7,FALSE) -> 268.21135 | J26: =VLOOKUP($B26,'Raw Datas'!$54:$101,J$7,FALSE) -> 199.73115 | ... V26: =VLOOKUP($B26,'Raw Datas'!$54:$101,V$7,FALSE) -> 541.46735
B27: 15-HETE | C27: =VLOOKUP($B27,'Raw Datas'!$54:$101,C$7,FALSE) -> 6.7071 | D27: =VLOOKUP($B27,'Raw Datas'!$54:$101,D$7,FALSE) -> 311.41932 | E27: =VLOOKUP($B27,'Raw Datas'!$54:$101,E$7,FALSE) -> 10.191233 | F27: =VLOOKUP($B27,'Raw Datas'!$54:$101,F$7,FALSE) -> 20.330717 | G27: =VLOOKUP($B27,'Raw Datas'!$54:$101,G$7,FALSE) -> 17.451 | H27: =VLOOKUP($B27,'Raw Datas'!$54:$101,H$7,FALSE) -> 10.967467 | I27: =VLOOKUP($B27,'Raw Datas'!$54:$101,I$7,FALSE) -> 14.669933 | J27: =VLOOKUP($B27,'Raw Datas'!$54:$101,J$7,FALSE) -> 8.5482333 | ... V27: =VLOOKUP($B27,'Raw Datas'!$54:$101,V$7,FALSE) -> 14.750683
B28: 5oxoETE | C28: =VLOOKUP($B28,'Raw Datas'!$54:$101,C$7,FALSE) -> ND | D28: =VLOOKUP($B28,'Raw Datas'!$54:$101,D$7,FALSE) -> ND | E28: =VLOOKUP($B28,'Raw Datas'!$54:$101,E$7,FALSE) -> ND | F28: =VLOOKUP($B28,'Raw Datas'!$54:$101,F$7,FALSE) -> ND | G28: =VLOOKUP($B28,'Raw Datas'!$54:$101,G$7,FALSE) -> ND | H28: =VLOOKUP($B28,'Raw Datas'!$54:$101,H$7,FALSE) -> ND | I28: =VLOOKUP($B28,'Raw Datas'!$54:$101,I$7,FALSE) -> ND | J28: =VLOOKUP($B28,'Raw Datas'!$54:$101,J$7,FALSE) -> ND | ... V28: =VLOOKUP($B28,'Raw Datas'!$54:$101,V$7,FALSE) -> ND
B29: LTB4 | C29: =VLOOKUP($B29,'Raw Datas'!$54:$101,C$7,FALSE) -> 2.7961333 | D29: =VLOOKUP($B29,'Raw Datas'!$54:$101,D$7,FALSE) -> 88.758683 | E29: =VLOOKUP($B29,'Raw Datas'!$54:$101,E$7,FALSE) -> 1.27205 | F29: =VLOOKUP($B29,'Raw Datas'!$54:$101,F$7,FALSE) -> 12.331933 | G29: =VLOOKUP($B29,'Raw Datas'!$54:$101,G$7,FALSE) -> 0.7804 | H29: =VLOOKUP($B29,'Raw Datas'!$54:$101,H$7,FALSE) -> 0.50225 | I29: =VLOOKUP($B29,'Raw Datas'!$54:$101,I$7,FALSE) -> 3.6323167 | J29: =VLOOKUP($B29,'Raw Datas'!$54:$101,J$7,FALSE) -> 1.037 | ... V29: =VLOOKUP($B29,'Raw Datas'!$54:$101,V$7,FALSE) -> 2.0367167
B30: LxA4 | C30: =VLOOKUP($B30,'Raw Datas'!$54:$101,C$7,FALSE) -> 1.97845 | D30: =VLOOKUP($B30,'Raw Datas'!$54:$101,D$7,FALSE) -> 27.089933 | E30: =VLOOKUP($B30,'Raw Datas'!$54:$101,E$7,FALSE) -> 1.20145 | F30: =VLOOKUP($B30,'Raw Datas'!$54:$101,F$7,FALSE) -> 5.1018667 | G30: =VLOOKUP($B30,'Raw Datas'!$54:$101,G$7,FALSE) -> 0.70056667 | H30: =VLOOKUP($B30,'Raw Datas'!$54:$101,H$7,FALSE) -> <LLOQ | I30: =VLOOKUP($B30,'Raw Datas'!$54:$101,I$7,FALSE) -> 2.1104667 | J30: =VLOOKUP($B30,'Raw Datas'!$54:$101,J$7,FALSE) -> 0.54208333 | ... V30: =VLOOKUP($B30,'Raw Datas'!$54:$101,V$7,FALSE) -> 1.6565667
B31: LXB4 | C31: =VLOOKUP($B31,'Raw Datas'!$54:$101,C$7,FALSE) -> ND | D31: =VLOOKUP($B31,'Raw Datas'!$54:$101,D$7,FALSE) -> ND | E31: =VLOOKUP($B31,'Raw Datas'!$54:$101,E$7,FALSE) -> ND | F31: =VLOOKUP($B31,'Raw Datas'!$54:$101,F$7,FALSE) -> ND | G31: =VLOOKUP($B31,'Raw Datas'!$54:$101,G$7,FALSE) -> ND | H31: =VLOOKUP($B31,'Raw Datas'!$54:$101,H$7,FALSE) -> ND | I31: =VLOOKUP($B31,'Raw Datas'!$54:$101,I$7,FALSE) -> ND | J31: =VLOOKUP($B31,'Raw Datas'!$54:$101,J$7,FALSE) -> ND | ... V31: =VLOOKUP($B31,'Raw Datas'!$54:$101,V$7,FALSE) -> ND
B32: 8isoPGA2 | C32: =VLOOKUP($B32,'Raw Datas'!$54:$101,C$7,FALSE) -> ND | D32: =VLOOKUP($B32,'Raw Datas'!$54:$101,D$7,FALSE) -> ND | E32: =VLOOKUP($B32,'Raw Datas'!$54:$101,E$7,FALSE) -> ND | F32: =VLOOKUP($B32,'Raw Datas'!$54:$101,F$7,FALSE) -> ND | G32: =VLOOKUP($B32,'Raw Datas'!$54:$101,G$7,FALSE) -> ND | H32: =VLOOKUP($B32,'Raw Datas'!$54:$101,H$7,FALSE) -> ND | I32: =VLOOKUP($B32,'Raw Datas'!$54:$101,I$7,FALSE) -> ND | J32: =VLOOKUP($B32,'Raw Datas'!$54:$101,J$7,FALSE) -> ND | ... V32: =VLOOKUP($B32,'Raw Datas'!$54:$101,V$7,FALSE) -> ND
... B40: TXB2 | C40: =VLOOKUP($B40,'Raw Datas'!$54:$101,C$7,FALSE) -> 1.4546833 | D40: =VLOOKUP($B40,'Raw Datas'!$54:$101,D$7,FALSE) -> 4.7540833 | E40: =VLOOKUP($B40,'Raw Datas'!$54:$101,E$7,FALSE) -> 7.1268667 | F40: =VLOOKUP($B40,'Raw Datas'!$54:$101,F$7,FALSE) -> 5.87205 | G40: =VLOOKUP($B40,'Raw Datas'!$54:$101,G$7,FALSE) -> 7.3161833 | H40: =VLOOKUP($B40,'Raw Datas'!$54:$101,H$7,FALSE) -> 2.6085333 | I40: =VLOOKUP($B40,'Raw Datas'!$54:$101,I$7,FALSE) -> 9.5049667 | J40: =VLOOKUP($B40,'Raw Datas'!$54:$101,J$7,FALSE) -> 6.9988 | ... V40: =VLOOKUP($B40,'Raw Datas'!$54:$101,V$7,FALSE) -> 26.27925
A42: Alpha-linolenic acid C18:3ꙍ3 | B42: 9-HOTrE | C42: =VLOOKUP($B42,'Raw Datas'!$54:$101,C$7,FALSE) -> <LLOQ | D42: =VLOOKUP($B42,'Raw Datas'!$54:$101,D$7,FALSE) -> 4.1621167 | E42: =VLOOKUP($B42,'Raw Datas'!$54:$101,E$7,FALSE) -> 0.52466667 | F42: =VLOOKUP($B42,'Raw Datas'!$54:$101,F$7,FALSE) -> 0.37418333 | G42: =VLOOKUP($B42,'Raw Datas'!$54:$101,G$7,FALSE) -> 0.74183333 | H42: =VLOOKUP($B42,'Raw Datas'!$54:$101,H$7,FALSE) -> 2.3444 | I42: =VLOOKUP($B42,'Raw Datas'!$54:$101,I$7,FALSE) -> 0.99165 | J42: =VLOOKUP($B42,'Raw Datas'!$54:$101,J$7,FALSE) -> <LLOQ | ... V42: =VLOOKUP($B42,'Raw Datas'!$54:$101,V$7,FALSE) -> 0.37901667
B43: 13-HOTrE | C43: =VLOOKUP($B43,'Raw Datas'!$54:$101,C$7,FALSE) -> 0.53488333 | D43: =VLOOKUP($B43,'Raw Datas'!$54:$101,D$7,FALSE) -> 5.5005333 | E43: =VLOOKUP($B43,'Raw Datas'!$54:$101,E$7,FALSE) -> 1.7635167 | F43: =VLOOKUP($B43,'Raw Datas'!$54:$101,F$7,FALSE) -> 0.3827 | G43: =VLOOKUP($B43,'Raw Datas'!$54:$101,G$7,FALSE) -> 0.93591667 | H43: =VLOOKUP($B43,'Raw Datas'!$54:$101,H$7,FALSE) -> 3.4536833 | I43: =VLOOKUP($B43,'Raw Datas'!$54:$101,I$7,FALSE) -> 0.91676667 | J43: =VLOOKUP($B43,'Raw Datas'!$54:$101,J$7,FALSE) -> 0.46706667 | ... V43: =VLOOKUP($B43,'Raw Datas'!$54:$101,V$7,FALSE) -> 0.82546667
A45: Eicosapentaenoic acid C20:5ꙍ3 | B45: 18-HEPE | C45: =VLOOKUP($B45,'Raw Datas'!$54:$101,C$7,FALSE) -> 1.6096833 | D45: =VLOOKUP($B45,'Raw Datas'!$54:$101,D$7,FALSE) -> 36.585767 | E45: =VLOOKUP($B45,'Raw Datas'!$54:$101,E$7,FALSE) -> 1.9542 | F45: =VLOOKUP($B45,'Raw Datas'!$54:$101,F$7,FALSE) -> 4.1008333 | G45: =VLOOKUP($B45,'Raw Datas'!$54:$101,G$7,FALSE) -> 1.8562333 | H45: =VLOOKUP($B45,'Raw Datas'!$54:$101,H$7,FALSE) -> 2.25905 | I45: =VLOOKUP($B45,'Raw Datas'!$54:$101,I$7,FALSE) -> 1.4301333 | J45: =VLOOKUP($B45,'Raw Datas'!$54:$101,J$7,FALSE) -> 1.0706 | ... V45: =VLOOKUP($B45,'Raw Datas'!$54:$101,V$7,FALSE) -> 1.1630833
B46: LTB5 | C46: =VLOOKUP($B46,'Raw Datas'!$54:$101,C$7,FALSE) -> ND | D46: =VLOOKUP($B46,'Raw Datas'!$54:$101,D$7,FALSE) -> ND | E46: =VLOOKUP($B46,'Raw Datas'!$54:$101,E$7,FALSE) -> ND | F46: =VLOOKUP($B46,'Raw Datas'!$54:$101,F$7,FALSE) -> ND | G46: =VLOOKUP($B46,'Raw Datas'!$54:$101,G$7,FALSE) -> ND | H46: =VLOOKUP($B46,'Raw Datas'!$54:$101,H$7,FALSE) -> ND | I46: =VLOOKUP($B46,'Raw Datas'!$54:$101,I$7,FALSE) -> ND | J46: =VLOOKUP($B46,'Raw Datas'!$54:$101,J$7,FALSE) -> ND | ... V46: =VLOOKUP($B46,'Raw Datas'!$54:$101,V$7,FALSE) -> ND
B47: PGE3 | C47: =VLOOKUP($B47,'Raw Datas'!$54:$101,C$7,FALSE) -> ND | D47: =VLOOKUP($B47,'Raw Datas'!$54:$101,D$7,FALSE) -> ND | E47: =VLOOKUP($B47,'Raw Datas'!$54:$101,E$7,FALSE) -> ND | F47: =VLOOKUP($B47,'Raw Datas'!$54:$101,F$7,FALSE) -> ND | G47: =VLOOKUP($B47,'Raw Datas'!$54:$101,G$7,FALSE) -> ND | H47: =VLOOKUP($B47,'Raw Datas'!$54:$101,H$7,FALSE) -> ND | I47: =VLOOKUP($B47,'Raw Datas'!$54:$101,I$7,FALSE) -> ND | J47: =VLOOKUP($B47,'Raw Datas'!$54:$101,J$7,FALSE) -> ND | ... V47: =VLOOKUP($B47,'Raw Datas'!$54:$101,V$7,FALSE) -> ND
B48: RvE1 | C48: =VLOOKUP($B48,'Raw Datas'!$54:$101,C$7,FALSE) -> ND | D48: =VLOOKUP($B48,'Raw Datas'!$54:$101,D$7,FALSE) -> ND | E48: =VLOOKUP($B48,'Raw Datas'!$54:$101,E$7,FALSE) -> ND | F48: =VLOOKUP($B48,'Raw Datas'!$54:$101,F$7,FALSE) -> ND | G48: =VLOOKUP($B48,'Raw Datas'!$54:$101,G$7,FALSE) -> ND | H48: =VLOOKUP($B48,'Raw Datas'!$54:$101,H$7,FALSE) -> ND | I48: =VLOOKUP($B48,'Raw Datas'!$54:$101,I$7,FALSE) -> ND | J48: =VLOOKUP($B48,'Raw Datas'!$54:$101,J$7,FALSE) -> ND | ... V48: =VLOOKUP($B48,'Raw Datas'!$54:$101,V$7,FALSE) -> ND
B49: 5,6-DiHETE | C49: =VLOOKUP($B49,'Raw Datas'!$54:$101,C$7,FALSE) -> <LLOQ | D49: =VLOOKUP($B49,'Raw Datas'!$54:$101,D$7,FALSE) -> 9.0408 | E49: =VLOOKUP($B49,'Raw Datas'!$54:$101,E$7,FALSE) -> <LLOQ | F49: =VLOOKUP($B49,'Raw Datas'!$54:$101,F$7,FALSE) -> 1.3332167 | G49: =VLOOKUP($B49,'Raw Datas'!$54:$101,G$7,FALSE) -> <LLOQ | H49: =VLOOKUP($B49,'Raw Datas'!$54:$101,H$7,FALSE) -> <LLOQ | I49: =VLOOKUP($B49,'Raw Datas'!$54:$101,I$7,FALSE) -> <LLOQ | J49: =VLOOKUP($B49,'Raw Datas'!$54:$101,J$7,FALSE) -> <LLOQ | ... V49: =VLOOKUP($B49,'Raw Datas'!$54:$101,V$7,FALSE) -> <LLOQ
A51: Docosahexaenoic acid C22:6ꙍ3 | B51: 14-HDHA | C51: =VLOOKUP($B51,'Raw Datas'!$54:$101,C$7,FALSE) -> 65.220717 | D51: =VLOOKUP($B51,'Raw Datas'!$54:$101,D$7,FALSE) -> 285.99188 | E51: =VLOOKUP($B51,'Raw Datas'!$54:$101,E$7,FALSE) -> 208.06285 | F51: =VLOOKUP($B51,'Raw Datas'!$54:$101,F$7,FALSE) -> 49.990067 | G51: =VLOOKUP($B51,'Raw Datas'!$54:$101,G$7,FALSE) -> 113.22055 | H51: =VLOOKUP($B51,'Raw Datas'!$54:$101,H$7,FALSE) -> 371.07 | I51: =VLOOKUP($B51,'Raw Datas'!$54:$101,I$7,FALSE) -> 75.871933 | J51: =VLOOKUP($B51,'Raw Datas'!$54:$101,J$7,FALSE) -> 112.06087 | ... V51: =VLOOKUP($B51,'Raw Datas'!$54:$101,V$7,FALSE) -> 101.8204
B52: 17-HDHA | C52: =VLOOKUP($B52,'Raw Datas'!$54:$101,C$7,FALSE) -> 12.364717 | D52: =VLOOKUP($B52,'Raw Datas'!$54:$101,D$7,FALSE) -> 238.88677 | E52: =VLOOKUP($B52,'Raw Datas'!$54:$101,E$7,FALSE) -> 15.891367 | F52: =VLOOKUP($B52,'Raw Datas'!$54:$101,F$7,FALSE) -> 37.662383 | G52: =VLOOKUP($B52,'Raw Datas'!$54:$101,G$7,FALSE) -> 12.941483 | H52: =VLOOKUP($B52,'Raw Datas'!$54:$101,H$7,FALSE) -> 28.762367 | I52: =VLOOKUP($B52,'Raw Datas'!$54:$101,I$7,FALSE) -> 14.75295 | J52: =VLOOKUP($B52,'Raw Datas'!$54:$101,J$7,FALSE) -> 12.250417 | ... V52: =VLOOKUP($B52,'Raw Datas'!$54:$101,V$7,FALSE) -> 12.634167
B53: 16-HDHA | C53: =VLOOKUP($B53,'Raw Datas'!$54:$101,C$7,FALSE) -> 2.67605 | D53: =VLOOKUP($B53,'Raw Datas'!$54:$101,D$7,FALSE) -> 74.694983 | E53: =VLOOKUP($B53,'Raw Datas'!$54:$101,E$7,FALSE) -> 1.72135 | F53: =VLOOKUP($B53,'Raw Datas'!$54:$101,F$7,FALSE) -> 10.255467 | G53: =VLOOKUP($B53,'Raw Datas'!$54:$101,G$7,FALSE) -> 2.1435333 | H53: =VLOOKUP($B53,'Raw Datas'!$54:$101,H$7,FALSE) -> 1.3975833 | I53: =VLOOKUP($B53,'Raw Datas'!$54:$101,I$7,FALSE) -> 4.0192833 | J53: =VLOOKUP($B53,'Raw Datas'!$54:$101,J$7,FALSE) -> 1.14545 | ... V53: =VLOOKUP($B53,'Raw Datas'!$54:$101,V$7,FALSE) -> 1.27395
B54: 7MaR1 | C54: =VLOOKUP($B54,'Raw Datas'!$54:$101,C$7,FALSE) -> ND | D54: =VLOOKUP($B54,'Raw Datas'!$54:$101,D$7,FALSE) -> ND | E54: =VLOOKUP($B54,'Raw Datas'!$54:$101,E$7,FALSE) -> ND | F54: =VLOOKUP($B54,'Raw Datas'!$54:$101,F$7,FALSE) -> ND | G54: =VLOOKUP($B54,'Raw Datas'!$54:$101,G$7,FALSE) -> ND | H54: =VLOOKUP($B54,'Raw Datas'!$54:$101,H$7,FALSE) -> ND | I54: =VLOOKUP($B54,'Raw Datas'!$54:$101,I$7,FALSE) -> ND | J54: =VLOOKUP($B54,'Raw Datas'!$54:$101,J$7,FALSE) -> ND | ... V54: =VLOOKUP($B54,'Raw Datas'!$54:$101,V$7,FALSE) -> ND
...

Sheet Raw Datas
A1: Sample name | B1: Cal min conc | C1: JV-015-RAN-IC-M2 | D1: BS-007-RAN-01-M3 | E1: BS-007-RAN-02-M3 | F1: KT-004-SOC-16-M1 | G1: BS-135-RAN-IC-M3 | H1: JV-070-DAV-07-M3 | I1: BS-129-RAT-10-M5 | J1: JV-036-SOC-10-M2 | K1: BS-126-RAT-05-M2 | L1: JV-017-RAN-10-M3 | M1: JV-070-DAV-04-M1 | N1: BS-356-RAN-03-M4 | O1: JV-090-MIN-IC-M4 | P1: BS-391-RAN-06-M2 | Q1: JV-061-MIN-03-M5 | R1: JV-070-MIN-01-M1 | S1: KT-004-SOC-14-M1 | T1: JV-089-SOC-04-M1 | U1: BS-472-RAT-01-M1 | V1: BS-172-RAT-10-M3
A2: 6kPGF1a | B2: 2.0102
A3: RvE1
A4: 11B-PGF2a
A5: PGE3
A6: PGE2 | B6: 1.8942
A7: TXB2 | B7: 1.7002 | C7: 8.7281 | D7: 28.5245 | E7: 42.7612 | F7: 35.2323 | G7: 43.8971 | H7: 15.6512 | I7: 57.0298 | J7: 41.9928 | K7: 20.1218 | L7: 22.2375 | M7: 1.8733 | N7: 35.5854 | O7: 19.7625 | P7: 5.1954 | Q7: 8.8081 | R7: 15.4191 | S7: 7.486 | T7: 33.6093 | U7: 12.8239 | V7: 157.6755
A8: 10-TriHOME | B8: 3.31 | C8: 0.7773 | D8: 7.5797 | E8: 7.5273 | F8: 0.3495 | G8: 2.7372 | H8: 11.399 | I8: 4.8925 | J8: 1.651 | K8: 8.0069 | L8: 1.0814 | M8: 4.9578 | N8: 13.1762 | O8: 0.0289 | P8: 2.5396 | Q8: 3.3096 | R8: 2.1997 | S8: 16.9982 | T8: 0.8742 | U8: 1.205 | V8: 8.8713
A9: 12-TriHOME | B9: 2.3085 | C9: 5.4281 | D9: 28.6234 | E9: 22.5676 | F9: 3.5649 | G9: 9.8386 | H9: 54.1647 | I9: 12.0898 | J9: 6.7698 | K9: 14.7754 | L9: 8.1519 | M9: 20.5976 | N9: 35.7589 | O9: 6.0982 | P9: 12.4378 | Q9: 17.2121 | R9: 17.9689 | S9: 49.9056 | T9: 4.5791 | U9: 5.4369 | V9: 26.2442
A10: PGF2a | B10: 2.2699 | E10: 29.4545 | G10: 56.6607 | H10: 9.1207 | I10: 25.2801 | L10: 11.492 | R10: 34.4467 | T10: 15.9961 | V10: 91.8573
A11: LXB4
A12: PGD2
A13: RvD3
A14: RvD1 | B14: 2.474
A15: LXA4 | B15: 3.2369 | C15: 11.8707 | D15: 162.5396 | E15: 7.2087 | F15: 30.6112 | G15: 4.2034 | H15: 1.9231 | I15: 12.6628 | J15: 3.2525 | K15: 29.9546 | L15: 2.805 | M15: 23.2006 | N15: 82.4853 | O15: 17.1714 | P15: 0.5991 | Q15: 43.6246 | R15: 0.1013 | S15: 116.1773 | T15: 2.9037 | U15: 19.7541 | V15: 9.9394
A16: PGFM | B16: 2.0869 | C16: 0.0048 | E16: 1.7796 | F16: 0.1857 | G16: 1.3157 | H16: 0.5769 | I16: 1.4775 | J16: 0.0432 | K16: -0.6015 | L16: 0.1321 | M16: -0.3694 | O16: 0.4092 | P16: -0.8751 | R16: 3.4533 | V16: 3.3073
A17: RvD2
A18: 8isoPGA2 | B18: 1.4837
A19: PGA1 | B19: 2.0392
A20: LTB5 | B20: 2.437
A21: 7MaR1
A22: RvD5
A23: LTB4 | B23: 2.3275 | C23: 16.7768 | D23: 532.5521 | E23: 7.6323 | F23: 73.9916 | G23: 4.6824 | H23: 3.0135 | I23: 21.7939 | J23: 6.222 | K23: 46.4618 | L23: 1.6604 | M23: 13.7081 | N23: 90.7654 | O23: 31.2482 | P23: 11.6984 | Q23: 57.3444 | R23: 2.497 | S23: 312.238 | U23: 16.3074 | V23: 12.2203
A24: PDx
A25: 9,10-DiHOME | B25: 2.1503 | C25: 21.793 | D25: 14.096 | E25: 38.7966 | F25: 15.8697 | G25: 62.9722 | H25: 51.0487 | I25: 27.4375 | J25: 19.2771 | K25: 19.7478 | L25: 26.8086 | M25: 10.2078 | N25: 3539.1715 | O25: 15.4732 | P25: 34.6941 | Q25: 11.1712 | R25: 5.4329 | S25: 114.1244 | T25: 6.7382 | U25: 5.9304 | V25: 26.6848
A26: 12,13-DiHOME | B26: 1.9931 | C26: 19.5255 | D26: 13.3555 | E26: 22.1394 | F26: 9.1296 | G26: 34.1955 | H26: 87.6694 | I26: 30.2131 | J26: 9.2035 | K26: 15.5654 | L26: 37.9128 | M26: 11.9693 | N26: 19.602 | O26: 15.5968 | P26: 44.6918 | Q26: 6.1935 | R26: 3.3379 | S26: 74.4591 | T26: 3.5512 | U26: 3.0266 | V26: 22.3689
A27: 18-HEPE | B27: 2.3509 | C27: 9.6581 | D27: 219.5146 | E27: 11.7252 | F27: 24.605 | G27: 11.1374 | H27: 13.5543 | I27: 8.5808 | J27: 6.4236 | K27: 4.5827 | L27: 2.8535 | M27: 11.5462 | N27: 22.8782 | O27: 14.7177 | P27: 11.288 | Q27: 75.6365 | R27: 7.71 | S27: 216.3168 | T27: 3.0793 | U27: 7.6839 | V27: 6.9785
A28: 9-HOTrE | B28: 2.1056 | C28: 1.8966 | D28: 24.9727 | E28: 3.148 | F28: 2.2451 | G28: 4.451 | H28: 14.0664 | I28: 5.9499 | J28: 0.3136 | K28: 3.3916 | L28: 5.389 | M28: 2.3168 | N28: 4.8889 | O28: 4.7211 | P28: 5.3148 | Q28: 5.255 | R28: 1.0211 | S28: 34.9175 | T28: 0.1131 | U28: 0.8391 | V28: 2.2741
A29: 13-HOTrE | B29: 1.9303 | C29: 3.2093 | D29: 33.0032 | E29: 10.5811 | F29: 2.2962 | G29: 5.6155 | H29: 20.7221 | I29: 5.5006 | J29: 2.8024 | K29: 2.4745 | L29: 20.7688 | M29: 1.8546 | N29: 3.359 | O29: 8.996 | P29: 2.6876 | Q29: 7.667 | R29: 4.4776 | S29: 50.2239 | T29: -0.1239 | U29: 0.8724 | V29: 4.9528
A30: 5,6-DiHETE | B30: 2.3392 | C30: 1.2485 | D30: 54.2448 | E30: 0.31 | F30: 7.9993 | G30: -0.1455 | H30: -0.0046 | I30: 1.4648 | J30: -0.3315 | K30: 4.0041 | L30: -0.5493 | M30: 1.2228 | N30: 13.7839 | O30: 4.6343 | P30: 0.8388 | Q30: 9.2714 | R30: -0.0531 | S30: 32.3618 | T30: -0.2349 | U30: 2.2343 | V30: 0.3108
A31: 15dPGJ2
A32: 10-HODE | B32: 2.1774 | C32: 2.9555 | D32: 9.0396 | E32: 3.8696 | F32: 2.1755 | G32: 8.4594 | H32: 8.1583 | I32: 3.8821 | J32: 3.4208 | K32: 1.2235 | L32: 2.7489 | M32: 1.7616 | N32: 2.7521 | O32: 2.1028 | P32: 10.4189 | Q32: 2.4292 | R32: 3.0029 | S32: 9.4552 | T32: 0.8452 | U32: 1.5756 | V32: 5.9379
A33: 13-HODE | B33: 2.3779 | C33: 296.065 | D33: 4760.3947 | E33: 813.8632 | F33: 441.4479 | G33: 454.0134 | H33: 1033.1252 | I33: 705.9969 | J33: 333.89 | K33: 436.0925 | L33: 1126.8049 | M33: 427.2974 | N33: 562.9576 | O33: 484.9313 | P33: 529.5689 | Q33: 851.355 | R33: 317.0174 | S33: 3377.301 | T33: 128.6186 | U33: 228.3192 | V33: 568.2192
A34: 9-HODE | B34: 1.9205 | C34: 142.606 | D34: 2825.8493 | E34: 312.5368 | F34: 337.0336 | G34: 241.8058 | H34: 568.6577 | I34: 400.283 | J34: 76.0835 | K34: 249.0036 | L34: 372.2786 | M34: 334.2683 | N34: 412.3493 | O34: 271.0577 | P34: 301.6386 | Q34: 667.4444 | R34: 72.5149 | S34: 2378.5079 | T34: 68.1906 | U34: 157.0302 | V34: 246.9576
A35: 15-HETE | B35: 1.7749 | C35: 40.2426 | D35: 1868.5159 | E35: 61.1474 | F35: 121.9843 | G35: 104.706 | H35: 65.8048 | I35: 88.0196 | J35: 51.2894 | K35: 58.5143 | L35: 56.1761 | M35: 82.4344 | N35: 80.8733 | O35: 66.2639 | P35: 50.3581 | Q35: 126.1385 | R35: 94.0867 | S35: 785.613 | T35: 27.9538 | U35: 40.5941 | V35: 88.5041
A36: 13-oxoODE | B36: 2.1186 | C36: 26.2178 | D36: 67.8905 | E36: 81.7334 | F36: 65.1056 | G36: 18.3107 | H36: 116.8443 | I36: 52.181 | J36: 14.9312 | K36: 58.9337 | L36: 60.9785 | M36: 44.7592 | N36: 119.9884 | O36: 54.4229 | P36: 39.6639 | Q36: 55.0521 | R36: 19.7902 | S36: 171.3054 | T36: 14.7274 | U36: 37.4044 | V36: 60.7749
A37: 17-HDHA | B37: 2.3065 | C37: 74.1883 | D37: 1433.3206 | E37: 95.3482 | F37: 225.9743 | G37: 77.6489 | H37: 172.5742 | I37: 88.5177 | J37: 73.5025 | K37: 78.2557 | L37: 69.0652 | M37: 142.1992 | N37: 112.0761 | O37: 99.8087 | P37: 69.255 | Q37: 81.4148 | R37: 114.8128 | S37: 975.913 | T37: 23.5899 | U37: 48.4075 | V37: 75.805
A38: 9-oxoODE | B38: 2.0106 | C38: 17.4252 | D38: 24.8915 | E38: 107.1424 | F38: 26.8246 | G38: 21.8009 | H38: 134.31 | I38: 56.8945 | J38: 9.773 | K38: 45.7569 | L38: 78.506 | M38: 49.0791 | N38: 136.3947 | O38: 14.3781 | P38: 28.5987 | Q38: 30.8879 | R38: 22.7108 | S38: 102.2095 | T38: 20.1254 | U38: 38.4474 | V38: 82.8958
A39: 8-HETE | B39: 2.0709 | C39: 25.59 | D39: 944.9885 | E39: 35.882 | F39: 110.5066 | G39: 45.2302 | H39: 29.768 | I39: 51.8614 | J39: 21.8981 | K39: 41.2074 | L39: 33.8649 | M39: 62.8707 | N39: 57.8555 | O39: 47.1747 | P39: 39.0358 | Q39: 91.6035 | R39: 23.177 | S39: 528.1497 | T39: 17.1818 | U39: 37.0131 | V39: 43.994
A40: 12-HETE | B40: 2.0402 | C40: 541.3639 | D40: 4962.6643 | E40: 2650.8219 | F40: 763.9395 | G40: 2391.552 | H40: 2608.4136 | I40: 1609.2681 | J40: 1198.3869 | K40: 904.3038 | L40: 3444.9233 | M40: 121.8904 | N40: 833.101 | O40: 557.2512 | P40: 141.2196 | Q40: 268.615 | R40: 1622.3597 | S40: 1283.6351 | T40: 716.8143 | U40: 500.5737 | V40: 3248.8041
...

Sheet Identifiants
C1: Synonymes | D1: IUPAC name | E1: CHEBI | F1: InChiKEY | G1: InChi
A2: 5,6-EET | C2: 5,6-EpETrE | D2: (±)5,6-epoxy-8Z,11Z,14Z-eicosatrienoic acid | E2: 34450 | F2: VBQNSZQZRAGRIX-GSKBNKFLSA-N | G2: InChI=1S/C20H32O3/c1-2-3-4-5-6-7-8-9-10-11-12-13-15-18-19(23-18)16-14-17-20(21)22/h6-7,9-10,12-13,18-19H,2-5,8,11,14-17H2,1H3,(H,21,22)/b7-6-,10-9-,13-12-/t18-,19+/m1/s1
A3: 8,9-EET | C3: 8,9-EpETrE | D3: (±)8,9-epoxy-5Z,11Z,14Z-eicosatrienoic acid | E3: 34490 | F3: DBWQSCSXHFNTMO-TYAUOURKSA-N | G3: 1S/C20H32O3/c1-2-3-4-5-6-7-8-9-12-15-18-19(23-18)16-13-10-11-14-17-20(21)22/h6-7,9-10,12-13,18-19H,2-5,8,11,14-17H2,1H3,(H,21,22)/b7-6-,12-9-,13-10-
A4: 11,12-EET | C4: 11,12-EpETrE | D4: (±)11,(12)-epoxy-5Z,8Z,14Z-eicosatrienoic acid | E4: 34130 | F4: DXOYQVHGIODESM-KROJNAHFSA-N | G4: 1S/C20H32O3/c1-2-3-4-5-9-12-15-18-19(23-18)16-13-10-7-6-8-11-14-17-20(21)22/h6,8-10,12-13,18-19H,2-5,7,11,14-17H2,1H3,(H,21,22)/b8-6-,12-9-,13-10-
A5: 14,15-EET | C5: 14,15-EpETrE | D5: (±)14(15)-epoxy-5Z,8Z,11Z-eicosatrienoic acid | E5: 34157 | F5: JBSCUHKPLGKXKH-ILYOTBPNSA-N | G5: 1S/C20H32O3/c1-2-3-12-15-18-19(23-18)16-13-10-8-6-4-5-7-9-11-14-17-20(21)22/h4,6-7,9-10,13,18-19H,2-3,5,8,11-12,14-17H2,1H3,(H,21,22)/b6-4-,9-7-,13-10-
A6: 5-HETE | D6: 5-Hydroxyeicosatetraenoic Acid | E6: 28209 | F6: KGIJOOYOSFUGPC-JGKLHWIESA-N | G6: 1S/C20H32O3/c1-2-3-4-5-6-7-8-9-10-11-12-13-14-16-19(21)17-15-18-20(22)23/h6-7,9-10,12-14,16,19,21H,2-5,8,11,15,17-18H2,1H3,(H,22,23)/b7-6-,10-9-,13-12-,16-14+/t19-/m1/s1
A7: 8-HETE | D7: 8-Hydroxyeicosatetraenoic Acid | E7: 72643 | F7: NLUNAYAEIJYXRB-HEJOTXCHSA-N | G7: 1S/C20H32O3/c1-2-3-4-5-6-7-8-9-10-13-16-19(21)17-14-11-12-15-18-20(22)23/h6-7,9-11,13-14,16,19,21H,2-5,8,12,15,17-18H2,1H3,(H,22,23)/b7-6-,10-9-,14-11-,16-13+
A8: 12-HETE | D8: 12-Hydroxyeicosatetraenoic Acid | E8: 84447 | F8: ZNHVWPKMFKADKW-VXBMJZGYSA-N | G8: 1S/C20H32O3/c1-2-3-4-5-10-13-16-19(21)17-14-11-8-6-7-9-12-15-18-20(22)23/h7-11,13-14,17,19,21H,2-6,12,15-16,18H2,1H3,(H,22,23)/b9-7-,11-8-,13-10-,17-14+
A9: 15-HETE | D9: 15-Hydroxyeicosatetraenoic Acid | E9: 64017 | F9: JSFATNQSLKRBCI-USWFWKISSA-N | G9: 1S/C20H32O3/c1-2-3-13-16-19(21)17-14-11-9-7-5-4-6-8-10-12-15-18-20(22)23/h4-5,8-11,14,17,19,21H,2-3,6-7,12-13,15-16,18H2,1H3,(H,22,23)/b5-4-,10-8-,11-9-,17-14+
A10: 5-oxo-ETE | C10: 5-KETE | D10: 5-oxo-6E,8Z,11Z,14Z-eicosatetraenoic acid | E10: 52449 | F10: MEASLHGILYBXFO-XTDASVJISA-N | G10: 1S/C20H30O3/c1-2-3-4-5-6-7-8-9-10-11-12-13-14-16-19(21)17-15-18-20(22)23/h6-7,9-10,12-14,16H,2-5,8,11,15,17-18H2,1H3,(H,22,23)/b7-6-,10-9-,13-12-,16-14+
A11: LTB4 | B11: Leuktriene B4 | D11: 5S,12R-dihydroxy-6Z,8E,10E,14Z-eicosatetraenoic acid | E11: 15647 | F11: VNYSSYRCGWBHLG-AMOLWHMGSA-N | G11: 1S/C20H32O4/c1-2-3-4-5-6-9-13-18(21)14-10-7-8-11-15-19(22)16-12-17-20(23)2 4/h6-11,14-15,18-19,21-22H,2-5,12-13,16-17H2,1H3,(H,23,24)/b8-7+,9-6-,14-10+,15- 11-/t18-,19-/m1/s1
A12: LxA4 | B12: Lipoxin A4 | C12: 5(S),6(R),15(S)-TriHETE | D12: 5S,6R,15S-trihydroxy-7E,9E,11Z,13E-eicosatetraenoic acid | E12: 6498 | F12: IXAQOQZEOGMIQS-SSQFXEBMSA-N | G12: 1S/C20H32O5/c1-2-3-8-12-17(21)13-9-6-4-5-7-10-14-18(22)19(23)15-11-16-20(2 4)25/h4-7,9-10,13-14,17-19,21-23H,2-3,8,11-12,15-16H2,1H3,(H,24,25)/b6-4-,7-5+,1 3-9+,14-10+/t17-,18+,19-/m0/s1
A13: LXB4 | B13: Lipoxin B4 | C13: 5(S),14(R),15(S)-TriHETE | D13: 5S,14R,15S-trihydroxy-6E,8Z,10E,12E-eicosatetraenoic acid | E13: 6499 | F13: UXVRTOKOJOMENI-WLPVFMORSA-N | G13: InChI=1S/C20H32O5/c1-2-3-8-14-18(22)19(23)15-10-7-5-4-6-9-12-17(21)13-11-16-20(24)25/h4-7,9-10,12,15,17-19,21-23H,2-3,8,11,13-14,16H2,1H3,(H,24,25)/b6-4-,7-5+,12-9+,15-10+/t17-,18+,19-/m1/s1
A14: 8isoPGA2 | B14: 8-iso-Prostaglandin A2 | C14: 8-epi PGA2 | D14: 9-oxo-15S-hydroxy-(8β)-prosta-5Z,10,13E-trien-1-oic acid | E14: - | F14: MYHXHCUNDDAEOZ-UKUWKSPLSA-N | G14: nChI=1S/C20H30O4/c1-2-3-6-9-17(21)14-12-16-13-15-19(22)18(16)10-7-4-5-8-11-20(23)24/h4,7,12-18,21H,2-3,5-6,8-11H2,1H3,(H,23,24)/b7-4-,14-12+/t16-,17-,18-/m0/s1
A15: PGD2 | B15: Prostaglandin D2 | D15: 9α,15S-dihydroxy-11-oxo-prosta-5Z,13E-dien-1-oic acid | E15: 15555 | F15: BHMBVRSPMRCCGG-OUTUXVNYSA-N | G15: InChI=1S/C20H32O5/c1-2-3-6-9-15(21)12-13-17-16(18(22)14-19(17)23)10-7-4-5-8-11-20(24)25/h4,7,12-13,15-18,21-22H,2-3,5-6,8-11,14H2,1H3,(H,24,25)/b7-4-,13-12+/t15-,16+,17+,18-/m0/s1
A16: PGE2 | B16: Prostaglandin E2 | D16: 9-oxo-11α,15S-dihydroxy-prosta-5Z,13E-dien-1-oic acid | E16: 15551 | F16: XEYBRNLFEZDVAW-ARSRFYASSA-N | G16: InChI=1S/C20H32O5/c1-2-3-6-9-15(21)12-13-17-16(18(22)14-19(17)23)10-7-4-5-8-11-20(24)25/h4,7,12-13,15-17,19,21,23H,2-3,5-6,8-11,14H2,1H3,(H,24,25)/b7-4-,13-12+/t15-,16+,17+,19+/m0/s1
A17: PGF2a | B17: Prostaglandin F2 alpha | D17: 9α,11α,15S-trihydroxy-prosta-5Z,13E-dien-1-oic acid | E17: 15553 | F17: PXGPLTODNUVGFL-YNNPMVKQSA-N | G17: 1S/C20H34O5/c1-2-3-6-9-15(21)12-13-17-16(18(22)14-19(17)23)10-7-4-5-8-11-2 0(24)25/h4,7,12-13,15-19,21-23H,2-3,5-6,8-11,14H2,1H3,(H,24,25)/b7-4-,13-12+/t15 -,16+,17+,18-,19+/m0/s1
A18: 11B-PGF2a | B18: 11-beta-Prostaglandin F2 alpha | D18: (5Z,9α,11β,13E,15S)-9,11,15-trihydroxy-prosta-5,13-dien-1-oic acid | E18: 27595 | F18: PXGPLTODNUVGFL-ZWAKLXPCSA-N | G18: InChI=1S/C20H34O5/c1-2-3-6-9-15(21)12-13-17-16(18(22)14-19(17)23)10-7-4-5-8-11-20(24)25/h4,7,12-13,15-19,21-23H,2-3,5-6,8-11,14H2,1H3,(H,24,25)/b7-4-,13-12+/t15-,16+,17+,18-,19-/m0/s1
A19: PGFM | B19: 13,14-dihydro-15-keto PGF2α | D19: 9α,11α-dihydroxy-15-oxo-prost-5Z-en-1-oic acid | E19: 63976 | F19: VKTIONYPMSCHQI-XAGFEHLVSA-N | G19: InChI=1S/C20H34O5/c1-2-3-6-9-15(21)12-13-17-16(18(22)14-19(17)23)10-7-4-5-8-11-20(24)25/h4,7,16-19,22-23H,2-3,5-6,8-14H2,1H3,(H,24,25)/b7-4-/t16-,17-,18+,19-/m1/s1
A20: 15dPGJ2 | B20: 15-deoxy-Δ12,14-Prostaglandin J2 | C20: 15-deoxy-Δ12,14-PGJ2 | D20: 11-oxo-prosta-5Z,9,12E,14E-tetraen-1-oic acid | E20: 34159 | F20: VHRUMKCAEVRUBK-GODQJPCRSA-N | G20: InChI=1S/C20H28O3/c1-2-3-4-5-6-10-13-18-17(15-16-19(18)21)12-9-7-8-11-14-20(22)23/h6-7,9-10,13,15-17H,2-5,8,11-12,14H2,1H3,(H,22,23)/b9-7-,10-6+,18-13+/t17-/m0/s1
A21: 6kPGF1a | B21: 6-keto-Prostaglandin-F1-alpha | D21: 6-oxo-9α,11α,15S-trihydroxy-prost-13E-en-1-oic acid | E21: 28158 | F21: KFGOFTHODYBSGM-ZUNNJUQCSA-N | G21: InChI=1S/C20H34O6/c1-2-3-4-7-14(21)10-11-16-17(19(24)13-18(16)23)12-15(22)8-5-6-9-20(25)26/h10-11,14,16-19,21,23-24H,2-9,12-13H2,1H3,(H,25,26)/b11-10+/t14-,16+,17+,18+,19-/m0/s1
A22: TXB2 | B22: Tromboxane B2 | D22: 9α,11,15S-trihydroxythromba-5Z,13E-dien-1-oic acid | E22: 28728 | F22: XNRNNGPBEPRNAR-JQBLCGNGSA-N | G22: InChI=1S/C20H34O6/c1-2-3-6-9-15(21)12-13-18-16(17(22)14-20(25)26-18)10-7-4-5-8-11-19(23)24/h4,7,12-13,15-18,20-22,25H,2-3,5-6,8-11,14H2,1H3,(H,23,24)/b7-4-,13-12+/t15-,16-,17-,18+,20?/m0/s1
A23: PGA1 | B23: Prostaglandin A1 | D23: 9-oxo-15S-hydroxy-prosta-10,13E-dien-1-oic acid | E23: 15545 | F23: BGKHCLZFGPIKKU-LDDQNKHRSA-N | G23: InChI=1S/C20H32O4/c1-2-3-6-9-17(21)14-12-16-13-15-19(22)18(16)10-7-4-5-8-11-20(23)24/h12-18,21H,2-11H2,1H3,(H,23,24)/b14-12+/t16-,17-,18+/m0/s1
A24: 14-HDHA | B24: 14-hydroxy Docosahexaenoic Acid | C24: 14-HDoHE | D24: 14-hydroxy-4Z,7Z,10Z,12E,16Z,19Z-docosahexaenoic acid | E24: 72647 | F24: ZNEBXONKCYFJAF-BGKMTWLOSA-N | G24: 1S/C22H32O3/c1-2-3-4-5-12-15-18-21(23)19-16-13-10-8-6-7-9-11-14-17-20-22(24)25/h3-4,6-7,10-16,19,21,23H,2,5,8-9,17-18,20H2,1H3,(H,24,25)/b4-3-,7-6-,13-10-,14-11-,15-12-,19-16+
A25: 17-HDHA | B25: 17-hydroxy Docosahexaenoic Acid | C25: 17-HDoHE | D25: 17-hydroxy-4Z,7Z,10Z,13Z,15E,19Z-docosahexaenoic acid | E25: 72637 | F25: SWTYBBUBEPPYCX-VIIQGJSXSA-N | G25: 1S/C22H32O3/c1-2-3-15-18-21(23)19-16-13-11-9-7-5-4-6-8-10-12-14-17-20-22(24)25/h3,5-8,11-16,19,21,23H,2,4,9-10,17-18,20H2,1H3,(H,24,25)/b7-5-,8-6-,13-11-,14-12-,15-3-,19-16+
A26: 7(S)-MaR1 | B26: Maresin 1 - 7(S)-MaR1 | C26: 7-epi-MaR1 | D26: 7S,14S-dihydroxy-4Z,8E,10E,12Z,16Z,19Z-docosahexaenoic acid | E26: - | F26: HLHYXXBCQOUTGK-NVFVPEJPSA-N | G26: InChI=1S/C22H32O4/c1-2-3-4-5-6-10-15-20(23)16-11-7-8-12-17-21(24)18-13-9-14-19-22(25)26/h3-4,6-13,16-17,20-21,23-24H,2,5,14-15,18-19H2,1H3,(H,25,26)/b4-3-,8-7+,10-6-,13-9-,16-11-,17-12+/t20-,21+/m0/s1
A27: PDx | B27: Neuro Protectin DX | C27: 10(S),17(S)-DiHDHA | D27: 10(S),17(S)-dihydroxy-4Z,7Z,11E,13Z,15E,19Z-docosahexaenoic acid | E27: 140930 | F27: CRDZYJSQHCXHEG-XLBFCUQGSA-N | G27: InChI=1S/C22H32O4/c1-2-3-10-15-20(23)17-12-8-9-13-18-21(24)16-11-6-4-5-7-14-19-22(25)26/h3,5-13,17-18,20-21,23-24H,2,4,14-16,19H2,1H3,(H,25,26)/b7-5-,9-8-,10-3-,11-6-,17-12+,18-13+/t20-,21-/m0/s1
A28: PD1
A29: RVD1 | B29: Resolvin D1 | C29: 17(S)-Resolvin D1 | D29: 7S,8R,17S-trihydroxy-4Z,9E,11E,13Z,15E,19Z-docosahexaenoic acid | E29: 81564 | F29: OIWTWACQMDFHJG-CCFUIAGSSA-N | G29: InChI=1S/C22H32O5/c1-2-3-9-14-19(23)15-10-6-4-5-7-11-16-20(24)21(25)17-12-8-13-18-22(26)27/h3-12,15-16,19-21,23-25H,2,13-14,17-18H2,1H3,(H,26,27)/b6-4-,7-5+,9-3-,12-8-,15-10+,16-11+/t19-,20+,21-/m0/s1
A30: RvD2 | B30: Resolvin D2 | C30: 7(S),16(R),17(S)-Resolvin D2 | D30: 7S,16R,17S-trihydroxy-4Z,8E,10Z,12E,14E,19Z-docosahexaenoic acid | E30: 81565 | F30: IKFAUGXNBOBQDM-XFMPMKITSA-N | G30: InChI=1S/C22H32O5/c1-2-3-9-16-20(24)21(25)17-12-7-5-4-6-10-14-19(23)15-11-8-13-18-22(26)27/h3-12,14,17,19-21,23-25H,2,13,15-16,18H2,1H3,(H,26,27)/b6-4-,7-5+,9-3-,11-8-,14-10+,17-12+/t19-,20+,21-/m1/s1
A31: RvD3 | B31: Resolvin D3 | D31: 4S,11R,17S-trihydroxy-5Z,7E,9E,13Z,15E,19Z-docosahexaenoic acid | E31: 138648 | F31: QBTJOLCUKWLTIC-UZAFJXHNSA-N | G31: InChI=1S/C22H32O5/c1-2-3-7-12-19(23)14-10-6-11-15-20(24)13-8-4-5-9-16-21(25)17-18-22(26)27/h3-11,13-14,16,19-21,23-25H,2,12,15,17-18H2,1H3,(H,26,27)/b5-4+,7-3-,11-6-,13-8+,14-10+,16-9-/t19-,20-,21+/m0/s1
A32: RvD5 | B32: Resolvin D5 | C32: 7(S),17(S)-diHDHA | D32: 7S,17S-dihydroxy-4Z,8E,10Z,13Z,15E,19Z-docosahexaenoic acid | E32: 138645 | F32: CFOFZYMMJZILHE-XGTWDWJNSA-N | G32: InChI=1S/C22H32O4/c1-2-3-10-15-20(23)16-11-7-5-4-6-8-12-17-21(24)18-13-9-14-19-22(25)26/h3,5-13,16-17,20-21,23-24H,2,4,14-15,18-19H2,1H3,(H,25,26)/b7-5-,8-6-,10-3-,13-9-,16-11+,17-12+/t20-,21+/m0/s1
A33: 18-HEPE | D33: (±)-18-hydroxy-5Z,8Z,11Z,14Z,16E-eicosapentaenoic acid | E33: 72802 | F33: LRWYBGFSVUBWMO-UXNZXXPISA-N | G33: 1S/C20H30O3/c1-2-19(21)17-15-13-11-9-7-5-3-4-6-8-10-12-14-16-18-20(22)23/h 4-7,10-13,15,17,19,21H,2-3,8-9,14,16,18H2,1H3,(H,22,23)/b6-4-,7-5-,12-10-,13-11- ,17-15+
A34: LTB5 | B34: Leuktriene B5 | D34: 5S,12R-dihydroxy-6Z,8E,10E,14Z,17Z-eicosapentaenoic acid | E34: 88493 | F34: BISQPGCQOHLHQK-HDNPQISLSA-N | G34: InChI=1S/C20H30O4/c1-2-3-4-5-6-9-13-18(21)14-10-7-8-11-15-19(22)16-12-17-20(23)24/h3-4,6-11,14-15,18-19,21-22H,2,5,12-13,16-17H2,1H3,(H,23,24)/b4-3-,8-7+,9-6-,14-10+,15-11-/t18-,19-/m1/s1
A35: PGE3 | B35: Prostaglandin E3 | D35: 9-oxo-11α,15S-dihydroxy-prosta-5Z,13E,17Z-trien-1-oic acid | E35: 28031 | F35: CBOMORHDRONZRN-QLOYDKTKSA-N | G35: InChI=1S/C20H30O5/c1-2-3-6-9-15(21)12-13-17-16(18(22)14-19(17)23)10-7-4-5-8-11-20(24)25/h3-4,6-7,12-13,15-17,19,21,23H,2,5,8-11,14H2,1H3,(H,24,25)/b6-3-,7-4-,13-12+/t15-,16+,17+,19+/m0/s1
A36: RvE1 | B36: Resolvin E1 | C36: 5,12,18R-triHEPE | D36: 5S,12R,18R-trihydroxy-6Z,8E,10E,14Z,16E-eicosapentaenoic acid | E36: 81559 | F36: AOPOCGPBAIARAV-OTBJXLELSA-N | G36: InChI=1S/C20H30O5/c1-2-17(21)11-8-5-9-14-18(22)12-6-3-4-7-13-19(23)15-10-16-20(24)25/h3-9,11-13,17-19,21-23H,2,10,14-16H2,1H3,(H,24,25)/b4-3+,9-5-,11-8+,12-6+,13-7-/t17-,18+,19-/m1/s1
A37: 5,6-DiHETE | D37: (±)5,6-dihydroxy-8Z,11Z,14Z,17Z-eicosatetraenoic acid | E37: 165283 | F37: VPXVODYVPILPRC-CLQAUIESSA-N | G37: 1S/C20H32O4/c1-2-3-4-5-6-7-8-9-10-11-12-13-15-18(21)19(22)16-14-17-20(23)24/h3-4,6-7,9-10,12-13,18-19,21-22H,2,5,8,11,14-17H2,1H3,(H,23,24)/b4-3-,7-6-,10-9-,13-12-/t18-,19+/m1/s1
A38: 13-HODE | D38: (±)-13-hydroxy-9Z,11E-octadecadienoic acid | E38: 34154 | F38: HNICUWMFWZBIFP-IRQZEAMPSA-N | G38: 1S/C18H32O3/c1-2-3-11-14-17(19)15-12-9-7-5-4-6-8-10-13-16-18(20)21/h7,9,12,15,17,19H,2-6,8,10-11,13-14,16H2,1H3,(H,20,21)/b9-7-,15-12+/t17-/m0/s1
A39: 9-HODE | D39: (±)-9-hydroxy-10E,12Z-octadecadienoic acid | E39: 72651 | F39: NPDSHTNEKLQQIJ-ZJHFMPGASA-N | G39: 1S/C18H32O3/c1-2-3-4-5-6-8-11-14-17(19)15-12-9-7-10-13-16-18(20)21/h6,8,11,14,17,19H,2-5,7,9-10,12-13,15-16H2,1H3,(H,20,21)/b8-6-,14-11+
A40: 12,13-DiHOME | C40: Isoleukotoxin diol | D40: 12,13-dihydroxy-9Z-octadecenoic acid | E40: 72665 | F40: CQSLTKIXAJTQGA-FLIBITNWSA-N | G40: 1S/C18H34O4/c1-2-3-10-13-16(19)17(20)14-11-8-6-4-5-7-9-12-15-18(21)22/h8,11,16-17,19-20H,2-7,9-10,12-15H2,1H3,(H,21,22)/b11-8-
...

Sheet PUFA's metabolismes
I3: 9,12,13-TriHOME | K3: 9,10,13-TriHOME
I4: ↑ | K4: ↑ | AB4: PGE3 | AC4: ← | AD4: PGH3 | AE4: ← | AF4: PGG3 | AG4: COX | AH4: Eicosapentaenoic acid (EPA) | AK4: LOX | AL4: 5-HpEPE | AM4: → | AN4: LTA5 | AO4: → | AP4: LTB5
G5: 9-OxoODE | H5: ← | I5: 9-HODE | J5: ← | K5: 9-HpODE
L6: ↖ | M6: LOX | N6: Linoleic acid (LA) | O6: CYP450 | P6: 12(13)-EpOME | Q6: → | R6: 12,13-DiHOME | AK6: CYP450
L7: ↙ | P7: 9(10)-EpOME | Q7: → | R7: 9,10-DiHOME | AB7: RvE1 | AC7: ← | AD7: 18-HEPE | AE7: ← | AF7: 18R-HpEPE
G8: 13-OxoODE | H8: ← | I8: 13-HODE | J8: ← | K8: 13-HpODE | AL8: 5(6)-EpETE | AM8: → | AN8: 5,6-DiHETE
K9: ↓ | O9: Peroxidation | P9: 10-HpODE | Q9: → | R9: 10-HODE
K10: 9,12,13-TriHOME | P10: (Non-enzymatic) | R10: (Non-enzymatic)
M12: Dihomo-γ-linolenic acid (DGLA)
O13: COX | P13: PGH1 | Q13: → | R13: PGE1 | S13: → | T13: PGA1
AP15: RvD1
R16: 8-HpETE | S16: → | T16: 8-HETE | AP16: RvD2
K17: TXB2 | AB17: Maresin1 | AC17: ← | AD17: 14S-HDHA | AE17: ← | AF17: 14S-HpDHA | AG17: LOX | AH17: Docohexaenoic acid (DHA) | AK17: LOX | AL17: 17S-HpDHA | AM17: → | AN17: 17S-HDHA | AP17: RvD3
K18: ↑ | R18: 5-HETE | S18: → | T18: 5-oxo-ETE | AP18: RvD5
K19: TXA2 | R19: ↑ | AJ19: Epoxidase/hydrolase
K20: ↑ | R20: 5-HpETE | S20: → | T20: LTA4 | U20: → | V20: LTB4
C21: 6-keto-PGE1α | D21: ← | E21: 6-keto-PGF1α | F21: ← | G21: PGI2 | H21: ← | I21: PGH2 | J21: ← | K21: PGG2 | M21: COX | N21: Arachidonic acid (AA) | O21: LOX | T21: ↓ | U21: ↘ | AK21: NPD1 | AL21: PDX (NPDX)
H22: ↙ | I22: ↓ | J22: ↘ | T22: LXB4 | V22: LXA4
G23: PGE2 | H23: → | I23: PGF2α | K23: PGD2 | M23: Peroxidation | T23: ↑ | U23: ↗
I24: ↓ | K24: ↓ | R24: 15-HpETE | S24: → | T24: 15(S)-HETE
I25: 15-keto-PGF2α | K25: 11β-PGF2α | N25: CYP450 | AH25: α-linolenic acid (ALA) | AK25: LOX | AL25: 9-HOTrE
I26: ↓ | R26: 12-HpETE | S26: → | T26: 12-HETE | AL26: 13-HOTrE
I27: PGFM
K30: 8-iso-PGF2α
K31: (Non-enzymatic)
M34: 5(6)-EpETrE | N34: 8(9)-EpETrE | O34: 11(12)-EpETrE | P34: 14(15)-EpETrE
M35: ↓ | N35: ↓ | O35: ↓ | P35: ↓
M36: 5,6-DiHETrE | N36: 8,9-DiHETrE | O36: 11,12-DiHETrE | P36: 14,15-DiHETrE
