Workbook

Sheet Results
B1: Absolute quantification of enzymatic oxyilipins profil with HPLC-QqQ
B4: Matrix: | E4: Fluid
B5: Normalize: | E5: Volume
B7: ='Raw Datas'!A55 -> pg/µL of fluid | E7: ='Raw Datas'!C1 -> KT-312D10 | F7: ='Raw Datas'!D1 -> BS-364D0 | G7: ='Raw Datas'!E1 -> KT-412D60 | H7: ='Raw Datas'!F1 -> KT-974D03 | I7: ='Raw Datas'!G1 -> JV-138D0 | J7: ='Raw Datas'!H1 -> BS-671D03 | K7: ='Raw Datas'!I1 -> KT-723D10 | L7: ='Raw Datas'!J1 -> KT-705D60 | ... FQ7: ='Raw Datas'!FO1 -> KT-974D60
A8: Precursor
A9: Linoleic acid C18:2ꙍ6 | B9: 9-HODE | C9: FA 18:2;O(12Z) | E9: ='Raw Datas'!C56 -> 14.865283 | F9: ='Raw Datas'!D56 -> 21.497567 | G9: ='Raw Datas'!E56 -> 10.8469 | H9: ='Raw Datas'!F56 -> 89.5585 | I9: ='Raw Datas'!G56 -> 35.85765 | J9: ='Raw Datas'!H56 -> 27.483217 | K9: ='Raw Datas'!I56 -> 14.128983 | L9: ='Raw Datas'!J56 -> 7.4184 | ... FQ9: ='Raw Datas'!FO56 -> 17.897417
B10: 10-HODE | C10: FA 18:2;O(12Z) | E10: ='Raw Datas'!C57 -> 0 | F10: ='Raw Datas'!D57 -> 0 | G10: ='Raw Datas'!E57 -> 0 | H10: ='Raw Datas'!F57 -> 0 | I10: ='Raw Datas'!G57 -> 0 | J10: ='Raw Datas'!H57 -> 0 | K10: ='Raw Datas'!I57 -> 0 | L10: ='Raw Datas'!J57 -> 0 | ... FQ10: ='Raw Datas'!FO57 -> 0
B11: 13-HODE | C11: FA 18:2;O(9Z) | E11: ='Raw Datas'!C58 -> 27.323333 | F11: ='Raw Datas'!D58 -> 47.252867 | G11: ='Raw Datas'!E58 -> 13.73985 | H11: ='Raw Datas'!F58 -> 108.00115 | I11: ='Raw Datas'!G58 -> 46.803067 | J11: ='Raw Datas'!H58 -> 33.524733 | K11: ='Raw Datas'!I58 -> 47.74745 | L11: ='Raw Datas'!J58 -> 19.417933 | ... FQ11: ='Raw Datas'!FO58 -> 29.08675
B12: 9,10-DiHOME | C12: FA 18:1;O2(12Z) | E12: ='Raw Datas'!C59 -> 1.97035 | F12: ='Raw Datas'!D59 -> 2.8201 | G12: ='Raw Datas'!E59 -> 4.6212333 | H12: ='Raw Datas'!F59 -> 13.86495 | I12: ='Raw Datas'!G59 -> 2.5101667 | J12: ='Raw Datas'!H59 -> 0.59873333 | K12: ='Raw Datas'!I59 -> 2.7499333 | L12: ='Raw Datas'!J59 -> 1.2010333 | ... FQ12: ='Raw Datas'!FO59 -> 1.6691167
B13: 12,13-DiHOME | C13: FA 18:1;O2(9Z) | E13: ='Raw Datas'!C60 -> 2.4824333 | F13: ='Raw Datas'!D60 -> 2.25685 | G13: ='Raw Datas'!E60 -> 4.97675 | H13: ='Raw Datas'!F60 -> 19.789067 | I13: ='Raw Datas'!G60 -> 2.1857333 | J13: ='Raw Datas'!H60 -> 0.61315 | K13: ='Raw Datas'!I60 -> 3.63365 | L13: ='Raw Datas'!J60 -> 0.93755 | ... FQ13: ='Raw Datas'!FO60 -> 2.86305
B14: 9-OxoODE | C14: FA 18:3;O(12E) | E14: ='Raw Datas'!C61 -> 1.7366167 | F14: ='Raw Datas'!D61 -> 0.71836667 | G14: ='Raw Datas'!E61 -> 0 | H14: ='Raw Datas'!F61 -> 6.35905 | I14: ='Raw Datas'!G61 -> 0.56305 | J14: ='Raw Datas'!H61 -> 0.18223333 | K14: ='Raw Datas'!I61 -> 0.13431667 | L14: ='Raw Datas'!J61 -> 0.13605 | ... FQ14: ='Raw Datas'!FO61 -> 0.18566667
B15: 13-OxoODE | C15: FA 18:3;O(9Z) | E15: ='Raw Datas'!C62 -> 2.0874 | F15: ='Raw Datas'!D62 -> 0.94246667 | G15: ='Raw Datas'!E62 -> 0 | H15: ='Raw Datas'!F62 -> 7.48095 | I15: ='Raw Datas'!G62 -> 2.31495 | J15: ='Raw Datas'!H62 -> 0.62655 | K15: ='Raw Datas'!I62 -> 0 | L15: ='Raw Datas'!J62 -> 0.23433333 | ... FQ15: ='Raw Datas'!FO62 -> 0
B16: 9,10,13-TriHOME | C16: FA 18:1;O3(11E) | E16: ='Raw Datas'!C63 -> 0.36576667 | F16: ='Raw Datas'!D63 -> 0.30868333 | G16: ='Raw Datas'!E63 -> 0.47098333 | H16: ='Raw Datas'!F63 -> 5.4668833 | I16: ='Raw Datas'!G63 -> 0 | J16: ='Raw Datas'!H63 -> 0.1987 | K16: ='Raw Datas'!I63 -> 0.14626667 | L16: ='Raw Datas'!J63 -> 0.2453 | ... FQ16: ='Raw Datas'!FO63 -> 0
B17: 9,12,13-TriHOME | C17: FA 18:1;O3(10E) | E17: ='Raw Datas'!C64 -> 1.4444167 | F17: ='Raw Datas'!D64 -> 1.2342667 | G17: ='Raw Datas'!E64 -> 2.72865 | H17: ='Raw Datas'!F64 -> 15.297733 | I17: ='Raw Datas'!G64 -> 0.48801667 | J17: ='Raw Datas'!H64 -> 0.92513333 | K17: ='Raw Datas'!I64 -> 1.8946833 | L17: ='Raw Datas'!J64 -> 1.0618833 | ... FQ17: ='Raw Datas'!FO64 -> 1.6807333
A19: Dihomo-gamma-linoleic acid C20:3ꙍ6 | B19: PGA1 | E19: ='Raw Datas'!C65 -> 0 | F19: ='Raw Datas'!D65 -> 0 | G19: ='Raw Datas'!E65 -> 0 | H19: ='Raw Datas'!F65 -> 0 | I19: ='Raw Datas'!G65 -> 0 | J19: ='Raw Datas'!H65 -> 0 | K19: ='Raw Datas'!I65 -> 0 | L19: ='Raw Datas'!J65 -> 0 | ... FQ19: ='Raw Datas'!FO65 -> 0
A21: Arachidonic acid C20:4ꙍ6 | B21: 5,6-EET | C21: FA 20:4;O(8Z,11Z,14Z) | E21: ='Raw Datas'!C66 -> 0 | F21: ='Raw Datas'!D66 -> 0 | G21: ='Raw Datas'!E66 -> 0 | H21: ='Raw Datas'!F66 -> 0 | I21: ='Raw Datas'!G66 -> 0 | J21: ='Raw Datas'!H66 -> 0 | K21: ='Raw Datas'!I66 -> 0 | L21: ='Raw Datas'!J66 -> 0 | ... FQ21: ='Raw Datas'!FO66 -> 0
B22: 8,9-EET | C22: FA 20:4;O(5Z,11Z,14Z) | E22: ='Raw Datas'!C67 -> 0.76226667 | F22: ='Raw Datas'!D67 -> 2.2586333 | G22: ='Raw Datas'!E67 -> 0 | H22: ='Raw Datas'!F67 -> 2.6011333 | I22: ='Raw Datas'!G67 -> 0.82863333 | J22: ='Raw Datas'!H67 -> 1.5406 | K22: ='Raw Datas'!I67 -> 2.9791 | L22: ='Raw Datas'!J67 -> 1.6943 | ... FQ22: ='Raw Datas'!FO67 -> 0
B23: 11,12-EET | C23: FA 20:4;O(5Z,8Z,14Z) | E23: ='Raw Datas'!C68 -> 0 | F23: ='Raw Datas'!D68 -> 0 | G23: ='Raw Datas'!E68 -> 0 | H23: ='Raw Datas'!F68 -> 0 | I23: ='Raw Datas'!G68 -> 0 | J23: ='Raw Datas'!H68 -> 0 | K23: ='Raw Datas'!I68 -> 0 | L23: ='Raw Datas'!J68 -> 0 | ... FQ23: ='Raw Datas'!FO68 -> 0
B24: 14,15-EET | C24: FA 20:4;O(5Z,8Z,11Z) | E24: ='Raw Datas'!C69 -> 0 | F24: ='Raw Datas'!D69 -> 0 | G24: ='Raw Datas'!E69 -> 0 | H24: ='Raw Datas'!F69 -> 0 | I24: ='Raw Datas'!G69 -> 0 | J24: ='Raw Datas'!H69 -> 0 | K24: ='Raw Datas'!I69 -> 0 | L24: ='Raw Datas'!J69 -> 0 | ... FQ24: ='Raw Datas'!FO69 -> 0
B25: 5-HETE | C25: FA 20:4;O(6E,8Z,11Z,14Z) | E25: ='Raw Datas'!C70 -> 96.875467 | F25: ='Raw Datas'!D70 -> 118.98988 | G25: ='Raw Datas'!E70 -> 125.0451 | H25: ='Raw Datas'!F70 -> 156.1364 | I25: ='Raw Datas'!G70 -> 173.93033 | J25: ='Raw Datas'!H70 -> 193.97865 | K25: ='Raw Datas'!I70 -> 93.744783 | L25: ='Raw Datas'!J70 -> 49.4655 | ... FQ25: ='Raw Datas'!FO70 -> 28.531367
B26: 8-HETE | C26: FA 20:4;O(5Z,9E,11Z,14Z) | E26: ='Raw Datas'!C71 -> 5.12275 | F26: ='Raw Datas'!D71 -> 11.544283 | G26: ='Raw Datas'!E71 -> 3.94405 | H26: ='Raw Datas'!F71 -> 11.911617 | I26: ='Raw Datas'!G71 -> 7.9660833 | J26: ='Raw Datas'!H71 -> 12.4113 | K26: ='Raw Datas'!I71 -> 13.142167 | L26: ='Raw Datas'!J71 -> 7.8844667 | ... FQ26: ='Raw Datas'!FO71 -> 2.1349833
B27: 12-HETE | C27: FA 20:4;O(5Z,8Z,10E,14Z) | E27: ='Raw Datas'!C72 -> 208.29615 | F27: ='Raw Datas'!D72 -> 954.27485 | G27: ='Raw Datas'!E72 -> 138.65638 | H27: ='Raw Datas'!F72 -> 927.74048 | I27: ='Raw Datas'!G72 -> 399.92992 | J27: ='Raw Datas'!H72 -> 444.51615 | K27: ='Raw Datas'!I72 -> 1101.6004 | L27: ='Raw Datas'!J72 -> 594.95652 | ... FQ27: ='Raw Datas'!FO72 -> 216.58352
B28: 15-HETE | C28: FA 20:4;O(5E,8Z,11Z,13Z) | E28: ='Raw Datas'!C73 -> 2.6258167 | F28: ='Raw Datas'!D73 -> 7.1347 | G28: ='Raw Datas'!E73 -> 1.6251 | H28: ='Raw Datas'!F73 -> 7.2202 | I28: ='Raw Datas'!G73 -> 4.51385 | J28: ='Raw Datas'!H73 -> 6.99615 | K28: ='Raw Datas'!I73 -> 8.9310167 | L28: ='Raw Datas'!J73 -> 5.3078 | ... FQ28: ='Raw Datas'!FO73 -> 3.4712333
B29: 5-oxo-ETE | C29: FA 20:5(6E,8Z,11Z,14Z) | E29: ='Raw Datas'!C74 -> 3.5515667 | F29: ='Raw Datas'!D74 -> 1.8797333 | G29: ='Raw Datas'!E74 -> 1.2228833 | H29: ='Raw Datas'!F74 -> 7.4822333 | I29: ='Raw Datas'!G74 -> 2.1341167 | J29: ='Raw Datas'!H74 -> 1.47055 | K29: ='Raw Datas'!I74 -> 0.86285 | L29: ='Raw Datas'!J74 -> 0.69088333 | ... FQ29: ='Raw Datas'!FO74 -> 0.18695
B30: LTB4 | C30: FA 20:4;O2(6Z,8E,10E,14Z) | E30: ='Raw Datas'!C75 -> 0 | F30: ='Raw Datas'!D75 -> 0 | G30: ='Raw Datas'!E75 -> 0 | H30: ='Raw Datas'!F75 -> 0 | I30: ='Raw Datas'!G75 -> 0 | J30: ='Raw Datas'!H75 -> 0 | K30: ='Raw Datas'!I75 -> 0 | L30: ='Raw Datas'!J75 -> 0 | ... FQ30: ='Raw Datas'!FO75 -> 0
B31: LxA4 | C31: FA 20:4;O3(7E,9E,11Z,13E) | E31: ='Raw Datas'!C76 -> 0.46458333 | F31: ='Raw Datas'!D76 -> 0.90195 | G31: ='Raw Datas'!E76 -> 1.21435 | H31: ='Raw Datas'!F76 -> 5.6536167 | I31: ='Raw Datas'!G76 -> 1.0921167 | J31: ='Raw Datas'!H76 -> 2.03055 | K31: ='Raw Datas'!I76 -> 0.68046667 | L31: ='Raw Datas'!J76 -> 0 | ... FQ31: ='Raw Datas'!FO76 -> 0.12246667
B32: LXB4 | C32: FA 20:4;O3(6E,8Z,10E,12E) | E32: ='Raw Datas'!C77 -> 0 | F32: ='Raw Datas'!D77 -> 0 | G32: ='Raw Datas'!E77 -> 0 | H32: ='Raw Datas'!F77 -> 0 | I32: ='Raw Datas'!G77 -> 0 | J32: ='Raw Datas'!H77 -> 0 | K32: ='Raw Datas'!I77 -> 0 | L32: ='Raw Datas'!J77 -> 0 | ... FQ32: ='Raw Datas'!FO77 -> 0
B33: 8isoPGA2 | C33: FA 20:5;O2(5Z,10Z,13E) | E33: ='Raw Datas'!C78 -> 0 | F33: ='Raw Datas'!D78 -> 0.17503333 | G33: ='Raw Datas'!E78 -> 0 | H33: ='Raw Datas'!F78 -> 1.0163667 | I33: ='Raw Datas'!G78 -> 0.11028333 | J33: ='Raw Datas'!H78 -> 0.26415 | K33: ='Raw Datas'!I78 -> 0.2027 | L33: ='Raw Datas'!J78 -> 0.18293333 | ... FQ33: ='Raw Datas'!FO78 -> 0.074066667
B34: PGD2 | C34: FA 20:4;O3(5Z,13E) | D34: Prostaglandin D2 | E34: ='Raw Datas'!C79 -> 0 | F34: ='Raw Datas'!D79 -> 0 | G34: ='Raw Datas'!E79 -> 0 | H34: ='Raw Datas'!F79 -> 0 | I34: ='Raw Datas'!G79 -> 0 | J34: ='Raw Datas'!H79 -> 0 | K34: ='Raw Datas'!I79 -> 0 | L34: ='Raw Datas'!J79 -> 0 | ... FQ34: ='Raw Datas'!FO79 -> 0
B35: PGE2 | C35: FA 20:4;O3(5Z,13E) | D35: Prostaglandin E2 | E35: ='Raw Datas'!C80 -> 0 | F35: ='Raw Datas'!D80 -> 0 | G35: ='Raw Datas'!E80 -> 0 | H35: ='Raw Datas'!F80 -> 1.8032333 | I35: ='Raw Datas'!G80 -> 0.49661667 | J35: ='Raw Datas'!H80 -> 0.53221667 | K35: ='Raw Datas'!I80 -> 0.54988333 | L35: ='Raw Datas'!J80 -> 0.57231667 | ... FQ35: ='Raw Datas'!FO80 -> 0.34343333
B36: PGF2a | C36: FA 20:3;O3 | D36: Prostaglandin F2alpha | E36: ='Raw Datas'!C81 -> 0.81108333 | F36: ='Raw Datas'!D81 -> 3.1465167 | G36: ='Raw Datas'!E81 -> 0 | H36: ='Raw Datas'!F81 -> 11.769667 | I36: ='Raw Datas'!G81 -> 1.95355 | J36: ='Raw Datas'!H81 -> 2.0054833 | K36: ='Raw Datas'!I81 -> 5.8764333 | L36: ='Raw Datas'!J81 -> 6.9467 | ... FQ36: ='Raw Datas'!FO81 -> 2.4813667
B37: 11B-PGF2a | D37: 11beta-Prostaglandin F2alpha-d4 | E37: ='Raw Datas'!C82 -> 0 | F37: ='Raw Datas'!D82 -> 0 | G37: ='Raw Datas'!E82 -> 0 | H37: ='Raw Datas'!F82 -> 0 | I37: ='Raw Datas'!G82 -> 0 | J37: ='Raw Datas'!H82 -> 0 | K37: ='Raw Datas'!I82 -> 0 | L37: ='Raw Datas'!J82 -> 0 | ... FQ37: ='Raw Datas'!FO82 -> 0
B38: PGFM | C38: FA 20:3;O3
B39: 15dPGJ2 | C39: FA 20:6;O | E39: ='Raw Datas'!C84 -> 0 | F39: ='Raw Datas'!D84 -> 0 | G39: ='Raw Datas'!E84 -> 0 | H39: ='Raw Datas'!F84 -> 0 | I39: ='Raw Datas'!G84 -> 0 | J39: ='Raw Datas'!H84 -> 0 | K39: ='Raw Datas'!I84 -> 0 | L39: ='Raw Datas'!J84 -> 0 | ... FQ39: ='Raw Datas'!FO84 -> 0
B40: 6kPGF1a | C40: FA 20:3;O4(13E) | E40: ='Raw Datas'!C85 -> 0 | F40: ='Raw Datas'!D85 -> 0 | G40: ='Raw Datas'!E85 -> 0 | H40: ='Raw Datas'!F85 -> 0 | I40: ='Raw Datas'!G85 -> 0 | J40: ='Raw Datas'!H85 -> 0 | K40: ='Raw Datas'!I85 -> 0 | L40: ='Raw Datas'!J85 -> 0 | ... FQ40: ='Raw Datas'!FO85 -> 0
B41: TXB2 | C41: FA 20:3;O4(5Z,13E) | E41: ='Raw Datas'!C86 -> 11.630633 | F41: ='Raw Datas'!D86 -> 21.740717 | G41: ='Raw Datas'!E86 -> 3.3182 | H41: ='Raw Datas'!F86 -> 56.4474 | I41: ='Raw Datas'!G86 -> 15.070783 | J41: ='Raw Datas'!H86 -> 15.813233 | K41: ='Raw Datas'!I86 -> 13.514317 | L41: ='Raw Datas'!J86 -> 12.89965 | ... FQ41: ='Raw Datas'!FO86 -> 9.6633167
A43: Alpha-linolenic acid C18:3ꙍ3 | B43: 9-HOTrE | C43: FA 18:3;O(10E,12Z,15Z) | E43: ='Raw Datas'!C87 -> 0.28581667 | F43: ='Raw Datas'!D87 -> 0.2091 | G43: ='Raw Datas'!E87 -> 0.2396 | H43: ='Raw Datas'!F87 -> 2.0031667 | I43: ='Raw Datas'!G87 -> 0.40756667 | J43: ='Raw Datas'!H87 -> 0.23085 | K43: ='Raw Datas'!I87 -> 0.10843333 | L43: ='Raw Datas'!J87 -> 0.078516667 | ... FQ43: ='Raw Datas'!FO87 -> 0.7863
B44: 13-HOTrE | C44: FA 18:3;O(9Z,11E,15Z) | E44: ='Raw Datas'!C88 -> 0.79061667 | F44: ='Raw Datas'!D88 -> 0.85391667 | G44: ='Raw Datas'!E88 -> 0.40045 | H44: ='Raw Datas'!F88 -> 2.1096 | I44: ='Raw Datas'!G88 -> 1.3896 | J44: ='Raw Datas'!H88 -> 0.5676 | K44: ='Raw Datas'!I88 -> 1.3167167 | L44: ='Raw Datas'!J88 -> 0.56136667 | ... FQ44: ='Raw Datas'!FO88 -> 0.82583333
A46: Eicosapentaenoic acid C20:5ꙍ3 | B46: 18-HEPE | C46: FA 20:5;O(5Z,8Z,11Z,14Z,16E) | E46: ='Raw Datas'!C89 -> 0 | F46: ='Raw Datas'!D89 -> 0.11438333 | G46: ='Raw Datas'!E89 -> 0 | H46: ='Raw Datas'!F89 -> 0.26216667 | I46: ='Raw Datas'!G89 -> 0.23558333 | J46: ='Raw Datas'!H89 -> 0.14326667 | K46: ='Raw Datas'!I89 -> 1.3614167 | L46: ='Raw Datas'!J89 -> 0.30045 | ... FQ46: ='Raw Datas'!FO89 -> 0
B47: LTB5 | C47: FA 20:5;O2 | E47: ='Raw Datas'!C90 -> 0 | F47: ='Raw Datas'!D90 -> 0 | G47: ='Raw Datas'!E90 -> 0 | H47: ='Raw Datas'!F90 -> 0 | I47: ='Raw Datas'!G90 -> 0 | J47: ='Raw Datas'!H90 -> 0 | K47: ='Raw Datas'!I90 -> 0 | L47: ='Raw Datas'!J90 -> 0 | ... FQ47: ='Raw Datas'!FO90 -> 0
...

Sheet Feuil1
A1: feature | B1: ='Raw Datas'!C1 -> KT-312D10 | C1: ='Raw Datas'!D1 -> BS-364D0 | D1: ='Raw Datas'!E1 -> KT-412D60 | E1: ='Raw Datas'!F1 -> KT-974D03 | F1: ='Raw Datas'!G1 -> JV-138D0 | G1: ='Raw Datas'!H1 -> BS-671D03 | H1: ='Raw Datas'!I1 -> KT-723D10 | I1: ='Raw Datas'!J1 -> KT-705D60 | ... FN1: ='Raw Datas'!FO1 -> KT-974D60
A2: FA 18:2;O | B2: ='Raw Datas'!C56 -> 14.865283 | C2: ='Raw Datas'!D56 -> 21.497567 | D2: ='Raw Datas'!E56 -> 10.8469 | E2: ='Raw Datas'!F56 -> 89.5585 | F2: ='Raw Datas'!G56 -> 35.85765 | G2: ='Raw Datas'!H56 -> 27.483217 | H2: ='Raw Datas'!I56 -> 14.128983 | I2: ='Raw Datas'!J56 -> 7.4184 | ... FN2: ='Raw Datas'!FO56 -> 17.897417
A3: FA 18:1;O2 | B3: ='Raw Datas'!C59 -> 1.97035 | C3: ='Raw Datas'!D59 -> 2.8201 | D3: ='Raw Datas'!E59 -> 4.6212333 | E3: ='Raw Datas'!F59 -> 13.86495 | F3: ='Raw Datas'!G59 -> 2.5101667 | G3: ='Raw Datas'!H59 -> 0.59873333 | H3: ='Raw Datas'!I59 -> 2.7499333 | I3: ='Raw Datas'!J59 -> 1.2010333 | ... FN3: ='Raw Datas'!FO59 -> 1.6691167
A4: FA 18:3;O | B4: ='Raw Datas'!C61 -> 1.7366167 | C4: ='Raw Datas'!D61 -> 0.71836667 | D4: ='Raw Datas'!E61 -> 0 | E4: ='Raw Datas'!F61 -> 6.35905 | F4: ='Raw Datas'!G61 -> 0.56305 | G4: ='Raw Datas'!H61 -> 0.18223333 | H4: ='Raw Datas'!I61 -> 0.13431667 | I4: ='Raw Datas'!J61 -> 0.13605 | ... FN4: ='Raw Datas'!FO61 -> 0.18566667
A5: FA 18:1;O3 | B5: ='Raw Datas'!C63 -> 0.36576667 | C5: ='Raw Datas'!D63 -> 0.30868333 | D5: ='Raw Datas'!E63 -> 0.47098333 | E5: ='Raw Datas'!F63 -> 5.4668833 | F5: ='Raw Datas'!G63 -> 0 | G5: ='Raw Datas'!H63 -> 0.1987 | H5: ='Raw Datas'!I63 -> 0.14626667 | I5: ='Raw Datas'!J63 -> 0.2453 | ... FN5: ='Raw Datas'!FO63 -> 0
A8: FA 20:4;O | B8: ='Raw Datas'!C67 -> 0.76226667 | C8: ='Raw Datas'!D67 -> 2.2586333 | D8: ='Raw Datas'!E67 -> 0 | E8: ='Raw Datas'!F67 -> 2.6011333 | F8: ='Raw Datas'!G67 -> 0.82863333 | G8: ='Raw Datas'!H67 -> 1.5406 | H8: ='Raw Datas'!I67 -> 2.9791 | I8: ='Raw Datas'!J67 -> 1.6943 | ... FN8: ='Raw Datas'!FO67 -> 0
A9: FA 20:5 | B9: ='Raw Datas'!C74 -> 3.5515667 | C9: ='Raw Datas'!D74 -> 1.8797333 | D9: ='Raw Datas'!E74 -> 1.2228833 | E9: ='Raw Datas'!F74 -> 7.4822333 | F9: ='Raw Datas'!G74 -> 2.1341167 | G9: ='Raw Datas'!H74 -> 1.47055 | H9: ='Raw Datas'!I74 -> 0.86285 | I9: ='Raw Datas'!J74 -> 0.69088333 | ... FN9: ='Raw Datas'!FO74 -> 0.18695
A10: FA 20:4;O3 | B10: ='Raw Datas'!C76 -> 0.46458333 | C10: ='Raw Datas'!D76 -> 0.90195 | D10: ='Raw Datas'!E76 -> 1.21435 | E10: ='Raw Datas'!F76 -> 5.6536167 | F10: ='Raw Datas'!G76 -> 1.0921167 | G10: ='Raw Datas'!H76 -> 2.03055 | H10: ='Raw Datas'!I76 -> 0.68046667 | I10: ='Raw Datas'!J76 -> 0 | ... FN10: ='Raw Datas'!FO76 -> 0.12246667
A11: FA 20:3;O4 | B11: ='Raw Datas'!C86 -> 11.630633 | C11: ='Raw Datas'!D86 -> 21.740717 | D11: ='Raw Datas'!E86 -> 3.3182 | E11: ='Raw Datas'!F86 -> 56.4474 | F11: ='Raw Datas'!G86 -> 15.070783 | G11: ='Raw Datas'!H86 -> 15.813233 | H11: ='Raw Datas'!I86 -> 13.514317 | I11: ='Raw Datas'!J86 -> 12.89965 | ... FN11: ='Raw Datas'!FO86 -> 9.6633167
A12: FA 20:5;O | B12: ='Raw Datas'!C89 -> 0 | C12: ='Raw Datas'!D89 -> 0.11438333 | D12: ='Raw Datas'!E89 -> 0 | E12: ='Raw Datas'!F89 -> 0.26216667 | F12: ='Raw Datas'!G89 -> 0.23558333 | G12: ='Raw Datas'!H89 -> 0.14326667 | H12: ='Raw Datas'!I89 -> 1.3614167 | I12: ='Raw Datas'!J89 -> 0.30045 | ... FN12: ='Raw Datas'!FO89 -> 0
A13: FA 22:6;O | B13: ='Raw Datas'!C94 -> 60.11 | C13: ='Raw Datas'!D94 -> 223.86982 | D13: ='Raw Datas'!E94 -> 28.000933 | E13: ='Raw Datas'!F94 -> 162.6376 | F13: ='Raw Datas'!G94 -> 122.10465 | G13: ='Raw Datas'!H94 -> 143.1937 | H13: ='Raw Datas'!I94 -> 551.66067 | I13: ='Raw Datas'!J94 -> 214.54028 | ... FN13: ='Raw Datas'!FO94 -> 78.768317

Sheet Feuil2
B1: Absolute quantification of enzymatic oxyilipins profil with HPLC-QqQ
B4: Matrix: | C4: Fluid
B5: Normalize: | C5: Volume
B7: ='Raw Datas'!A55 -> pg/µL of fluid | C7: ='Raw Datas'!C1 -> KT-312D10 | D7: ='Raw Datas'!D1 -> BS-364D0 | E7: ='Raw Datas'!E1 -> KT-412D60 | F7: ='Raw Datas'!F1 -> KT-974D03 | G7: ='Raw Datas'!G1 -> JV-138D0 | H7: ='Raw Datas'!H1 -> BS-671D03 | I7: ='Raw Datas'!I1 -> KT-723D10 | J7: ='Raw Datas'!J1 -> KT-705D60 | ... FO7: ='Raw Datas'!FO1 -> KT-974D60
A8: Precursor
A9: Linoleic acid C18:2ꙍ6 | B9: FA 18:2;O | C9: ='Raw Datas'!C58 -> 27.323333 | D9: ='Raw Datas'!D58 -> 47.252867 | E9: ='Raw Datas'!E58 -> 13.73985 | F9: ='Raw Datas'!F58 -> 108.00115 | G9: ='Raw Datas'!G58 -> 46.803067 | H9: ='Raw Datas'!H58 -> 33.524733 | I9: ='Raw Datas'!I58 -> 47.74745 | J9: ='Raw Datas'!J58 -> 19.417933 | ... FO9: ='Raw Datas'!FO58 -> 29.08675
B10: FA 18:1;O2 | C10: ='Raw Datas'!C60 -> 2.4824333 | D10: ='Raw Datas'!D60 -> 2.25685 | E10: ='Raw Datas'!E60 -> 4.97675 | F10: ='Raw Datas'!F60 -> 19.789067 | G10: ='Raw Datas'!G60 -> 2.1857333 | H10: ='Raw Datas'!H60 -> 0.61315 | I10: ='Raw Datas'!I60 -> 3.63365 | J10: ='Raw Datas'!J60 -> 0.93755 | ... FO10: ='Raw Datas'!FO60 -> 2.86305
B11: FA 18:3;O | C11: ='Raw Datas'!C62 -> 2.0874 | D11: ='Raw Datas'!D62 -> 0.94246667 | E11: ='Raw Datas'!E62 -> 0 | F11: ='Raw Datas'!F62 -> 7.48095 | G11: ='Raw Datas'!G62 -> 2.31495 | H11: ='Raw Datas'!H62 -> 0.62655 | I11: ='Raw Datas'!I62 -> 0 | J11: ='Raw Datas'!J62 -> 0.23433333 | ... FO11: ='Raw Datas'!FO62 -> 0
B12: FA 18:1;O3 | C12: ='Raw Datas'!C64 -> 1.4444167 | D12: ='Raw Datas'!D64 -> 1.2342667 | E12: ='Raw Datas'!E64 -> 2.72865 | F12: ='Raw Datas'!F64 -> 15.297733 | G12: ='Raw Datas'!G64 -> 0.48801667 | H12: ='Raw Datas'!H64 -> 0.92513333 | I12: ='Raw Datas'!I64 -> 1.8946833 | J12: ='Raw Datas'!J64 -> 1.0618833 | ... FO12: ='Raw Datas'!FO64 -> 1.6807333
A15: Arachidonic acid C20:4ꙍ6 | B15: FA 20:4;O | C15: ='Raw Datas'!C70 -> 96.875467 | D15: ='Raw Datas'!D70 -> 118.98988 | E15: ='Raw Datas'!E70 -> 125.0451 | F15: ='Raw Datas'!F70 -> 156.1364 | G15: ='Raw Datas'!G70 -> 173.93033 | H15: ='Raw Datas'!H70 -> 193.97865 | I15: ='Raw Datas'!I70 -> 93.744783 | J15: ='Raw Datas'!J70 -> 49.4655 | ... FO15: ='Raw Datas'!FO70 -> 28.531367
B16: FA 20:4;O3 | C16: ='Raw Datas'!C80 -> 0 | D16: ='Raw Datas'!D80 -> 0 | E16: ='Raw Datas'!E80 -> 0 | F16: ='Raw Datas'!F80 -> 1.8032333 | G16: ='Raw Datas'!G80 -> 0.49661667 | H16: ='Raw Datas'!H80 -> 0.53221667 | I16: ='Raw Datas'!I80 -> 0.54988333 | J16: ='Raw Datas'!J80 -> 0.57231667 | ... FO16: ='Raw Datas'!FO80 -> 0.34343333
A18: Alpha-linolenic acid C18:3ꙍ3 | B18: FA 18:3;O | C18: ='Raw Datas'!C88 -> 0.79061667 | D18: ='Raw Datas'!D88 -> 0.85391667 | E18: ='Raw Datas'!E88 -> 0.40045 | F18: ='Raw Datas'!F88 -> 2.1096 | G18: ='Raw Datas'!G88 -> 1.3896 | H18: ='Raw Datas'!H88 -> 0.5676 | I18: ='Raw Datas'!I88 -> 1.3167167 | J18: ='Raw Datas'!J88 -> 0.56136667 | ... FO18: ='Raw Datas'!FO88 -> 0.82583333
A20: Eicosapentaenoic acid C20:5ꙍ3 | B20: FA 20:5;O | C20: ='Raw Datas'!C89 -> 0 | D20: ='Raw Datas'!D89 -> 0.11438333 | E20: ='Raw Datas'!E89 -> 0 | F20: ='Raw Datas'!F89 -> 0.26216667 | G20: ='Raw Datas'!G89 -> 0.23558333 | H20: ='Raw Datas'!H89 -> 0.14326667 | I20: ='Raw Datas'!I89 -> 1.3614167 | J20: ='Raw Datas'!J89 -> 0.30045 | ... FO20: ='Raw Datas'!FO89 -> 0
A22: Docosahexaenoic acid C22:6ꙍ3 | B22: FA 22:6;O | C22: ='Raw Datas'!C95 -> 2.5767 | D22: ='Raw Datas'!D95 -> 4.1894833 | E22: ='Raw Datas'!E95 -> 0.94011667 | F22: ='Raw Datas'!F95 -> 2.8106 | G22: ='Raw Datas'!G95 -> 3.8370833 | H22: ='Raw Datas'!H95 -> 4.9248 | I22: ='Raw Datas'!I95 -> 7.7584667 | J22: ='Raw Datas'!J95 -> 4.0750167 | ... FO22: ='Raw Datas'!FO95 -> 1.9704167
B25: =B7 -> pg/µL of fluid | C25: =C7 -> KT-312D10 | D25: =D7 -> BS-364D0 | E25: =E7 -> KT-412D60 | F25: =F7 -> KT-974D03 | G25: =G7 -> JV-138D0 | H25: =H7 -> BS-671D03 | I25: =I7 -> KT-723D10 | ... FO25: =FO7 -> KT-974D60
B26: Total oxylipins issued from LA cascade | C26: =SUM(C9:C12) -> 33.337583 | D26: =SUM(D9:D12) -> 51.68645 | E26: =SUM(E9:E12) -> 21.44525 | F26: =SUM(F9:F12) -> 150.5689 | G26: =SUM(G9:G12) -> 51.791767 | H26: =SUM(H9:H12) -> 35.689567 | I26: =SUM(I9:I12) -> 53.275783 | J26: =SUM(J9:J12) -> 21.6517 | ... FO26: =SUM(FO9:FO12) -> 33.630533
B27: Total oxylipins issued from DGLA cascade | C27: =SUM(#REF!) -> #REF! | D27: =SUM(#REF!) -> #REF! | E27: =SUM(#REF!) -> #REF! | F27: =SUM(#REF!) -> #REF! | G27: =SUM(#REF!) -> #REF! | H27: =SUM(#REF!) -> #REF! | I27: =SUM(#REF!) -> #REF! | J27: =SUM(#REF!) -> #REF! | ... FO27: =SUM(#REF!) -> #REF!
B28: Total oxylipins issued from AA cascade | C28: =SUM(C15:C16) -> 96.875467 | D28: =SUM(D15:D16) -> 118.98988 | E28: =SUM(E15:E16) -> 125.0451 | F28: =SUM(F15:F16) -> 157.93963 | G28: =SUM(G15:G16) -> 174.42695 | H28: =SUM(H15:H16) -> 194.51087 | I28: =SUM(I15:I16) -> 94.294667 | J28: =SUM(J15:J16) -> 50.037817 | ... FO28: =SUM(FO15:FO16) -> 28.8748
B29: Total oxylipins issued from alpha-LA cascade | C29: =SUM(C18:C18) -> 0.79061667 | D29: =SUM(D18:D18) -> 0.85391667 | E29: =SUM(E18:E18) -> 0.40045 | F29: =SUM(F18:F18) -> 2.1096 | G29: =SUM(G18:G18) -> 1.3896 | H29: =SUM(H18:H18) -> 0.5676 | I29: =SUM(I18:I18) -> 1.3167167 | J29: =SUM(J18:J18) -> 0.56136667 | ... FO29: =SUM(FO18:FO18) -> 0.82583333
B30: Total oxylipins issued from EPA cascade | C30: =SUM(C20:C20) -> 0 | D30: =SUM(D20:D20) -> 0.11438333 | E30: =SUM(E20:E20) -> 0 | F30: =SUM(F20:F20) -> 0.26216667 | G30: =SUM(G20:G20) -> 0.23558333 | H30: =SUM(H20:H20) -> 0.14326667 | I30: =SUM(I20:I20) -> 1.3614167 | J30: =SUM(J20:J20) -> 0.30045 | ... FO30: =SUM(FO20:FO20) -> 0
B31: Total oxylipins issued from DHA cascade | C31: =SUM(C22:C22) -> 2.5767 | D31: =SUM(D22:D22) -> 4.1894833 | E31: =SUM(E22:E22) -> 0.94011667 | F31: =SUM(F22:F22) -> 2.8106 | G31: =SUM(G22:G22) -> 3.8370833 | H31: =SUM(H22:H22) -> 4.9248 | I31: =SUM(I22:I22) -> 7.7584667 | J31: =SUM(J22:J22) -> 4.0750167 | ... FO31: =SUM(FO22:FO22) -> 1.9704167
B32: Total | C32: =SUM(C26:C31) -> #REF! | D32: =SUM(D26:D31) -> #REF! | E32: =SUM(E26:E31) -> #REF! | F32: =SUM(F26:F31) -> #REF! | G32: =SUM(G26:G31) -> #REF! | H32: =SUM(H26:H31) -> #REF! | I32: =SUM(I26:I31) -> #REF! | J32: =SUM(J26:J31) -> #REF! | ... FO32: =SUM(FO26:FO31) -> #REF!

Sheet Feuil3
B1: Absolute quantification of enzymatic oxyilipins profil with HPLC-QqQ
B4: Matrix: | E4: Fluid
B5: Normalize: | E5: Volume
B7: ='Raw Datas'!A55 -> pg/µL of fluid | E7: ='Raw Datas'!C1 -> KT-312D10 | F7: ='Raw Datas'!D1 -> BS-364D0 | G7: ='Raw Datas'!E1 -> KT-412D60 | H7: ='Raw Datas'!F1 -> KT-974D03 | I7: ='Raw Datas'!G1 -> JV-138D0 | J7: ='Raw Datas'!H1 -> BS-671D03 | K7: ='Raw Datas'!I1 -> KT-723D10 | L7: ='Raw Datas'!J1 -> KT-705D60 | ... FQ7: ='Raw Datas'!FO1 -> KT-974D60
A8: Precursor
B9: 8,9-EET | C9: FA 20:4;O(5Z,11Z,14Z) | E9: ='Raw Datas'!C67 -> 0.76226667 | F9: ='Raw Datas'!D67 -> 2.2586333 | G9: ='Raw Datas'!E67 -> 0 | H9: ='Raw Datas'!F67 -> 2.6011333 | I9: ='Raw Datas'!G67 -> 0.82863333 | J9: ='Raw Datas'!H67 -> 1.5406 | K9: ='Raw Datas'!I67 -> 2.9791 | L9: ='Raw Datas'!J67 -> 1.6943 | ... FQ9: ='Raw Datas'!FO67 -> 0
B10: 5-HETE | C10: FA 20:4;O(6E,8Z,11Z,14Z) | E10: ='Raw Datas'!C70 -> 96.875467 | F10: ='Raw Datas'!D70 -> 118.98988 | G10: ='Raw Datas'!E70 -> 125.0451 | H10: ='Raw Datas'!F70 -> 156.1364 | I10: ='Raw Datas'!G70 -> 173.93033 | J10: ='Raw Datas'!H70 -> 193.97865 | K10: ='Raw Datas'!I70 -> 93.744783 | L10: ='Raw Datas'!J70 -> 49.4655 | ... FQ10: ='Raw Datas'!FO70 -> 28.531367
B11: 8-HETE | C11: FA 20:4;O(5Z,9E,11Z,14Z) | E11: ='Raw Datas'!C71 -> 5.12275 | F11: ='Raw Datas'!D71 -> 11.544283 | G11: ='Raw Datas'!E71 -> 3.94405 | H11: ='Raw Datas'!F71 -> 11.911617 | I11: ='Raw Datas'!G71 -> 7.9660833 | J11: ='Raw Datas'!H71 -> 12.4113 | K11: ='Raw Datas'!I71 -> 13.142167 | L11: ='Raw Datas'!J71 -> 7.8844667 | ... FQ11: ='Raw Datas'!FO71 -> 2.1349833
B12: 12-HETE | C12: FA 20:4;O(5Z,8Z,10E,14Z) | E12: ='Raw Datas'!C72 -> 208.29615 | F12: ='Raw Datas'!D72 -> 954.27485 | G12: ='Raw Datas'!E72 -> 138.65638 | H12: ='Raw Datas'!F72 -> 927.74048 | I12: ='Raw Datas'!G72 -> 399.92992 | J12: ='Raw Datas'!H72 -> 444.51615 | K12: ='Raw Datas'!I72 -> 1101.6004 | L12: ='Raw Datas'!J72 -> 594.95652 | ... FQ12: ='Raw Datas'!FO72 -> 216.58352
B13: 15-HETE | C13: FA 20:4;O(5E,8Z,11Z,13Z) | E13: ='Raw Datas'!C73 -> 2.6258167 | F13: ='Raw Datas'!D73 -> 7.1347 | G13: ='Raw Datas'!E73 -> 1.6251 | H13: ='Raw Datas'!F73 -> 7.2202 | I13: ='Raw Datas'!G73 -> 4.51385 | J13: ='Raw Datas'!H73 -> 6.99615 | K13: ='Raw Datas'!I73 -> 8.9310167 | L13: ='Raw Datas'!J73 -> 5.3078 | ... FQ13: ='Raw Datas'!FO73 -> 3.4712333
B14: PGF2a | C14: FA 20:3;O3 | D14: Prostaglandin F2alpha | E14: ='Raw Datas'!C81 -> 0.81108333 | F14: ='Raw Datas'!D81 -> 3.1465167 | G14: ='Raw Datas'!E81 -> 0 | H14: ='Raw Datas'!F81 -> 11.769667 | I14: ='Raw Datas'!G81 -> 1.95355 | J14: ='Raw Datas'!H81 -> 2.0054833 | K14: ='Raw Datas'!I81 -> 5.8764333 | L14: ='Raw Datas'!J81 -> 6.9467 | ... FQ14: ='Raw Datas'!FO81 -> 2.4813667
B15: 9-HOTrE | C15: FA 18:3;O | D15: ='Raw Datas'!C87 -> 0.28581667 | E15: ='Raw Datas'!D87 -> 0.2091 | F15: ='Raw Datas'!E87 -> 0.2396 | G15: ='Raw Datas'!F87 -> 2.0031667 | H15: ='Raw Datas'!G87 -> 0.40756667 | I15: ='Raw Datas'!H87 -> 0.23085 | J15: ='Raw Datas'!I87 -> 0.10843333 | K15: ='Raw Datas'!J87 -> 0.078516667 | ... FP15: ='Raw Datas'!FO87 -> 0.7863
A16: Docosahexaenoic acid C22:6ꙍ3 | B16: 14-HDHA | C16: FA 22:6;O(4Z,7Z,10Z,12E,16Z,19Z) | E16: ='Raw Datas'!C94 -> 60.11 | F16: ='Raw Datas'!D94 -> 223.86982 | G16: ='Raw Datas'!E94 -> 28.000933 | H16: ='Raw Datas'!F94 -> 162.6376 | I16: ='Raw Datas'!G94 -> 122.10465 | J16: ='Raw Datas'!H94 -> 143.1937 | K16: ='Raw Datas'!I94 -> 551.66067 | L16: ='Raw Datas'!J94 -> 214.54028 | ... FQ16: ='Raw Datas'!FO94 -> 78.768317
B17: 17-HDHA | C17: FA 22:6;O(4Z,7Z,10Z,13Z,15E,19Z) | E17: ='Raw Datas'!C95 -> 2.5767 | F17: ='Raw Datas'!D95 -> 4.1894833 | G17: ='Raw Datas'!E95 -> 0.94011667 | H17: ='Raw Datas'!F95 -> 2.8106 | I17: ='Raw Datas'!G95 -> 3.8370833 | J17: ='Raw Datas'!H95 -> 4.9248 | K17: ='Raw Datas'!I95 -> 7.7584667 | L17: ='Raw Datas'!J95 -> 4.0750167 | ... FQ17: ='Raw Datas'!FO95 -> 1.9704167
B20: =B7 -> pg/µL of fluid | E20: =E7 -> KT-312D10 | F20: =F7 -> BS-364D0 | G20: =G7 -> KT-412D60 | H20: =H7 -> KT-974D03 | I20: =I7 -> JV-138D0 | J20: =J7 -> BS-671D03 | K20: =K7 -> KT-723D10 | L20: =L7 -> KT-705D60 | ... FQ20: =FQ7 -> KT-974D60
B21: Total oxylipins issued from LA cascade | E21: =SUM(#REF!) -> #REF! | F21: =SUM(#REF!) -> #REF! | G21: =SUM(#REF!) -> #REF! | H21: =SUM(#REF!) -> #REF! | I21: =SUM(#REF!) -> #REF! | J21: =SUM(#REF!) -> #REF! | K21: =SUM(#REF!) -> #REF! | L21: =SUM(#REF!) -> #REF! | ... FQ21: =SUM(#REF!) -> #REF!
B22: Total oxylipins issued from DGLA cascade | E22: =SUM(#REF!) -> #REF! | F22: =SUM(#REF!) -> #REF! | G22: =SUM(#REF!) -> #REF! | H22: =SUM(#REF!) -> #REF! | I22: =SUM(#REF!) -> #REF! | J22: =SUM(#REF!) -> #REF! | K22: =SUM(#REF!) -> #REF! | L22: =SUM(#REF!) -> #REF! | ... FQ22: =SUM(#REF!) -> #REF!
B23: Total oxylipins issued from AA cascade | E23: =SUM(E9:E14) -> 314.49353 | F23: =SUM(F9:F14) -> 1097.3489 | G23: =SUM(G9:G14) -> 269.27063 | H23: =SUM(H9:H14) -> 1117.3795 | I23: =SUM(I9:I14) -> 589.12237 | J23: =SUM(J9:J14) -> 661.44833 | K23: =SUM(K9:K14) -> 1226.2739 | L23: =SUM(L9:L14) -> 666.25528 | ... FQ23: =SUM(FQ9:FQ14) -> 253.20247
B24: Total oxylipins issued from alpha-LA cascade | E24: =SUM(#REF!) -> #REF! | F24: =SUM(#REF!) -> #REF! | G24: =SUM(#REF!) -> #REF! | H24: =SUM(#REF!) -> #REF! | I24: =SUM(#REF!) -> #REF! | J24: =SUM(#REF!) -> #REF! | K24: =SUM(#REF!) -> #REF! | L24: =SUM(#REF!) -> #REF! | ... FQ24: =SUM(#REF!) -> #REF!
B25: Total oxylipins issued from EPA cascade | E25: =SUM(#REF!) -> #REF! | F25: =SUM(#REF!) -> #REF! | G25: =SUM(#REF!) -> #REF! | H25: =SUM(#REF!) -> #REF! | I25: =SUM(#REF!) -> #REF! | J25: =SUM(#REF!) -> #REF! | K25: =SUM(#REF!) -> #REF! | L25: =SUM(#REF!) -> #REF! | ... FQ25: =SUM(#REF!) -> #REF!
B26: Total oxylipins issued from DHA cascade | E26: =SUM(E16:E17) -> 62.6867 | F26: =SUM(F16:F17) -> 228.0593 | G26: =SUM(G16:G17) -> 28.94105 | H26: =SUM(H16:H17) -> 165.4482 | I26: =SUM(I16:I17) -> 125.94173 | J26: =SUM(J16:J17) -> 148.1185 | K26: =SUM(K16:K17) -> 559.41913 | L26: =SUM(L16:L17) -> 218.6153 | ... FQ26: =SUM(FQ16:FQ17) -> 80.738733
B27: Total | E27: =SUM(E21:E26) -> #REF! | F27: =SUM(F21:F26) -> #REF! | G27: =SUM(G21:G26) -> #REF! | H27: =SUM(H21:H26) -> #REF! | I27: =SUM(I21:I26) -> #REF! | J27: =SUM(J21:J26) -> #REF! | K27: =SUM(K21:K26) -> #REF! | L27: =SUM(L21:L26) -> #REF! | ... FQ27: =SUM(FQ21:FQ26) -> #REF!

Sheet Raw Datas
A1: Sample name | C1: KT-312D10 | D1: BS-364D0 | E1: KT-412D60 | F1: KT-974D03 | G1: JV-138D0 | H1: BS-671D03 | I1: KT-723D10 | J1: KT-705D60 | K1: KT-434D03 | L1: BS-082D60 | M1: BS-064D0 | N1: BS-336D10 | O1: KT-723D60 | P1: KT-612D10 | Q1: KT-705D03 | R1: JV-157D0 | S1: JV-148D60 | T1: KT-663D0 | U1: BS-346D03 | V1: JV-048D10 | W1: BS-351D0 | X1: JV-148D10 | Y1: KT-929D60 | Z1: BS-336D03 | AA1: KT-771D10 | AB1: KT-695D03 | AC1: KT-612D0 | AD1: KT-312D60 | AE1: KT-927D03 | AF1: JV-071D60 | AG1: KT-193D10 | AH1: KT-247D0 | AI1: BS-064D03 | AJ1: KT-537D60 | AK1: BS-377D0 | AL1: KT-347D10 | AM1: JV-138D60 | AN1: JV-138D10 | AO1: KT-247D03 | AP1: KT-718D0 | AQ1: BS-082D10 | AR1: KT-445D0 | AS1: KT-716D60 | AT1: KT-347D03 | AU1: KT-805D0 | AV1: BS-351D03 | AW1: KT-538D10 | AX1: JV-035D60 | AY1: KT-718D03 | AZ1: KT-723D0 | BA1: KT-515D10 | BB1: KT-412D03 | BC1: KT-313D10 | BD1: BS-377D60 | BE1: KT-417D0 | BF1: KT-412D10 | BG1: KT-515D0 | BH1: JV-148D03 | BI1: KT-313D0 | BJ1: KT-445D60 | BK1: KT-434D10 | BL1: BS-082D03 | BM1: KT-880D03 | BN1: KT-247D60 | BO1: KT-705D10 | BP1: BS-082D0 | BQ1: JV-157D60 | BR1: KT-312D0 | BS1: KT-445D03 | BT1: BS-377D10 | BU1: KT-695D0 | BV1: BS-351D10 | BW1: KT-417D60 | BX1: JV-138D03 | BY1: KT-805D10 | BZ1: JV-048D03 | CA1: KT-705D0 | CB1: BS-671D60 | CC1: JV-157D03 | CD1: KT-974D0 | CE1: BS-364D60 | CF1: KT-716D10 | CG1: KT-538D0 | CH1: KT-718D10 | CI1: KT-538D03 | CJ1: KT-805D60 | CK1: KT-612D60 | CL1: KT-926D0 | CM1: KT-193D03 | CN1: KT-663D60 | CO1: KT-352D03 | CP1: KT-537D10 | CQ1: JV-035D0 | CR1: KT-522D60 | CS1: KT-352D10 | CT1: KT-716D03 | CU1: KT-716D0 | CV1: BS-346D10 | CW1: KT-347D0 | CX1: BS-336D60 | CY1: KT-515D03 | CZ1: KT-352D0 | DA1: KT-771D03 | DB1: BS-364D10 | DC1: BS-064D60 | DD1: KT-723D03 | DE1: KT-538D60 | DF1: KT-193D0 | DG1: KT-445D10 | DH1: KT-771D0 | DI1: KT-247D10 | DJ1: KT-515D60 | DK1: JV-071D03 | DL1: KT-525D10 | DM1: KT-522D03 | DN1: KT-525D0 | DO1: BS-346D60 | DP1: KT-525D03 | DQ1: KT-771D60 | DR1: KT-417D10 | DS1: JV-048D0 | DT1: KT-539D60 | DU1: KT-880D0 | DV1: KT-805D03 | DW1: KT-565D10 | DX1: BS-351D60 | DY1: KT-663D03 | DZ1: KT-695D10 | EA1: KT-539D0 | EB1: KT-539D03 | EC1: BS-671D0 | ED1: KT-313D60 | EE1: BS-064D10 | EF1: BS-346D0 | EG1: KT-522D10 | EH1: KT-565D03 | EI1: KT-695D60 | EJ1: KT-928D10 | EK1: KT-347D60 | EL1: KT-522D0 | EM1: BS-364D03 | EN1: KT-352D60 | EO1: JV-157D10 | EP1: KT-565D0 | EQ1: KT-612D03 | ER1: KT-974D10 | ES1: KT-537D03 | ET1: KT-718D60 | EU1: JV-071D0 | EV1: KT-312D03 | EW1: BS-336D0 | EX1: KT-880D10 | EY1: KT-193D60 | EZ1: JV-148D0 | FA1: KT-434D60 | FB1: KT-417D03 | FC1: KT-663D10 | FD1: KT-525D60 | FE1: KT-539D10 | FF1: KT-537D0 | FG1: KT-313D03 | FH1: JV-035D10 | FI1: BS-377D03 | FJ1: KT-880D60 | FK1: KT-434D0 | FL1: JV-035D03 | FM1: KT-412D0 | FN1: BS-671D10 | FO1: KT-974D60
C2: 241008GMI_oxy_011_29 | D2: 241008GMI_oxy_033_51 | E2: 241009GMI_oxy_136_151 | F2: 241009GMI_oxy_108_123 | G2: 241008GMI_oxy_068_84 | H2: 241008GMI_oxy_064_80 | I2: 241008GMI_oxy_041_59 | J2: 241008GMI_oxy_010_28 | K2: 241009GMI_oxy_154_169 | L2: 241008GMI_oxy_024bis_188 | M2: 241008GMI_oxy_012_30 | N2: 241009GMI_oxy_103_118 | O2: 241009GMI_oxy_137_152 | P2: 241008GMI_oxy_019_37 | Q2: 241009GMI_oxy_101_116 | R2: 241009GMI_oxy_120_135 | S2: 241008GMI_oxy_021_39 | T2: 241008GMI_oxy_046_64 | U2: 241008GMI_oxy_074_90 | V2: 241009GMI_oxy_129_144 | W2: 241008GMI_oxy_002_20 | X2: 241009GMI_oxy_144_159 | Y2: 241009GMI_oxy_107_122 | Z2: 241008GMI_oxy_083_99 | AA2: 241008GMI_oxy_035_53 | AB2: 241009GMI_oxy_166_181 | AC2: 241008GMI_oxy_072_88 | AD2: 241008GMI_oxy_055_72 | AE2: 241009GMI_oxy_134_149 | AF2: 241008GMI_oxy_006_24 | AG2: 241009GMI_oxy_171_186 | AH2: 241008GMI_oxy_080_96 | AI2: 241008GMI_oxy_096_111 | AJ2: 241009GMI_oxy_169_184 | AK2: 241009GMI_oxy_165_180 | AL2: 241008GMI_oxy_049_66 | AM2: 241009GMI_oxy_124_139 | AN2: 241008GMI_oxy_078_94 | AO2: 241008GMI_oxy_020_38 | AP2: 241009GMI_oxy_152_167 | AQ2: 241009GMI_oxy_116_131 | AR2: 241008GMI_oxy_030_48 | AS2: 241008GMI_oxy_005_23 | AT2: 241008GMI_oxy_076_92 | AU2: 241008GMI_oxy_038_56 | AV2: 241008GMI_oxy_037_55 | AW2: 241009GMI_oxy_157_172 | AX2: 241008GMI_oxy_059_76 | AY2: 241008GMI_oxy_022_40 | AZ2: 241008GMI_oxy_017_35 | BA2: 241008GMI_oxy_016_34 | BB2: 241008GMI_oxy_081_97 | BC2: 241009GMI_oxy_146_161 | BD2: 241008GMI_oxy_069_85 | BE2: 241009GMI_oxy_111_126 | BF2: 241008GMI_oxy_092_107 | BG2: 241008GMI_oxy_031_49 | BH2: 241009GMI_oxy_156_171 | BI2: 241008GMI_oxy_032 | BJ2: 241008GMI_oxy_039_57 | BK2: 241009GMI_oxy_114_129 | BL2: 241008GMI_oxy_066_82 | BM2: 241008GMI_oxy_070_86 | BN2: 241009GMI_oxy_153_168 | BO2: 241008GMI_oxy_001_19 | BP2: 241008GMI_oxy_028_46 | BQ2: 241008GMI_oxy_061_77 | BR2: 241009GMI_oxy_164_179 | BS2: 241008GMI_oxy_054_71 | BT2: 241009GMI_oxy_135_150 | BU2: 241009GMI_oxy_102_117 | BV2: 241008GMI_oxy_044_62 | BW2: 241008GMI_oxy_036_54 | BX2: 241009GMI_oxy_142_157 | BY2: 241009GMI_oxy_105_120 | BZ2: 241008GMI_oxy_094_109 | CA2: 241009GMI_oxy_098_113 | CB2: 241009GMI_oxy_145_160 | CC2: 241009GMI_oxy_170_185 | CD2: 241008GMI_oxy_053_70 | CE2: 241008GMI_oxy_057_74 | CF2: 241008GMI_oxy_003_21 | CG2: 241008GMI_oxy_056_73 | CH2: 241009GMI_oxy_159_174 | CI2: 241009GMI_oxy_123_138 | CJ2: 241008GMI_oxy_075_91 | CK2: 241009GMI_oxy_168_183 | CL2: 241008GMI_oxy_009_27 | CM2: 241008GMI_oxy_063_79 | CN2: 241009GMI_oxy_158_173 | CO2: 241008GMI_oxy_042_60 | CP2: 241008GMI_oxy_071_87 | CQ2: 241009GMI_oxy_112_127 | CR2: 241008GMI_oxy_062_78 | CS2: 241008GMI_oxy_058_75 | CT2: 241009GMI_oxy_104_119 | CU2: 241008GMI_oxy_052_69 | CV2: 241009GMI_oxy_115_130 | CW2: 241009GMI_oxy_143_158 | CX2: 241009GMI_oxy_118_133 | CY2: 241009GMI_oxy_138_153 | CZ2: 241008GMI_oxy_097_112 | DA2: 241009GMI_oxy_119_134 | DB2: 241009GMI_oxy_121_136 | DC2: 241009GMI_oxy_117_132 | DD2: 241009GMI_oxy_161_176 | DE2: 241009GMI_oxy_163_178 | DF2: 241009GMI_oxy_150_165 | DG2: 241008GMI_oxy_095_110 | DH2: 241008GMI_oxy_034_52 | DI2: 241008GMI_oxy_085_101 | DJ2: 241008GMI_oxy_087_103 | DK2: 241008GMI_oxy_047_65 | DL2: 241009GMI_oxy_110_125 | DM2: 241009GMI_oxy_132_147 | DN2: 241009GMI_oxy_133_148 | DO2: 241009GMI_oxy_162_177 | DP2: 241009GMI_oxy_125_140 | DQ2: 241009GMI_oxy_147_162 | DR2: 241009GMI_oxy_139_154 | DS2: 241009GMI_oxy_128_143 | DT2: 241008GMI_oxy_027_45 | DU2: 241009GMI_oxy_148_163 | DV2: 241008GMI_oxy_014_32 | DW2: 241008GMI_oxy_090_105 | DX2: 241008GMI_oxy_018_36 | DY2: 241009GMI_oxy_130_145 | DZ2: 241009GMI_oxy_160_175 | EA2: 241008GMI_oxy_093_108 | EB2: 241008GMI_oxy_073_89 | EC2: 241008GMI_oxy_026_44 | ED2: 241009GMI_oxy_131_146 | EE2: 241009GMI_oxy_140_155 | EF2: 241008GMI_oxy_079_95 | EG2: 241008GMI_oxy_015_33 | EH2: 241008GMI_oxy_067_83 | EI2: 241008GMI_oxy_008_26 | EJ2: 241009GMI_oxy_100_115 | EK2: 241009GMI_oxy_099_114 | EL2: 241008GMI_oxy_084_100 | EM2: 241008GMI_oxy_043_61 | EN2: 241008GMI_oxy_040_58 | EO2: 241008GMI_oxy_050_67 | EP2: 241008GMI_oxy_086_102 | EQ2: 241009GMI_oxy_151_166 | ER2: 241008GMI_oxy_051_68 | ES2: 241009GMI_oxy_109_124 | ET2: 241008GMI_oxy_007_25 | EU2: 241008GMI_oxy_013_31 | EV2: 241009GMI_oxy_113_128 | EW2: 241009GMI_oxy_106_121 | EX2: 241008GMI_oxy_025_43 | EY2: 241009GMI_oxy_122_137 | EZ2: 241008GMI_oxy_045_63 | FA2: 241009GMI_oxy_127_142 | FB2: 241008GMI_oxy_077_93 | FC2: 241008GMI_oxy_088_104 | FD2: 241009GMI_oxy_126_141 | FE2: 241008GMI_oxy_065_81 | FF2: 241009GMI_oxy_155_170 | FG2: 241009GMI_oxy_167_182 | FH2: 241008GMI_oxy_091_106 | FI2: 241008GMI_oxy_029_47 | FJ2: 241009GMI_oxy_141_156 | FK2: 241008GMI_oxy_023_41 | FL2: 241008GMI_oxy_082_98 | FM2: 241008GMI_oxy_004_22 | FN2: 241009GMI_oxy_149_164 | FO2: 241009GMI_oxy_172_187
A3: 9-HODE | C3: 89.1917 | D3: 128.9854 | E3: 65.0814 | F3: 537.351 | G3: 215.1459 | H3: 164.8993 | I3: 84.7739 | J3: 44.5104 | K3: 172.0578 | L3: 421.1112 | M3: 68.9659 | N3: 204.206 | O3: 137.4288 | P3: 271.7701 | Q3: 484.7874 | R3: 2378.7011 | S3: 207.3824 | T3: 110.6282 | U3: 160.9335 | V3: 127.6316 | W3: 196.4404 | X3: 117.1816 | Y3: 153.6918 | Z3: 1979.7331 | AA3: 128.1907 | AB3: 151.4351 | AC3: 105.8734 | AD3: 114.8253 | AE3: 67.7669 | AF3: 182.92 | AG3: 624.1813 | AH3: 134.025 | AI3: 536.3877 | AJ3: 229.1465 | AK3: 97.8534 | AL3: 256.2922 | AM3: 700.7812 | AN3: 162.0704 | AO3: 50.7274 | AP3: 193.8357 | AQ3: 472.8055 | AR3: 73.2979 | AS3: 741.0535 | AT3: 503.6817 | AU3: 22.6445 | AV3: 24.8632 | AW3: 68.7651 | AX3: 100.7081 | AY3: 130.0608 | AZ3: 39.0718 | BA3: 140.5757 | BB3: 84.6964 | BC3: 70.3095 | BD3: 108.1353 | BE3: 147.7683 | BF3: 687.3891 | BG3: 38.1479 | BH3: 577.6908 | BI3: 1375.1399 | BJ3: 1828.3126 | BK3: 355.4328 | BL3: 8921.0722 | BM3: 3963.4912 | BN3: 6845.8945 | BO3: 9760.0952 | BP3: 5180.9059 | BQ3: 507.0801 | BR3: 101.8388 | BS3: 5462.2745 | BT3: 1822.6614 | BU3: 905.6078 | BV3: 777.4113 | BW3: 429.635 | BX3: 94.8168 | BY3: 819.0917 | BZ3: 488.8834 | CA3: 562.0182 | CB3: 167.0952 | CC3: 150.3503 | CD3: 155.4842 | CE3: 1180.6699 | CF3: 94.5886 | CG3: 208.5813 | CH3: 155.545 | CI3: 445.3258 | CJ3: 74.8337 | CK3: 129.7043 | CL3: 253.3493 | CM3: 120.4687 | CN3: 97.3703 | CO3: 66.5979 | CP3: 247.9415 | CQ3: 251.9559 | CR3: 376.2054 | CS3: 67.8315 | CT3: 284.1973 | CU3: 159.972 | CV3: 67.4066 | CW3: 198.8502 | CX3: 131.3243 | CY3: 82.2239 | CZ3: 38.1526 | DA3: 60.0175 | DB3: 227.4722 | DC3: 185.4338 | DD3: 127.9991 | DE3: 129.4753 | DF3: 246.1429 | DG3: 337.337 | DH3: 36.6114 | DI3: 159.433 | DJ3: 722.8819 | DK3: 789.7284 | DL3: 71.8114 | DM3: 168.8149 | DN3: 427.2177 | DO3: 197.9233 | DP3: 125.4175 | DQ3: 224.8991 | DR3: 101.4976 | DS3: 88.5629 | DT3: 57.5061 | DU3: 698.996 | DV3: 102.1659 | DW3: 202.1081 | DX3: 64.7279 | DY3: 132.2161 | DZ3: 201.9643 | EA3: 107.8334 | EB3: 198.6994 | EC3: 139.1768 | ED3: 126.1189 | EE3: 52.1968 | EF3: 243.1417 | EG3: 205.7021 | EH3: 152.744 | EI3: 42.4093 | EJ3: 207.4159 | EK3: 185.0866 | EL3: 164.1111 | EM3: 415.6494 | EN3: 337.9671 | EO3: 259.2417 | EP3: 298.9935 | EQ3: 71.8344 | ER3: 66.6856 | ES3: 113.7729 | ET3: 142.157 | EU3: 147.9041 | EV3: 167.0961 | EW3: 153.223 | EX3: 115.8508 | EY3: 352.7245 | EZ3: 244.4528 | FA3: 69.424 | FB3: 88.039 | FC3: 221.2469 | FD3: 78.7688 | FE3: 95.5945 | FF3: 132.9813 | FG3: 65.2637 | FH3: 142.2039 | FI3: 239.8661 | FJ3: 182.4669 | FK3: 79.2657 | FL3: 123.3699 | FM3: 81.9231 | FN3: 83.6865 | FO3: 107.3845
A4: 10-HODE | C4: 0 | D4: 0 | E4: 0 | F4: 0 | G4: 0 | H4: 0 | I4: 0 | J4: 0 | K4: 0 | L4: 0 | M4: 0 | N4: 0 | O4: 0 | P4: 0 | Q4: 0 | R4: 0 | S4: 0 | T4: 0 | U4: 0 | V4: 0 | W4: 0 | X4: 0 | Y4: 0 | Z4: 0 | AA4: 0 | AB4: 0 | AC4: 0 | AD4: 0 | AE4: 0 | AF4: 0 | AG4: 0 | AH4: 0 | AI4: 0 | AJ4: 0 | AK4: 0 | AL4: 0 | AM4: 0 | AN4: 0 | AO4: 0 | AP4: 0 | AQ4: 0 | AR4: 0 | AS4: 0 | AT4: 0 | AU4: 0 | AV4: 0 | AW4: 0 | AX4: 0 | AY4: 0 | AZ4: 0 | BA4: 0 | BB4: 0 | BC4: 0 | BD4: 0 | BE4: 0 | BF4: 0 | BG4: 0 | BH4: 0 | BI4: 0 | BJ4: 0 | BK4: 0 | BL4: 0 | BM4: 0 | BN4: 0 | BO4: 0 | BP4: 0 | BQ4: 0 | BR4: 0 | BS4: 0 | BT4: 0 | BU4: 0 | BV4: 0 | BW4: 0 | BX4: 0 | BY4: 0 | BZ4: 0 | CA4: 0 | CB4: 0 | CC4: 0 | CD4: 0 | CE4: 0 | CF4: 0 | CG4: 0 | CH4: 0 | CI4: 0 | CJ4: 0 | CK4: 0 | CL4: 0 | CM4: 0 | CN4: 0 | CO4: 0 | CP4: 0 | CQ4: 0 | CR4: 0 | CS4: 0 | CT4: 0 | CU4: 0 | CV4: 0 | CW4: 0 | CX4: 0 | CY4: 0 | CZ4: 0 | DA4: 0 | DB4: 0 | DC4: 0 | DD4: 0 | DE4: 0 | DF4: 0 | DG4: 0 | DH4: 0 | DI4: 0 | DJ4: 0 | DK4: 0 | DL4: 0 | DM4: 0 | DN4: 0 | DO4: 0 | DP4: 0 | DQ4: 0 | DR4: 0 | DS4: 0 | DT4: 0 | DU4: 0 | DV4: 0 | DW4: 0 | DX4: 0 | DY4: 0 | DZ4: 0 | EA4: 0 | EB4: 0 | EC4: 0 | ED4: 0 | EE4: 0 | EF4: 0 | EG4: 0 | EH4: 0 | EI4: 0 | EJ4: 0 | EK4: 0 | EL4: 0 | EM4: 0 | EN4: 0 | EO4: 0 | EP4: 0 | EQ4: 0 | ER4: 0 | ES4: 0 | ET4: 0 | EU4: 0 | EV4: 0 | EW4: 0 | EX4: 0 | EY4: 0 | EZ4: 0 | FA4: 0 | FB4: 0 | FC4: 0 | FD4: 0 | FE4: 0 | FF4: 0 | FG4: 0 | FH4: 0 | FI4: 0 | FJ4: 0 | FK4: 0 | FL4: 0 | FM4: 0 | FN4: 0 | FO4: 0
A5: 13-HODE | C5: 163.94 | D5: 283.5172 | E5: 82.4391 | F5: 648.0069 | G5: 280.8184 | H5: 201.1484 | I5: 286.4847 | J5: 116.5076 | K5: 522.9376 | L5: 403.1277 | M5: 211.8748 | N5: 250.3494 | O5: 245.3249 | P5: 427.5278 | Q5: 759.0148 | R5: 2848.8486 | S5: 601.1357 | T5: 138.6104 | U5: 229.5864 | V5: 372.8816 | W5: 334.7468 | X5: 139.2297 | Y5: 553.7716 | Z5: 2165.6591 | AA5: 263.2015 | AB5: 366.7788 | AC5: 154.7825 | AD5: 196.5932 | AE5: 138.7683 | AF5: 158.3846 | AG5: 630.6031 | AH5: 259.6205 | AI5: 539.7634 | AJ5: 528.1038 | AK5: 168.4484 | AL5: 320.9353 | AM5: 930.6487 | AN5: 306.3394 | AO5: 171.3399 | AP5: 214.6075 | AQ5: 1638.2603 | AR5: 127.2822 | AS5: 786.8425 | AT5: 461.3157 | AU5: 38.3473 | AV5: 58.9913 | AW5: 105.8143 | AX5: 153.8522 | AY5: 192.669 | AZ5: 72.7437 | BA5: 192.0079 | BB5: 141.3323 | BC5: 172.3913 | BD5: 142.6289 | BE5: 302.3007 | BF5: 928.2137 | BG5: 96.7499 | BH5: 793.984 | BI5: 1766.582 | BJ5: 2731.7505 | BK5: 685.1311 | BL5: 8917.6133 | BM5: 3729.8526 | BN5: 7706.5734 | BO5: 12136.489 | BP5: 5415.7138 | BQ5: 681.4105 | BR5: 127.7087 | BS5: 6148.9087 | BT5: 1905.9586 | BU5: 1082.7887 | BV5: 851.0798 | BW5: 622.249 | BX5: 176.1838 | BY5: 940.5887 | BZ5: 585.5219 | CA5: 732.4642 | CB5: 161.8287 | CC5: 290.428 | CD5: 253.0676 | CE5: 1510.8676 | CF5: 192.0368 | CG5: 375.2751 | CH5: 273.746 | CI5: 457.9438 | CJ5: 105.9204 | CK5: 147.909 | CL5: 277.8046 | CM5: 196.614 | CN5: 236.3143 | CO5: 153.9046 | CP5: 382.9845 | CQ5: 372.7332 | CR5: 427.4227 | CS5: 155.0962 | CT5: 475.2068 | CU5: 210.7923 | CV5: 199.5108 | CW5: 551.4888 | CX5: 268.1773 | CY5: 118.6448 | CZ5: 84.9895 | DA5: 170.8423 | DB5: 329.0451 | DC5: 295.5804 | DD5: 293.0441 | DE5: 183.4172 | DF5: 324.9747 | DG5: 337.3315 | DH5: 73.105 | DI5: 334.3666 | DJ5: 905.2216 | DK5: 590.1559 | DL5: 89.1145 | DM5: 488.5388 | DN5: 542.0589 | DO5: 369.2984 | DP5: 249.3275 | DQ5: 363.0902 | DR5: 365.0614 | DS5: 155.0415 | DT5: 131.5369 | DU5: 802.1192 | DV5: 210.437 | DW5: 278.9902 | DX5: 125.555 | DY5: 382.5559 | DZ5: 336.9306 | EA5: 253.8527 | EB5: 324.7041 | EC5: 168.3796 | ED5: 257.0702 | EE5: 88.7612 | EF5: 318.5322 | EG5: 311.5517 | EH5: 160.8274 | EI5: 93.5541 | EJ5: 411.6148 | EK5: 195.6145 | EL5: 232.3181 | EM5: 360.0047 | EN5: 439.8856 | EO5: 298.4762 | EP5: 338.706 | EQ5: 143.1952 | ER5: 164.051 | ES5: 171.8006 | ET5: 146.4118 | EU5: 258.2147 | EV5: 222.4248 | EW5: 212.5493 | EX5: 391.5945 | EY5: 855.7102 | EZ5: 494.7787 | FA5: 140.8689 | FB5: 125.2588 | FC5: 266.4387 | FD5: 120.0809 | FE5: 161.002 | FF5: 201.6432 | FG5: 120.9406 | FH5: 286.9066 | FI5: 236.1216 | FJ5: 380.333 | FK5: 403.0753 | FL5: 496.2049 | FM5: 399.7365 | FN5: 539.3918 | FO5: 174.5205
A6: 9,10-DiHOME | C6: 11.8221 | D6: 16.9206 | E6: 27.7274 | F6: 83.1897 | G6: 15.061 | H6: 3.5924 | I6: 16.4996 | J6: 7.2062 | K6: 14.3992 | L6: 25.0433 | M6: 17.8322 | N6: 3.7681 | O6: 13.519 | P6: 18.8426 | Q6: 139.2968 | R6: 70.4528 | S6: 31.4347 | T6: 16.1211 | U6: 21.9398 | V6: 61.0374 | W6: 11.6429 | X6: 2.1828 | Y6: 21.231 | Z6: 28.3054 | AA6: 13.364 | AB6: 12.838 | AC6: 11.0682 | AD6: 19.174 | AE6: 10.4122 | AF6: 5.743 | AG6: 22.3008 | AH6: 52.487 | AI6: 10.0369 | AJ6: 29.6838 | AK6: 17.6016 | AL6: 29.0662 | AM6: 16.6449 | AN6: 16.0963 | AO6: 39.9643 | AP6: 15.8636 | AQ6: 240.4567 | AR6: 6.8263 | AS6: 7.6211 | AT6: 6.3454 | AU6: 4.4819 | AV6: 10.8881 | AW6: 7.0283 | AX6: 8.0481 | AY6: 20.4101 | AZ6: 13.6637 | BA6: 12.404 | BB6: 20.5283 | BC6: 41.8607 | BD6: 10.1099 | BE6: 7.7632 | BF6: 27.847 | BG6: 32.5863 | BH6: 18.298 | BI6: 12.716 | BJ6: 26.143 | BK6: 71.5545 | BL6: 16.0828 | BM6: 3.5221 | BN6: 9.0528 | BO6: 127.2653 | BP6: 17.8149 | BQ6: 18.9761 | BR6: 14.9496 | BS6: 5.211 | BT6: 14.8885 | BU6: 17.1747 | BV6: 9.0585 | BW6: 101.0248 | BX6: 53.3036 | BY6: 9.1342 | BZ6: 9.3717 | CA6: 12.2702 | CB6: 9.2518 | CC6: 19.4374 | CD6: 13.122 | CE6: 45.7542 | CF6: 10.7605 | CG6: 33.7053 | CH6: 56.8452 | CI6: 26.9644 | CJ6: 12.935 | CK6: 7.2122 | CL6: 19.1222 | CM6: 32.2059 | CN6: 32.657 | CO6: 8.5905 | CP6: 23.5837 | CQ6: 50.9064 | CR6: 35.7846 | CS6: 15.1547 | CT6: 15.6194 | CU6: 16.9344 | CV6: 20.8091 | CW6: 17.5068 | CX6: 46.9297 | CY6: 15.4323 | CZ6: 8.2826 | DA6: 16.814 | DB6: 7.4721 | DC6: 14.5501 | DD6: 7.4825 | DE6: 59.5845 | DF6: 3.4818 | DG6: 26.6281 | DH6: 6.4905 | DI6: 30.6426 | DJ6: 36.1632 | DK6: 76.9445 | DL6: 8.9912 | DM6: 20.4472 | DN6: 14.3907 | DO6: 9.5153 | DP6: 38.0002 | DQ6: 11.2613 | DR6: 9.4237 | DS6: 40.808 | DT6: 20.3804 | DU6: 5.1031 | DV6: 22.0765 | DW6: 26.4008 | DX6: 35.4121 | DY6: 37.9166 | DZ6: 13.713 | EA6: 16.4472 | EB6: 15.2187 | EC6: 8.9078 | ED6: 35.7177 | EE6: 9.5105 | EF6: 13.0969 | EG6: 32.8585 | EH6: 8.5185 | EI6: 17.2411 | EJ6: 53.1111 | EK6: 7.1275 | EL6: 25.4072 | EM6: 69.897 | EN6: 7.9252 | EO6: 6.0175 | EP6: 78.2865 | EQ6: 13.1086 | ER6: 12.5778 | ES6: 9.1733 | ET6: 13.8198 | EU6: 20.0894 | EV6: 13.8587 | EW6: 30.0704 | EX6: 18.1308 | EY6: 200.4673 | EZ6: 16.1609 | FA6: 4.194 | FB6: 14.8115 | FC6: 20.1295 | FD6: 11.7961 | FE6: 9.7638 | FF6: 31.6362 | FG6: 9.1905 | FH6: 19.2873 | FI6: 4.2365 | FJ6: 24.8803 | FK6: 71.2848 | FL6: 26.4231 | FM6: 47.642 | FN6: 42.0368 | FO6: 10.0147
A7: 12,13-DiHOME | C7: 14.8946 | D7: 13.5411 | E7: 29.8605 | F7: 118.7344 | G7: 13.1144 | H7: 3.6789 | I7: 21.8019 | J7: 5.6253 | K7: 15.2867 | L7: 50.196 | M7: 20.4415 | N7: 2.2231 | O7: 12.1336 | P7: 20.6469 | Q7: 120.0088 | R7: 89.056 | S7: 43.315 | T7: 14.2594 | U7: 28.7474 | V7: 101.4849 | W7: 20.0547 | X7: 3.6686 | Y7: 21.4371 | Z7: 50.666 | AA7: 16.7095 | AB7: 11.7348 | AC7: 13.8591 | AD7: 14.1667 | AE7: 13.2502 | AF7: 11.0269 | AG7: 19.2005 | AH7: 39.0226 | AI7: 9.2685 | AJ7: 9.6124 | AK7: 7.419 | AL7: 50.2109 | AM7: 15.8624 | AN7: 11.7291 | AO7: 31.9105 | AP7: 12.4481 | AQ7: 172.5211 | AR7: 5.6707 | AS7: 9.1172 | AT7: 7.8877 | AU7: 2.5236 | AV7: 6.272 | AW7: 5.4281 | AX7: 6.3742 | AY7: 48.9165 | AZ7: 13.6449 | BA7: 16.1802 | BB7: 24.0439 | BC7: 37.7922 | BD7: 8.591 | BE7: 10.2636 | BF7: 28.603 | BG7: 19.6371 | BH7: 13.6291 | BI7: 9.8161 | BJ7: 23.6492 | BK7: 35.7264 | BL7: 12.3043 | BM7: 3.3135 | BN7: 7.1305 | BO7: 109.9608 | BP7: 13.6428 | BQ7: 19.4538 | BR7: 12.1165 | BS7: 4.8702 | BT7: 8.0301 | BU7: 12.5534 | BV7: 6.1891 | BW7: 82.568 | BX7: 35.2217 | BY7: 11.9364 | BZ7: 7.614 | CA7: 11.403 | CB7: 3.8306 | CC7: 23.6203 | CD7: 13.0119 | CE7: 31.5014 | CF7: 14.7591 | CG7: 27.9917 | CH7: 76.3062 | CI7: 62.2841 | CJ7: 13.8893 | CK7: 6.5847 | CL7: 13.3607 | CM7: 24.2716 | CN7: 16.9238 | CO7: 12.8972 | CP7: 19.3205 | CQ7: 74.6444 | CR7: 51.7079 | CS7: 15.4201 | CT7: 27.5371 | CU7: 11.9287 | CV7: 10.9061 | CW7: 19.6026 | CX7: 31.3132 | CY7: 12.9035 | CZ7: 6.5014 | DA7: 18.2378 | DB7: 4.1276 | DC7: 11.2253 | DD7: 7.4948 | DE7: 40.7493 | DF7: 2.7056 | DG7: 16.2006 | DH7: 4.104 | DI7: 35.4094 | DJ7: 27.3124 | DK7: 157.7774 | DL7: 6.9293 | DM7: 25.3413 | DN7: 12.3011 | DO7: 9.1526 | DP7: 61.7735 | DQ7: 14.5157 | DR7: 8.2408 | DS7: 27.6499 | DT7: 48.0234 | DU7: 3.3333 | DV7: 15.7867 | DW7: 36.8449 | DX7: 32.4309 | DY7: 19.9764 | DZ7: 10.4451 | EA7: 10.7378 | EB7: 15.5349 | EC7: 8.0894 | ED7: 31.7089 | EE7: 6.6436 | EF7: 15.2059 | EG7: 27.7892 | EH7: 5.3994 | EI7: 9.1012 | EJ7: 63.4419 | EK7: 6.2981 | EL7: 26.6534 | EM7: 161.8765 | EN7: 6.7846 | EO7: 5.1303 | EP7: 108.8583 | EQ7: 9.9514 | ER7: 10.6842 | ES7: 8.5375 | ET7: 25.296 | EU7: 18.8234 | EV7: 11.4353 | EW7: 24.1674 | EX7: 17.0883 | EY7: 95.5033 | EZ7: 18.0127 | FA7: 2.6185 | FB7: 10.1386 | FC7: 46.3092 | FD7: 8.971 | FE7: 17.4539 | FF7: 57.9072 | FG7: 8.4929 | FH7: 22.2288 | FI7: 4.6405 | FJ7: 29.3263 | FK7: 89.6576 | FL7: 25.2384 | FM7: 23.3844 | FN7: 39.1683 | FO7: 17.1783
A8: 9-oxo-ODE | C8: 10.4197 | D8: 4.3102 | E8: 0 | F8: 38.1543 | G8: 3.3783 | H8: 1.0934 | I8: 0.8059 | J8: 0.8163 | K8: 3.2723 | L8: 10.8624 | M8: 2.1266 | N8: 0.9763 | O8: 0.7723 | P8: 12.6328 | Q8: 12.979 | R8: 134.2607 | S8: 7.5411 | T8: 2.3375 | U8: 11.5652 | V8: 1.6504 | W8: 0.5112 | X8: 0 | Y8: 2.0721 | Z8: 2.786 | AA8: 5.8197 | AB8: 1.3526 | AC8: 6.1394 | AD8: 2.2708 | AE8: 1.4963 | AF8: 1.1905 | AG8: 4.782 | AH8: 0.5087 | AI8: 9.695 | AJ8: 2.6221 | AK8: 0.9677 | AL8: 3.8784 | AM8: 3.6817 | AN8: 3.552 | AO8: 1.5594 | AP8: 1.5027 | AQ8: 20.7772 | AR8: 1.5647 | AS8: 9.5178 | AT8: 7.9919 | AU8: 0 | AV8: 0.9623 | AW8: 1.4489 | AX8: 3.2392 | AY8: 4.6077 | AZ8: 3.2968 | BA8: 2.0467 | BB8: 1.9569 | BC8: 0.6385 | BD8: 2.7567 | BE8: 4.482 | BF8: 13.6572 | BG8: 0.6986 | BH8: 1.8187 | BI8: 5.4787 | BJ8: 69.2721 | BK8: 3.9961 | BL8: 39.047 | BM8: 27.8306 | BN8: 72.2277 | BO8: 32.9492 | BP8: 26.0249 | BQ8: 7.8591 | BR8: 0.4865 | BS8: 14.5563 | BT8: 6.0774 | BU8: 10.4313 | BV8: 7.3492 | BW8: 8.1983 | BX8: 2.3382 | BY8: 5.7242 | BZ8: 5.8719 | CA8: 3.7009 | CB8: 4.474 | CC8: 2.0444 | CD8: 3.2074 | CE8: 2.562 | CF8: 3.0638 | CG8: 5.3248 | CH8: 2.987 | CI8: 11.7058 | CJ8: 1.2695 | CK8: 0.4661 | CL8: 0.9956 | CM8: 3.7086 | CN8: 2.0803 | CO8: 0.9378 | CP8: 5.066 | CQ8: 1.6095 | CR8: 29.7755 | CS8: 0.6481 | CT8: 5.8111 | CU8: 2.3532 | CV8: 0 | CW8: 6.9488 | CX8: 4.6188 | CY8: 0.3734 | CZ8: 0 | DA8: 0 | DB8: 0.4418 | DC8: 5.2747 | DD8: 0 | DE8: 0 | DF8: 1.4136 | DG8: 8.8337 | DH8: 1.1106 | DI8: 2.8582 | DJ8: 5.0297 | DK8: 13.5957 | DL8: 0.7648 | DM8: 2.4964 | DN8: 0.6908 | DO8: 0.7231 | DP8: 2.3041 | DQ8: 7.0273 | DR8: 2.0477 | DS8: 0 | DT8: 0.5995 | DU8: 3.1345 | DV8: 1.9013 | DW8: 2.221 | DX8: 0 | DY8: 0 | DZ8: 0.3404 | EA8: 3.0325 | EB8: 4.2429 | EC8: 6.1893 | ED8: 1.4419 | EE8: 0 | EF8: 11.8925 | EG8: 11.4926 | EH8: 2.3537 | EI8: 1.0416 | EJ8: 4.2761 | EK8: 0 | EL8: 1.5939 | EM8: 13.1287 | EN8: 14.9707 | EO8: 4.0469 | EP8: 3.3234 | EQ8: 1.204 | ER8: 2.0147 | ES8: 1.695 | ET8: 4.384 | EU8: 3.4084 | EV8: 5.7804 | EW8: 4.0188 | EX8: 1.8804 | EY8: 5.5595 | EZ8: 18.7648 | FA8: 0 | FB8: 1.1059 | FC8: 3.4521 | FD8: 1.8639 | FE8: 4.4147 | FF8: 1.8564 | FG8: 2.7412 | FH8: 1.9104 | FI8: 5.1784 | FJ8: 4.3092 | FK8: 0 | FL8: 4.5911 | FM8: 4.9541 | FN8: 0.8141 | FO8: 1.114
A9: 13-oxo-ODE | C9: 12.5244 | D9: 5.6548 | E9: 0 | F9: 44.8857 | G9: 13.8897 | H9: 3.7593 | I9: 0 | J9: 1.406 | K9: 4.1765 | L9: 10.4672 | M9: 5.8073 | N9: 2.2096 | O9: 0 | P9: 15.4823 | Q9: 14.2336 | R9: 172.6133 | S9: 10.684 | T9: 3.2035 | U9: 9.4437 | V9: 4.8004 | W9: 2.4521 | X9: 0 | Y9: 0 | Z9: 8.2574 | AA9: 6.7461 | AB9: 0 | AC9: 5.092 | AD9: 7.7069 | AE9: 0 | AF9: 17.1997 | AG9: 17.831 | AH9: 3.1555 | AI9: 24.5789 | AJ9: 0 | AK9: 1.4501 | AL9: 19.0261 | AM9: 0 | AN9: 6.3241 | AO9: 2.169 | AP9: 0 | AQ9: 23.6993 | AR9: 3.6842 | AS9: 112.9377 | AT9: 75.0202 | AU9: 0 | AV9: 0 | AW9: 3.26 | AX9: 11.7524 | AY9: 5.1069 | AZ9: 1.2476 | BA9: 22.7184 | BB9: 3.463 | BC9: 0 | BD9: 3.8573 | BE9: 3.3163 | BF9: 40.1491 | BG9: 2.9708 | BH9: 0 | BI9: 8.4555 | BJ9: 58.5864 | BK9: 10.8552 | BL9: 107.977 | BM9: 79.1697 | BN9: 147.107 | BO9: 127.1887 | BP9: 116.4897 | BQ9: 9.0948 | BR9: 1.0872 | BS9: 47.6094 | BT9: 23.314 | BU9: 22.7433 | BV9: 11.0619 | BW9: 39.751 | BX9: 2.5298 | BY9: 12.9278 | BZ9: 9.4868 | CA9: 9.7247 | CB9: 9.7341 | CC9: 4.8151 | CD9: 8.916 | CE9: 19.8704 | CF9: 9.769 | CG9: 5.4312 | CH9: 4.7068 | CI9: 12.4612 | CJ9: 3.8816 | CK9: 0 | CL9: 3.6876 | CM9: 5.7022 | CN9: 0 | CO9: 2.8198 | CP9: 9.8533 | CQ9: 7.6403 | CR9: 37.3503 | CS9: 2.7142 | CT9: 3.4957 | CU9: 6.4304 | CV9: 0 | CW9: 6.7262 | CX9: 3.8252 | CY9: 2.7134 | CZ9: 0 | DA9: 0 | DB9: 2.7287 | DC9: 6.5576 | DD9: 0 | DE9: 1.6966 | DF9: 2.4179 | DG9: 21.3855 | DH9: 0 | DI9: 3.4949 | DJ9: 13.9134 | DK9: 18.6034 | DL9: 3.3978 | DM9: 6.4999 | DN9: 8.091 | DO9: 7.2661 | DP9: 4.8997 | DQ9: 10.6407 | DR9: 1.8807 | DS9: 0 | DT9: 0 | DU9: 16.3422 | DV9: 4.6316 | DW9: 0 | DX9: 3.9498 | DY9: 0.2233 | DZ9: 0 | EA9: 2.46 | EB9: 5.7738 | EC9: 10.4048 | ED9: 2.848 | EE9: 0 | EF9: 12.4679 | EG9: 12.8565 | EH9: 8.6857 | EI9: 2.0157 | EJ9: 4.727 | EK9: 2.8006 | EL9: 8.2396 | EM9: 6.372 | EN9: 17.0999 | EO9: 4.0362 | EP9: 15.0007 | EQ9: 3.5432 | ER9: 2.0154 | ES9: 2.9106 | ET9: 6.3334 | EU9: 5.915 | EV9: 9.4227 | EW9: 4.3974 | EX9: 2.4244 | EY9: 8.5409 | EZ9: 14.8458 | FA9: 0 | FB9: 5.9012 | FC9: 0 | FD9: 2.6625 | FE9: 7.1952 | FF9: 0 | FG9: 0 | FH9: 6.2267 | FI9: 34.0273 | FJ9: 8.4835 | FK9: 1.4719 | FL9: 4.1231 | FM9: 6.7885 | FN9: 2.6225 | FO9: 0
A10: 9,10,13-TriHOME | C10: 2.1946 | D10: 1.8521 | E10: 2.8259 | F10: 32.8013 | G10: 0 | H10: 1.1922 | I10: 0.8776 | J10: 1.4718 | K10: 5.5785 | L10: 4.0278 | M10: 0.8021 | N10: 1.0496 | O10: 1.4295 | P10: 4.7006 | Q10: 5.4086 | R10: 173.6363 | S10: 3.1845 | T10: 1.2003 | U10: 4.5712 | V10: 1.4127 | W10: 1.6408 | X10: 2.4627 | Y10: 3.0426 | Z10: 1.6438 | AA10: 1.4457 | AB10: 2.5051 | AC10: 5.631 | AD10: 6.5833 | AE10: 0.7603 | AF10: 0 | AG10: 1.4959 | AH10: 3.5963 | AI10: 6.2564 | AJ10: 2.5268 | AK10: 0 | AL10: 2.2823 | AM10: 2.0513 | AN10: 2.1691 | AO10: 1.3215 | AP10: 0 | AQ10: 40.811 | AR10: 1.0043 | AS10: 0 | AT10: 2.9265 | AU10: 0 | AV10: 0 | AW10: 3.0901 | AX10: 3.4487 | AY10: 2.5781 | AZ10: 0 | BA10: 0 | BB10: 0.9621 | BC10: 0 | BD10: 1.1408 | BE10: 1.5208 | BF10: 5.8244 | BG10: 0.9527 | BH10: 0 | BI10: 8.0135 | BJ10: 43.6891 | BK10: 2.9359 | BL10: 15.6963 | BM10: 7.4092 | BN10: 43.8217 | BO10: 7.5429 | BP10: 3.8591 | BQ10: 1.6942 | BR10: 0.9615 | BS10: 3.3241 | BT10: 1.8191 | BU10: 7.175 | BV10: 3.7932 | BW10: 5.6742 | BX10: 2.4093 | BY10: 2.7986 | BZ10: 2.8306 | CA10: 1.5918 | CB10: 1.2441 | CC10: 1.9334 | CD10: 0 | CE10: 3.4227 | CF10: 0 | CG10: 2.8848 | CH10: 4.0512 | CI10: 7.8277 | CJ10: 0 | CK10: 1.9873 | CL10: 5.8853 | CM10: 4.7958 | CN10: 1.1109 | CO10: 0.9137 | CP10: 1.3746 | CQ10: 3.1964 | CR10: 31.7666 | CS10: 1.2054 | CT10: 1.4688 | CU10: 1.9921 | CV10: 0 | CW10: 2.8344 | CX10: 1.927 | CY10: 0.8387 | CZ10: 0 | DA10: 0 | DB10: 0.9785 | DC10: 3.7538 | DD10: 0 | DE10: 4.9619 | DF10: 1.5119 | DG10: 4.5279 | DH10: 0 | DI10: 6.9551 | DJ10: 4.087 | DK10: 6.4435 | DL10: 0 | DM10: 1.0224 | DN10: 1.4999 | DO10: 0.8744 | DP10: 2.4167 | DQ10: 2.0408 | DR10: 0.7749 | DS10: 0 | DT10: 1.5491 | DU10: 3.9122 | DV10: 1.5948 | DW10: 0 | DX10: 2.2698 | DY10: 2.8157 | DZ10: 0 | EA10: 1.3383 | EB10: 1.7464 | EC10: 2.1973 | ED10: 1.3679 | EE10: 0 | EF10: 2.7991 | EG10: 2.8659 | EH10: 0 | EI10: 0 | EJ10: 0 | EK10: 2.2343 | EL10: 1.4139 | EM10: 1.7522 | EN10: 3.6978 | EO10: 0 | EP10: 6.581 | EQ10: 0 | ER10: 3.7671 | ES10: 0 | ET10: 0 | EU10: 0.8876 | EV10: 1.0804 | EW10: 1.7404 | EX10: 1.4119 | EY10: 3.6021 | EZ10: 4.2928 | FA10: 0 | FB10: 0 | FC10: 0 | FD10: 2.3325 | FE10: 5.7225 | FF10: 9.7428 | FG10: 3.9212 | FH10: 2.6729 | FI10: 0 | FJ10: 5.1393 | FK10: 13.2788 | FL10: 1.5144 | FM10: 1.3447 | FN10: 2.1324 | FO10: 0
A11: 9,12,13-TriHOME | C11: 8.6665 | D11: 7.4056 | E11: 16.3719 | F11: 91.7864 | G11: 2.9281 | H11: 5.5508 | I11: 11.3681 | J11: 6.3713 | K11: 16.9576 | L11: 32.3458 | M11: 4.9424 | N11: 4.4975 | O11: 7.627 | P11: 18.4647 | Q11: 32.8495 | R11: 494.3566 | S11: 10.7715 | T11: 4.9276 | U11: 17.1383 | V11: 7.809 | W11: 9.0833 | X11: 12.8477 | Y11: 17.4645 | Z11: 8.2174 | AA11: 6.022 | AB11: 13.8504 | AC11: 16.5464 | AD11: 11.3007 | AE11: 4.51 | AF11: 14.6164 | AG11: 11.1298 | AH11: 16.6023 | AI11: 18.3401 | AJ11: 14.928 | AK11: 4.224 | AL11: 25.6139 | AM11: 7.2868 | AN11: 10.2648 | AO11: 10.3701 | AP11: 3.5898 | AQ11: 202.119 | AR11: 5.7843 | AS11: 5.2062 | AT11: 7.4574 | AU11: 3.1253 | AV11: 4.1424 | AW11: 12.4911 | AX11: 14.5107 | AY11: 35.8091 | AZ11: 4.9032 | BA11: 2.4093 | BB11: 4.4617 | BC11: 6.205 | BD11: 4.3486 | BE11: 5.1344 | BF11: 26.2724 | BG11: 6.2125 | BH11: 4.9486 | BI11: 20.2808 | BJ11: 131.5985 | BK11: 17.4491 | BL11: 43.0091 | BM11: 19.2921 | BN11: 138.5567 | BO11: 29.8184 | BP11: 14.9339 | BQ11: 5.8159 | BR11: 6.2976 | BS11: 13.0358 | BT11: 6.6959 | BU11: 23.7096 | BV11: 15.0381 | BW11: 31.969 | BX11: 9.8013 | BY11: 12.5473 | BZ11: 12.3682 | CA11: 7.9377 | CB11: 6.6232 | CC11: 8.144 | CD11: 3.4343 | CE11: 12.6421 | CF11: 4.3645 | CG11: 11.302 | CH11: 20.0083 | CI11: 38.5607 | CJ11: 4.5383 | CK11: 11.5387 | CL11: 24.5691 | CM11: 18.056 | CN11: 9.1892 | CO11: 5.2559 | CP11: 5.4227 | CQ11: 21.2481 | CR11: 130.7306 | CS11: 6.2986 | CT11: 6.7872 | CU11: 7.5367 | CV11: 6.1828 | CW11: 12.2363 | CX11: 8.7313 | CY11: 6.452 | CZ11: 4.0701 | DA11: 0 | DB11: 6.4814 | DC11: 14.3421 | DD11: 7.4408 | DE11: 20.2327 | DF11: 4.8882 | DG11: 15.5412 | DH11: 3.5704 | DI11: 36.286 | DJ11: 8.9853 | DK11: 64.6589 | DL11: 4.7503 | DM11: 7.6678 | DN11: 5.1691 | DO11: 8.6032 | DP11: 28.935 | DQ11: 8.0821 | DR11: 7.994 | DS11: 4.4099 | DT11: 33.8253 | DU11: 10.947 | DV11: 9.8588 | DW11: 7.3922 | DX11: 11.6618 | DY11: 11.8635 | DZ11: 3.5459 | EA11: 9.3112 | EB11: 8.3158 | EC11: 8.4981 | ED11: 7.8081 | EE11: 3.7665 | EF11: 9.7143 | EG11: 11.1351 | EH11: 3.4714 | EI11: 3.9627 | EJ11: 5.7576 | EK11: 7.732 | EL11: 18.3128 | EM11: 20.413 | EN11: 12.6299 | EO11: 6.5759 | EP11: 73.3792 | EQ11: 4.8142 | ER11: 16.9813 | ES11: 3.4826 | ET11: 4.4912 | EU11: 5.7554 | EV11: 6.3223 | EW11: 6.962 | EX11: 12.0178 | EY11: 20.2347 | EZ11: 16.1619 | FA11: 0 | FB11: 2.6824 | FC11: 7.2321 | FD11: 11.8115 | FE11: 16.3022 | FF11: 45.5479 | FG11: 13.4137 | FH11: 10.862 | FI11: 2.3944 | FJ11: 23.5958 | FK11: 42.5151 | FL11: 10.6658 | FM11: 8.0597 | FN11: 33.8072 | FO11: 10.0844
A12: PGA1 | C12: 0 | D12: 0 | E12: 0 | F12: 0 | G12: 0 | H12: 0 | I12: 0 | J12: 0 | K12: 0 | L12: 0 | M12: 0 | N12: 0 | O12: 0 | P12: 0 | Q12: 0 | R12: 0 | S12: 0 | T12: 0 | U12: 0 | V12: 0 | W12: 0 | X12: 0 | Y12: 0 | Z12: 0 | AA12: 0 | AB12: 0 | AC12: 0 | AD12: 0 | AE12: 0 | AF12: 0 | AG12: 0 | AH12: 0 | AI12: 0 | AJ12: 0 | AK12: 0 | AL12: 0 | AM12: 0 | AN12: 0 | AO12: 0 | AP12: 0 | AQ12: 0 | AR12: 0 | AS12: 0 | AT12: 0 | AU12: 0 | AV12: 0 | AW12: 0 | AX12: 0 | AY12: 0 | AZ12: 0 | BA12: 0 | BB12: 0 | BC12: 0 | BD12: 0 | BE12: 0 | BF12: 0 | BG12: 0 | BH12: 0 | BI12: 0 | BJ12: 0 | BK12: 0 | BL12: 0 | BM12: 0 | BN12: 0 | BO12: 0 | BP12: 0 | BQ12: 0 | BR12: 0 | BS12: 0 | BT12: 0 | BU12: 0 | BV12: 0 | BW12: 0 | BX12: 0 | BY12: 0 | BZ12: 0 | CA12: 0 | CB12: 0 | CC12: 0 | CD12: 0 | CE12: 0 | CF12: 0 | CG12: 0 | CH12: 0 | CI12: 0 | CJ12: 0 | CK12: 0 | CL12: 0 | CM12: 0 | CN12: 0 | CO12: 0 | CP12: 0 | CQ12: 0 | CR12: 0 | CS12: 0 | CT12: 0 | CU12: 0 | CV12: 0 | CW12: 0 | CX12: 0 | CY12: 0 | CZ12: 0 | DA12: 0 | DB12: 0 | DC12: 0 | DD12: 0 | DE12: 0 | DF12: 0 | DG12: 0 | DH12: 0 | DI12: 0 | DJ12: 0 | DK12: 0 | DL12: 0 | DM12: 0 | DN12: 0 | DO12: 0 | DP12: 0 | DQ12: 0 | DR12: 0 | DS12: 0 | DT12: 0 | DU12: 0 | DV12: 0 | DW12: 0 | DX12: 0 | DY12: 0 | DZ12: 0 | EA12: 0 | EB12: 0 | EC12: 0 | ED12: 0 | EE12: 0 | EF12: 0 | EG12: 0 | EH12: 0 | EI12: 0 | EJ12: 0 | EK12: 0 | EL12: 0 | EM12: 0 | EN12: 0 | EO12: 0 | EP12: 0 | EQ12: 0 | ER12: 0 | ES12: 0 | ET12: 0 | EU12: 0 | EV12: 0 | EW12: 0 | EX12: 0 | EY12: 0 | EZ12: 0 | FA12: 0 | FB12: 0 | FC12: 0 | FD12: 0 | FE12: 0 | FF12: 0 | FG12: 0 | FH12: 0 | FI12: 0 | FJ12: 0 | FK12: 0 | FL12: 0 | FM12: 0 | FN12: 0 | FO12: 0
