Workbook

Sheet Raw datas
D1: Conditions | F1: BS-064D0 | G1: BS-064D03 | H1: BS-064D10 | I1: BS-064D60 | J1: BS-082D0 | K1: BS-082D03 | L1: BS-082D10 | M1: BS-082D60 | N1: BS-336D0 | O1: BS-336D03 | P1: BS-336D10 | Q1: BS-336D60 | R1: BS-346D0 | S1: BS-346D03 | T1: BS-346D10 | U1: BS-346D60 | V1: BS-351D0 | W1: BS-351D03 | X1: BS-351D10 | Y1: BS-351D60 | Z1: BS-364D0 | AA1: BS-364D03 | AB1: BS-364D10 | AC1: BS-364D60 | AD1: BS-377D0 | AE1: BS-377D03 | AF1: BS-377D10 | AG1: BS-377D60 | AH1: BS-671D0 | AI1: BS-671D03 | AJ1: BS-671D10 | AK1: BS-671D60 | AL1: JV-035D0 | AM1: JV-035D03 | AN1: JV-035D10 | AO1: JV-035D60 | AP1: JV-048D0 | AQ1: JV-048D03 | AR1: JV-048D10 | AS1: JV-071D0 | AT1: JV-071D03 | AU1: JV-071D60 | AV1: JV-138D0 | AW1: JV-138D03 | AX1: JV-138D10 | AY1: JV-138D60 | AZ1: JV-148D0 | BA1: JV-148D03 | BB1: JV-148D10 | BC1: JV-148D60 | BD1: JV-157D0 | BE1: JV-157D03 | BF1: JV-157D10 | BG1: JV-157D60 | BH1: KT-193D0 | BI1: KT-193D03 | BJ1: KT-193D10 | BK1: KT-193D60 | BL1: KT-247D0 | BM1: KT-247D03 | BN1: KT-247D10 | BO1: KT-247D60 | BP1: KT-312D0 | BQ1: KT-312D03 | BR1: KT-312D10 | BS1: KT-312D60 | BT1: KT-313D0 | BU1: KT-313D03 | BV1: KT-313D10 | BW1: KT-313D60 | BX1: KT-347D0 | BY1: KT-347D03 | BZ1: KT-347D10 | CA1: KT-347D60 | CB1: KT-352D0 | CC1: KT-352D03 | CD1: KT-352D10 | CE1: KT-352D60 | CF1: KT-412D0 | CG1: KT-412D03 | CH1: KT-412D10 | CI1: KT-412D60 | CJ1: KT-417D0 | CK1: KT-417D03 | CL1: KT-417D10 | CM1: KT-417D60 | CN1: KT-434D0 | CO1: KT-434D03 | CP1: KT-434D10 | CQ1: KT-434D60 | CR1: KT-445D0 | CS1: KT-445D03 | CT1: KT-445D10 | CU1: KT-445D60 | CV1: KT-515D0 | CW1: KT-515D03 | CX1: KT-515D10 | CY1: KT-515D60 | CZ1: KT-522D0 | DA1: KT-522D03 | DB1: KT-522D10 | DC1: KT-522D60 | DD1: KT-525D0 | DE1: KT-525D03 | DF1: KT-525D10 | DG1: KT-525D60 | DH1: KT-537D0 | DI1: KT-537D03 | DJ1: KT-537D10 | DK1: KT-537D60 | DL1: KT-538D0 | DM1: KT-538D03 | DN1: KT-538D10 | DO1: KT-538D60 | DP1: KT-539D0 | DQ1: KT-539D03 | DR1: KT-539D10 | DS1: KT-539D60 | DT1: KT-565D0 | DU1: KT-565D03 | DV1: KT-565D10 | DW1: KT-612D0 | DX1: KT-612D03 | DY1: KT-612D10 | DZ1: KT-612D60 | EA1: KT-663D0 | EB1: KT-663D03 | EC1: KT-663D10 | ED1: KT-663D60 | EE1: KT-695D0 | EF1: KT-695D03 | EG1: KT-695D10 | EH1: KT-695D60 | EI1: KT-705D0 | EJ1: KT-705D03 | EK1: KT-705D10 | EL1: KT-705D60 | EM1: KT-716D0 | EN1: KT-716D03 | EO1: KT-716D10 | EP1: KT-716D60 | EQ1: KT-718D0 | ER1: KT-718D03 | ES1: KT-718D10 | ET1: KT-718D60 | EU1: KT-723D0 | EV1: KT-723D03 | EW1: KT-723D10 | EX1: KT-723D60 | EY1: KT-771D0 | EZ1: KT-771D03 | FA1: KT-771D10 | FB1: KT-771D60 | FC1: KT-805D0 | FD1: KT-805D03 | FE1: KT-805D10 | FF1: KT-805D60 | FG1: KT-880D0 | FH1: KT-880D03 | FI1: KT-880D10 | FJ1: KT-880D60 | FK1: KT-926D0 | FL1: KT-927D03 | FM1: KT-928D10 | FN1: KT-929D60 | FO1: KT-974D0 | FP1: KT-974D03 | FQ1: KT-974D10 | FR1: KT-974D60 | FS1: Extraction Controls | FW1: Quality Controls | GI1: Injection Control
A2: Family | B2: Metabolite name | C2: mz | D2: rt | E2: rt_absolute_error | F2: 241008DMI_Global_11 | G2: 241008DMI_Global_33 | H2: 241008DMI_Global_136 | I2: 241008DMI_Global_108 | J2: 241008DMI_Global_68 | K2: 241008DMI_Global_64 | L2: 241008DMI_Global_41 | M2: 241008DMI_Global_10 | N2: 241008DMI_Global_154 | O2: 241008DMI_Global_24 | P2: 241008DMI_Global_12 | Q2: 241008DMI_Global_103 | R2: 241008DMI_Global_137 | S2: 241008DMI_Global_19 | T2: 241008DMI_Global_101 | U2: 241008DMI_Global_120 | V2: 241008DMI_Global_21 | W2: 241008DMI_Global_46 | X2: 241008DMI_Global_74 | Y2: 241008DMI_Global_129 | Z2: 241008DMI_Global_02 | AA2: 241008DMI_Global_144 | AB2: 241008DMI_Global_107 | AC2: 241008DMI_Global_83 | AD2: 241008DMI_Global_35 | AE2: 241008DMI_Global_166 | AF2: 241008DMI_Global_72 | AG2: 241008DMI_Global_55 | AH2: 241008DMI_Global_134 | AI2: 241008DMI_Global_06 | AJ2: 241008DMI_Global_171 | AK2: 241008DMI_Global_80 | AL2: 241008DMI_Global_96 | AM2: 241008DMI_Global_169 | AN2: 241008DMI_Global_165 | AO2: 241008DMI_Global_49 | AP2: 241008DMI_Global_124 | AQ2: 241008DMI_Global_78 | AR2: 241008DMI_Global_20 | AS2: 241008DMI_Global_152 | AT2: 241008DMI_Global_116 | AU2: 241008DMI_Global_30 | AV2: 241008DMI_Global_05 | AW2: 241008DMI_Global_76 | AX2: 241008DMI_Global_38 | AY2: 241008DMI_Global_37 | AZ2: 241008DMI_Global_157 | BA2: 241008DMI_Global_59 | BB2: 241008DMI_Global_22 | BC2: 241008DMI_Global_17 | BD2: 241008DMI_Global_16 | BE2: 241008DMI_Global_81 | BF2: 241008DMI_Global_146 | BG2: 241008DMI_Global_69 | BH2: 241008DMI_Global_111 | BI2: 241008DMI_Global_92 | BJ2: 241008DMI_Global_31 | BK2: 241008DMI_Global_156 | BL2: 241008DMI_Global_32 | BM2: 241008DMI_Global_39 | BN2: 241008DMI_Global_114 | BO2: 241008DMI_Global_66 | BP2: 241008DMI_Global_70 | BQ2: 241008DMI_Global_153 | BR2: 241008DMI_Global_01 | BS2: 241008DMI_Global_28 | BT2: 241008DMI_Global_61 | BU2: 241008DMI_Global_164 | BV2: 241008DMI_Global_54 | BW2: 241008DMI_Global_135 | BX2: 241008DMI_Global_102 | BY2: 241008DMI_Global_44 | BZ2: 241008DMI_Global_36 | CA2: 241008DMI_Global_142 | CB2: 241008DMI_Global_105 | CC2: 241008DMI_Global_94 | CD2: 241008DMI_Global_98 | CE2: 241008DMI_Global_145 | CF2: 241008DMI_Global_170 | CG2: 241008DMI_Global_53 | CH2: 241008DMI_Global_57 | CI2: 241008DMI_Global_03 | CJ2: 241008DMI_Global_56 | CK2: 241008DMI_Global_159 | CL2: 241008DMI_Global_123 | CM2: 241008DMI_Global_75 | CN2: 241008DMI_Global_168 | CO2: 241008DMI_Global_09 | CP2: 241008DMI_Global_63 | CQ2: 241008DMI_Global_158 | CR2: 241008DMI_Global_42 | CS2: 241008DMI_Global_71 | CT2: 241008DMI_Global_112 | CU2: 241008DMI_Global_62 | CV2: 241008DMI_Global_58 | CW2: 241008DMI_Global_104 | CX2: 241008DMI_Global_52 | CY2: 241008DMI_Global_115 | CZ2: 241008DMI_Global_143 | DA2: 241008DMI_Global_118 | DB2: 241008DMI_Global_138 | DC2: 241008DMI_Global_97 | DD2: 241008DMI_Global_119 | DE2: 241008DMI_Global_121 | DF2: 241008DMI_Global_117 | DG2: 241008DMI_Global_161 | DH2: 241008DMI_Global_163 | DI2: 241008DMI_Global_150 | DJ2: 241008DMI_Global_95 | DK2: 241008DMI_Global_34 | DL2: 241008DMI_Global_85 | DM2: 241008DMI_Global_87 | DN2: 241008DMI_Global_47 | DO2: 241008DMI_Global_110 | DP2: 241008DMI_Global_132 | DQ2: 241008DMI_Global_133 | DR2: 241008DMI_Global_162 | DS2: 241008DMI_Global_125 | DT2: 241008DMI_Global_147 | DU2: 241008DMI_Global_139 | DV2: 241008DMI_Global_128 | DW2: 241008DMI_Global_27 | DX2: 241008DMI_Global_148 | DY2: 241008DMI_Global_14 | DZ2: 241008DMI_Global_90 | EA2: 241008DMI_Global_18 | EB2: 241008DMI_Global_130 | EC2: 241008DMI_Global_160 | ED2: 241008DMI_Global_93 | EE2: 241008DMI_Global_73 | EF2: 241008DMI_Global_26 | EG2: 241008DMI_Global_131 | EH2: 241008DMI_Global_140 | EI2: 241008DMI_Global_79 | EJ2: 241008DMI_Global_15 | EK2: 241008DMI_Global_67 | EL2: 241008DMI_Global_08 | EM2: 241008DMI_Global_100 | EN2: 241008DMI_Global_99 | EO2: 241008DMI_Global_84 | EP2: 241008DMI_Global_43 | EQ2: 241008DMI_Global_40 | ER2: 241008DMI_Global_50 | ES2: 241008DMI_Global_86 | ET2: 241008DMI_Global_151 | EU2: 241008DMI_Global_51 | EV2: 241008DMI_Global_109 | EW2: 241008DMI_Global_07 | EX2: 241008DMI_Global_13 | EY2: 241008DMI_Global_113 | EZ2: 241008DMI_Global_106 | FA2: 241008DMI_Global_25 | FB2: 241008DMI_Global_122 | FC2: 241008DMI_Global_45 | FD2: 241008DMI_Global_127 | FE2: 241008DMI_Global_77 | FF2: 241008DMI_Global_88 | FG2: 241008DMI_Global_126 | FH2: 241008DMI_Global_65 | FI2: 241008DMI_Global_155 | FJ2: 241008DMI_Global_167 | FK2: 241008DMI_Global_91 | FL2: 241008DMI_Global_29 | FM2: 241008DMI_Global_141 | FN2: 241008DMI_Global_23 | FO2: 241008DMI_Global_82 | FP2: 241008DMI_Global_04 | FQ2: 241008DMI_Global_149 | FR2: 241008DMI_Global_172 | FS2: 241008DMI_Global_ISTD_01 | FT2: 241008DMI_Global_blc01 | FU2: 241009DMI_Global_ISTD_02 | FV2: 241009DMI_Global_blc02 | FW2: 241009DMI_Global_QC01 | FX2: 241009DMI_Global_QC02 | FY2: 241009DMI_Global_QC03 | FZ2: 241009DMI_Global_QC04 | GA2: 241009DMI_Global_QC05 | GB2: 241009DMI_Global_QC06 | GC2: 241009DMI_Global_QC07 | GD2: 241009DMI_Global_QC08 | GE2: 241009DMI_Global_QC09 | GF2: 241009DMI_Global_QCdil02 | GG2: 241009DMI_Global_QCdil04 | GH2: 241009DMI_Global_QCdil08 | GI2: 241028 CCM_Global_ISTD03
A3: DG | B3: (1,2) DG 24:0 | C3: 439.37915 | D3: 2.2409 | E3: 0.0353 | F3: 101600 | G3: 131600 | H3: 71650 | I3: 82110 | J3: 108500 | K3: 49980 | L3: 79890 | M3: 114500 | N3: 61890 | O3: 103900 | P3: 101400 | Q3: 95500 | R3: 64300 | S3: 73070 | T3: 53320 | U3: 88140 | V3: 107700 | W3: 105500 | X3: 87250 | Y3: 86370 | Z3: 99640 | AA3: 61180 | AB3: 60520 | AC3: 101500 | AD3: 93990 | AE3: 67660 | AF3: 99120 | AG3: 128300 | AH3: 56210 | AI3: 69870 | AJ3: 64980 | AK3: 83420 | AL3: 88890 | AM3: 71370 | AN3: 45340 | AO3: 97540 | AP3: 111900 | AQ3: 119000 | AR3: 94880 | AS3: 79480 | AT3: 87450 | AU3: 120900 | AV3: 95060 | AW3: 94230 | AX3: 88960 | AY3: 60470 | AZ3: 76620 | BA3: 54410 | BB3: 100600 | BC3: 263100 | BD3: 93180 | BE3: 89070 | BF3: 59600 | BG3: 100800 | BH3: 75680 | BI3: 95760 | BJ3: 101400 | BK3: 101700 | BL3: 117300 | BM3: 71060 | BN3: 86950 | BO3: 112600 | BP3: 117300 | BQ3: 62180 | BR3: 97410 | BS3: 138800 | BT3: 109200 | BU3: 53620 | BV3: 97130 | BW3: 65290 | BX3: 69340 | BY3: 123300 | BZ3: 98230 | CA3: 49930 | CB3: 95590 | CC3: 104800 | CD3: 105100 | CE3: 48230 | CF3: 87550 | CG3: 93600 | CH3: 117900 | CI3: 103400 | CJ3: 94920 | CK3: 46750 | CL3: 91290 | CM3: 79890 | CN3: 36340 | CO3: 65030 | CP3: 111600 | CQ3: 34280 | CR3: 72260 | CS3: 108800 | CT3: 102200 | CU3: 105600 | CV3: 98630 | CW3: 76690 | CX3: 125800 | CY3: 103200 | CZ3: 57460 | DA3: 81140 | DB3: 60150 | DC3: 79080 | DD3: 84320 | DE3: 112600 | DF3: 92380 | DG3: 64480 | DH3: 70280 | DI3: 43410 | DJ3: 120200 | DK3: 85160 | DL3: 122400 | DM3: 113400 | DN3: 75470 | DO3: 100900 | DP3: 64900 | DQ3: 62230 | DR3: 53190 | DS3: 51270 | DT3: 35880 | DU3: 59160 | DV3: 73000 | DW3: 135500 | DX3: 54280 | DY3: 122800 | DZ3: 85760 | EA3: 140500 | EB3: 86320 | EC3: 59530 | ED3: 93480 | EE3: 100800 | EF3: 100700 | EG3: 76220 | EH3: 55530 | EI3: 109000 | EJ3: 113900 | EK3: 111800 | EL3: 119500 | EM3: 89930 | EN3: 70700 | EO3: 114700 | EP3: 96440 | EQ3: 94190 | ER3: 124800 | ES3: 100200 | ET3: 71600 | EU3: 103100 | EV3: 102400 | EW3: 110600 | EX3: 101700 | EY3: 104000 | EZ3: 82030 | FA3: 111800 | FB3: 67370 | FC3: 89770 | FD3: 46270 | FE3: 68480 | FF3: 185900 | FG3: 64090 | FH3: 90010 | FI3: 49190 | FJ3: 50010 | FK3: 82880 | FL3: 104800 | FM3: 72680 | FN3: 105700 | FO3: 99910 | FP3: 106400 | FQ3: 65200 | FR3: 83370 | FS3: 158400 | FT3: 1e-06 | FU3: 126200 | FV3: 1e-06 | FW3: 129100 | FX3: 104900 | FY3: 96070 | FZ3: 93340 | GA3: 84700 | GB3: 100800 | GC3: 79330 | GD3: 85670 | GE3: 98630 | GF3: 32920 | GG3: 17170 | GH3: 2252 | GI3: 34230
A4: DG | B4: (1,2) DG 30:0 | C4: 523.4734 | D4: 2.3486 | E4: 0.0265 | F4: 1e-06 | G4: 1e-06 | H4: 1e-06 | I4: 1e-06 | J4: 1e-06 | K4: 1e-06 | L4: 1e-06 | M4: 1e-06 | N4: 1e-06 | O4: 1e-06 | P4: 1e-06 | Q4: 1e-06 | R4: 1e-06 | S4: 1e-06 | T4: 1e-06 | U4: 1e-06 | V4: 1e-06 | W4: 1e-06 | X4: 1e-06 | Y4: 1e-06 | Z4: 1e-06 | AA4: 1e-06 | AB4: 1e-06 | AC4: 1e-06 | AD4: 1e-06 | AE4: 1e-06 | AF4: 2614 | AG4: 1644 | AH4: 1e-06 | AI4: 1e-06 | AJ4: 1e-06 | AK4: 1e-06 | AL4: 1028 | AM4: 1e-06 | AN4: 1626 | AO4: 1e-06 | AP4: 1e-06 | AQ4: 1690 | AR4: 1e-06 | AS4: 1e-06 | AT4: 1e-06 | AU4: 1e-06 | AV4: 1e-06 | AW4: 1e-06 | AX4: 1497 | AY4: 1e-06 | AZ4: 1e-06 | BA4: 1e-06 | BB4: 1588 | BC4: 1e-06 | BD4: 1e-06 | BE4: 1e-06 | BF4: 1e-06 | BG4: 1e-06 | BH4: 1e-06 | BI4: 1e-06 | BJ4: 1e-06 | BK4: 1e-06 | BL4: 1e-06 | BM4: 1e-06 | BN4: 1e-06 | BO4: 1e-06 | BP4: 1e-06 | BQ4: 1e-06 | BR4: 3078 | BS4: 1e-06 | BT4: 1e-06 | BU4: 1e-06 | BV4: 1166 | BW4: 1e-06 | BX4: 1e-06 | BY4: 1e-06 | BZ4: 1e-06 | CA4: 1e-06 | CB4: 1e-06 | CC4: 1e-06 | CD4: 1646 | CE4: 1e-06 | CF4: 1e-06 | CG4: 1e-06 | CH4: 1e-06 | CI4: 1281 | CJ4: 1e-06 | CK4: 1e-06 | CL4: 1e-06 | CM4: 1e-06 | CN4: 1e-06 | CO4: 1e-06 | CP4: 1e-06 | CQ4: 1e-06 | CR4: 1e-06 | CS4: 1e-06 | CT4: 1e-06 | CU4: 1e-06 | CV4: 1e-06 | CW4: 1e-06 | CX4: 1e-06 | CY4: 1e-06 | CZ4: 1e-06 | DA4: 1e-06 | DB4: 1e-06 | DC4: 1e-06 | DD4: 1e-06 | DE4: 1e-06 | DF4: 1e-06 | DG4: 1e-06 | DH4: 1e-06 | DI4: 1e-06 | DJ4: 1e-06 | DK4: 1e-06 | DL4: 1e-06 | DM4: 1e-06 | DN4: 1e-06 | DO4: 1e-06 | DP4: 1e-06 | DQ4: 1e-06 | DR4: 1e-06 | DS4: 1e-06 | DT4: 1e-06 | DU4: 1e-06 | DV4: 1e-06 | DW4: 1e-06 | DX4: 1e-06 | DY4: 1936 | DZ4: 1e-06 | EA4: 1e-06 | EB4: 1e-06 | EC4: 1e-06 | ED4: 1e-06 | EE4: 1e-06 | EF4: 1e-06 | EG4: 1e-06 | EH4: 1e-06 | EI4: 1e-06 | EJ4: 1e-06 | EK4: 1519 | EL4: 1442 | EM4: 1e-06 | EN4: 1e-06 | EO4: 1e-06 | EP4: 1e-06 | EQ4: 1e-06 | ER4: 1e-06 | ES4: 1e-06 | ET4: 1e-06 | EU4: 1e-06 | EV4: 1e-06 | EW4: 1e-06 | EX4: 1e-06 | EY4: 1e-06 | EZ4: 1e-06 | FA4: 1408 | FB4: 1620 | FC4: 1e-06 | FD4: 1e-06 | FE4: 1e-06 | FF4: 1e-06 | FG4: 1e-06 | FH4: 1e-06 | FI4: 1e-06 | FJ4: 1e-06 | FK4: 1e-06 | FL4: 1e-06 | FM4: 1e-06 | FN4: 1e-06 | FO4: 1e-06 | FP4: 1e-06 | FQ4: 1e-06 | FR4: 1e-06 | FS4: 1e-06 | FT4: 1e-06 | FU4: 1e-06 | FV4: 1e-06 | FW4: 1e-06 | FX4: 1e-06 | FY4: 1e-06 | FZ4: 1e-06 | GA4: 1e-06 | GB4: 1e-06 | GC4: 1e-06 | GD4: 1e-06 | GE4: 1e-06 | GF4: 1e-06 | GG4: 1e-06 | GH4: 1e-06 | GI4: 1e-06
A5: DG | B5: (1,2) DG 32:0 | C5: 551.50404 | D5: 2.378 | E5: 0.0265 | F5: 2090 | G5: 2827.4765 | H5: 2655.3528 | I5: 2112 | J5: 1552.3388 | K5: 1e-06 | L5: 1951.2601 | M5: 1602.4245 | N5: 1e-06 | O5: 1379.9442 | P5: 3775.5984 | Q5: 1176.9175 | R5: 1e-06 | S5: 3127.2324 | T5: 6679.745 | U5: 2850.1162 | V5: 1454 | W5: 2556.2226 | X5: 3705.433 | Y5: 1047 | Z5: 1e-06 | AA5: 1381 | AB5: 1202.8313 | AC5: 1672 | AD5: 1660 | AE5: 1873.3772 | AF5: 6462.2666 | AG5: 9120.5098 | AH5: 1e-06 | AI5: 3860.6326 | AJ5: 1104 | AK5: 1562 | AL5: 8101.7764 | AM5: 1672.0126 | AN5: 3622.0805 | AO5: 1248 | AP5: 1528 | AQ5: 3401.5417 | AR5: 2521.6682 | AS5: 3362.7221 | AT5: 4430.0318 | AU5: 2624.999 | AV5: 1979 | AW5: 1562 | AX5: 11227.528 | AY5: 1220.0253 | AZ5: 1e-06 | BA5: 1473.3219 | BB5: 5375.6578 | BC5: 2530.6743 | BD5: 2180.0211 | BE5: 2189.3589 | BF5: 1794.4278 | BG5: 1186 | BH5: 3591.1003 | BI5: 4982.5778 | BJ5: 3731.1888 | BK5: 2086.2971 | BL5: 2677 | BM5: 2484 | BN5: 3105.358 | BO5: 2489.6007 | BP5: 2813.1429 | BQ5: 1953.2469 | BR5: 14017.384 | BS5: 2915.3833 | BT5: 1e-06 | BU5: 1e-06 | BV5: 2443.7713 | BW5: 1162.8205 | BX5: 1215 | BY5: 2026.1696 | BZ5: 1375.1556 | CA5: 1e-06 | CB5: 1077 | CC5: 1045 | CD5: 5678.4343 | CE5: 1e-06 | CF5: 1e-06 | CG5: 2109.5918 | CH5: 3421.4428 | CI5: 8182.9906 | CJ5: 2384.1415 | CK5: 1e-06 | CL5: 1183 | CM5: 1e-06 | CN5: 1e-06 | CO5: 1e-06 | CP5: 1605.4213 | CQ5: 1e-06 | CR5: 1e-06 | CS5: 1789.9883 | CT5: 4721.6143 | CU5: 2096.4259 | CV5: 1e-06 | CW5: 2574.9297 | CX5: 6121.8893 | CY5: 1009 | CZ5: 1e-06 | DA5: 3032 | DB5: 1e-06 | DC5: 1e-06 | DD5: 1e-06 | DE5: 1106 | DF5: 3898.5164 | DG5: 1e-06 | DH5: 1e-06 | DI5: 1e-06 | DJ5: 1475.7076 | DK5: 1e-06 | DL5: 1331 | DM5: 2467.6345 | DN5: 3068.0703 | DO5: 1470 | DP5: 1e-06 | DQ5: 1e-06 | DR5: 1107.0572 | DS5: 1e-06 | DT5: 1342 | DU5: 1087 | DV5: 4032.918 | DW5: 1029 | DX5: 2707.9583 | DY5: 14863.075 | DZ5: 1836.7516 | EA5: 1e-06 | EB5: 1464 | EC5: 2944.4203 | ED5: 1108 | EE5: 1e-06 | EF5: 2681 | EG5: 2001.3589 | EH5: 1e-06 | EI5: 2537 | EJ5: 1602 | EK5: 3278.462 | EL5: 4783.3003 | EM5: 1802 | EN5: 1167.663 | EO5: 1e-06 | EP5: 1717.3589 | EQ5: 2488 | ER5: 1519 | ES5: 2404.9686 | ET5: 1e-06 | EU5: 1e-06 | EV5: 1761.7774 | EW5: 4170.0229 | EX5: 925.36033 | EY5: 2392 | EZ5: 1692 | FA5: 6992.0369 | FB5: 4728.8589 | FC5: 2096.6452 | FD5: 1471 | FE5: 4591.8312 | FF5: 3455.6148 | FG5: 1348 | FH5: 2266 | FI5: 2517.4428 | FJ5: 3493 | FK5: 2655.1279 | FL5: 2709.4311 | FM5: 1771 | FN5: 1138 | FO5: 1e-06 | FP5: 1245 | FQ5: 1e-06 | FR5: 1075 | FS5: 1e-06 | FT5: 1e-06 | FU5: 1e-06 | FV5: 1e-06 | FW5: 2063.2258 | FX5: 2220.4306 | FY5: 2468.149 | FZ5: 2804.6354 | GA5: 1820.9658 | GB5: 2125.5431 | GC5: 1260.0023 | GD5: 2114.5778 | GE5: 2408.4728 | GF5: 1e-06 | GG5: 1e-06 | GH5: 1e-06 | GI5: 1e-06
A6: DG | B6: (1,2) DG 32:1 | C6: 549.48894 | D6: 2.3956 | E6: 0.0265 | F6: 1e-06 | G6: 3141 | H6: 3251 | I6: 1e-06 | J6: 1081 | K6: 1e-06 | L6: 1733 | M6: 1514 | N6: 1e-06 | O6: 1351 | P6: 3453 | Q6: 1496 | R6: 1e-06 | S6: 1022 | T6: 4042 | U6: 1578 | V6: 1e-06 | W6: 1637 | X6: 2816 | Y6: 1e-06 | Z6: 1e-06 | AA6: 1e-06 | AB6: 1702 | AC6: 1e-06 | AD6: 1e-06 | AE6: 2033 | AF6: 5591 | AG6: 4720 | AH6: 1e-06 | AI6: 1620 | AJ6: 1e-06 | AK6: 1e-06 | AL6: 6043 | AM6: 1953 | AN6: 5328 | AO6: 1e-06 | AP6: 1e-06 | AQ6: 3948 | AR6: 2138 | AS6: 3343 | AT6: 1362 | AU6: 3412 | AV6: 1e-06 | AW6: 1e-06 | AX6: 6902 | AY6: 1772 | AZ6: 1e-06 | BA6: 2745 | BB6: 5526 | BC6: 2367 | BD6: 1121 | BE6: 3480 | BF6: 1309 | BG6: 1e-06 | BH6: 1964 | BI6: 1693 | BJ6: 2831 | BK6: 2468 | BL6: 1e-06 | BM6: 1e-06 | BN6: 2624 | BO6: 2392 | BP6: 1433 | BQ6: 2553 | BR6: 7386 | BS6: 2262 | BT6: 1026 | BU6: 1e-06 | BV6: 2402 | BW6: 1461 | BX6: 1e-06 | BY6: 1288 | BZ6: 1252 | CA6: 1e-06 | CB6: 1e-06 | CC6: 1e-06 | CD6: 5167 | CE6: 1e-06 | CF6: 1e-06 | CG6: 1729 | CH6: 2201 | CI6: 4244 | CJ6: 1216 | CK6: 1e-06 | CL6: 1e-06 | CM6: 1e-06 | CN6: 1e-06 | CO6: 1e-06 | CP6: 1719 | CQ6: 1e-06 | CR6: 1e-06 | CS6: 1037 | CT6: 3067 | CU6: 1731 | CV6: 1e-06 | CW6: 1954 | CX6: 5692 | CY6: 1e-06 | CZ6: 1e-06 | DA6: 1e-06 | DB6: 1e-06 | DC6: 1e-06 | DD6: 1e-06 | DE6: 1e-06 | DF6: 2176 | DG6: 1e-06 | DH6: 1e-06 | DI6: 1e-06 | DJ6: 1812 | DK6: 1e-06 | DL6: 1e-06 | DM6: 1198 | DN6: 2314 | DO6: 1e-06 | DP6: 1e-06 | DQ6: 1e-06 | DR6: 1000 | DS6: 1e-06 | DT6: 1e-06 | DU6: 1e-06 | DV6: 2991 | DW6: 1e-06 | DX6: 1387 | DY6: 3821 | DZ6: 1498 | EA6: 1e-06 | EB6: 1e-06 | EC6: 2997 | ED6: 1e-06 | EE6: 1e-06 | EF6: 1e-06 | EG6: 1346 | EH6: 1e-06 | EI6: 1e-06 | EJ6: 1e-06 | EK6: 3744 | EL6: 4397 | EM6: 1e-06 | EN6: 2765 | EO6: 1e-06 | EP6: 1346 | EQ6: 1e-06 | ER6: 1e-06 | ES6: 2267 | ET6: 1e-06 | EU6: 1e-06 | EV6: 2631 | EW6: 2833 | EX6: 1563 | EY6: 1e-06 | EZ6: 1e-06 | FA6: 5003 | FB6: 4547 | FC6: 1439 | FD6: 1e-06 | FE6: 3836 | FF6: 2428 | FG6: 1e-06 | FH6: 1e-06 | FI6: 2201 | FJ6: 1e-06 | FK6: 2675 | FL6: 1104 | FM6: 1e-06 | FN6: 1e-06 | FO6: 1e-06 | FP6: 1e-06 | FQ6: 1e-06 | FR6: 1e-06 | FS6: 1e-06 | FT6: 1e-06 | FU6: 1e-06 | FV6: 1e-06 | FW6: 1432 | FX6: 1743 | FY6: 1662 | FZ6: 2054 | GA6: 1833 | GB6: 2031 | GC6: 1073 | GD6: 1693 | GE6: 1851 | GF6: 1e-06 | GG6: 1e-06 | GH6: 1e-06 | GI6: 1e-06
A7: DG | B7: (1,2) DG 34:1 | C7: 577.52002 | D7: 2.4196 | E7: 0.0264 | F7: 6371 | G7: 14880 | H7: 9657 | I7: 10680 | J7: 7044 | K7: 2485 | L7: 7205 | M7: 5628 | N7: 2840 | O7: 10110 | P7: 13480 | Q7: 9799 | R7: 1550 | S7: 12220 | T7: 16370 | U7: 14940 | V7: 6685 | W7: 10210 | X7: 11660 | Y7: 5603 | Z7: 4408 | AA7: 6262 | AB7: 9476 | AC7: 9006 | AD7: 10960 | AE7: 14070 | AF7: 18180 | AG7: 26800 | AH7: 2305 | AI7: 11310 | AJ7: 6574 | AK7: 7416 | AL7: 44650 | AM7: 9425 | AN7: 11480 | AO7: 8577 | AP7: 7087 | AQ7: 13010 | AR7: 10280 | AS7: 19320 | AT7: 15350 | AU7: 11860 | AV7: 6155 | AW7: 8691 | AX7: 24010 | AY7: 4996 | AZ7: 5918 | BA7: 13920 | BB7: 18500 | BC7: 12390 | BD7: 8802 | BE7: 17350 | BF7: 8994 | BG7: 6965 | BH7: 19480 | BI7: 23600 | BJ7: 11010 | BK7: 9638 | BL7: 11440 | BM7: 9950 | BN7: 16850 | BO7: 17330 | BP7: 10440 | BQ7: 11690 | BR7: 18020 | BS7: 6357 | BT7: 4098 | BU7: 2281 | BV7: 6434 | BW7: 6582 | BX7: 7780 | BY7: 10770 | BZ7: 9094 | CA7: 3075 | CB7: 7800 | CC7: 6266 | CD7: 22080 | CE7: 3111 | CF7: 1229 | CG7: 13820 | CH7: 14170 | CI7: 28560 | CJ7: 11330 | CK7: 3953 | CL7: 7184 | CM7: 2005 | CN7: 2309 | CO7: 2366 | CP7: 11040 | CQ7: 4106 | CR7: 2139 | CS7: 8360 | CT7: 18590 | CU7: 10800 | CV7: 2061 | CW7: 18250 | CX7: 28290 | CY7: 5828 | CZ7: 2361 | DA7: 10170 | DB7: 5188 | DC7: 4050 | DD7: 6146 | DE7: 7308 | DF7: 13950 | DG7: 1724 | DH7: 2415 | DI7: 2384 | DJ7: 7484 | DK7: 2080 | DL7: 7578 | DM7: 16140 | DN7: 15800 | DO7: 11190 | DP7: 1530 | DQ7: 3660 | DR7: 6748 | DS7: 2253 | DT7: 5465 | DU7: 4306 | DV7: 12560 | DW7: 3927 | DX7: 12210 | DY7: 21740 | DZ7: 10200 | EA7: 2219 | EB7: 5402 | EC7: 12050 | ED7: 5337 | EE7: 3320 | EF7: 7011 | EG7: 10270 | EH7: 2801 | EI7: 10470 | EJ7: 7201 | EK7: 8666 | EL7: 14460 | EM7: 11640 | EN7: 12370 | EO7: 4001 | EP7: 10430 | EQ7: 8706 | ER7: 13700 | ES7: 18180 | ET7: 3657 | EU7: 2286 | EV7: 14250 | EW7: 16200 | EX7: 7334 | EY7: 11350 | EZ7: 16240 | FA7: 21620 | FB7: 17880 | FC7: 14190 | FD7: 7296 | FE7: 20110 | FF7: 19150 | FG7: 6818 | FH7: 6470 | FI7: 12980 | FJ7: 7697 | FK7: 18610 | FL7: 8787 | FM7: 8064 | FN7: 5072 | FO7: 2387 | FP7: 6466 | FQ7: 3414 | FR7: 5738 | FS7: 1e-06 | FT7: 1e-06 | FU7: 1e-06 | FV7: 1e-06 | FW7: 9615 | FX7: 10940 | FY7: 10660 | FZ7: 10680 | GA7: 12430 | GB7: 12310 | GC7: 8895 | GD7: 9690 | GE7: 10070 | GF7: 2917 | GG7: 1409 | GH7: 1e-06 | GI7: 1e-06
A8: DG | B8: (1,2) DG 34:3 | C8: 573.48912 | D8: 2.4592 | E8: 0.0265 | F8: 1e-06 | G8: 1e-06 | H8: 1e-06 | I8: 1e-06 | J8: 1e-06 | K8: 1e-06 | L8: 1e-06 | M8: 1e-06 | N8: 1e-06 | O8: 1013 | P8: 1e-06 | Q8: 1e-06 | R8: 1e-06 | S8: 1e-06 | T8: 1062 | U8: 1e-06 | V8: 1e-06 | W8: 1e-06 | X8: 1e-06 | Y8: 1e-06 | Z8: 1e-06 | AA8: 1e-06 | AB8: 1e-06 | AC8: 1e-06 | AD8: 1e-06 | AE8: 1e-06 | AF8: 1e-06 | AG8: 1242 | AH8: 1e-06 | AI8: 1e-06 | AJ8: 1e-06 | AK8: 1e-06 | AL8: 1402 | AM8: 1e-06 | AN8: 1e-06 | AO8: 1e-06 | AP8: 1e-06 | AQ8: 1e-06 | AR8: 1e-06 | AS8: 1e-06 | AT8: 1e-06 | AU8: 1005 | AV8: 1e-06 | AW8: 1e-06 | AX8: 1404 | AY8: 1e-06 | AZ8: 1e-06 | BA8: 1278 | BB8: 1006 | BC8: 1128 | BD8: 1e-06 | BE8: 1e-06 | BF8: 1e-06 | BG8: 1e-06 | BH8: 1e-06 | BI8: 1e-06 | BJ8: 1e-06 | BK8: 1e-06 | BL8: 1e-06 | BM8: 1e-06 | BN8: 1e-06 | BO8: 1e-06 | BP8: 1e-06 | BQ8: 1e-06 | BR8: 1294 | BS8: 1e-06 | BT8: 1e-06 | BU8: 1e-06 | BV8: 1e-06 | BW8: 1e-06 | BX8: 1e-06 | BY8: 1e-06 | BZ8: 1e-06 | CA8: 1e-06 | CB8: 1e-06 | CC8: 1e-06 | CD8: 1220 | CE8: 1e-06 | CF8: 1e-06 | CG8: 1e-06 | CH8: 1e-06 | CI8: 1693 | CJ8: 1e-06 | CK8: 1e-06 | CL8: 1e-06 | CM8: 1e-06 | CN8: 1e-06 | CO8: 1e-06 | CP8: 1e-06 | CQ8: 1e-06 | CR8: 1e-06 | CS8: 1e-06 | CT8: 1e-06 | CU8: 1e-06 | CV8: 1e-06 | CW8: 1e-06 | CX8: 1476 | CY8: 1e-06 | CZ8: 1e-06 | DA8: 1e-06 | DB8: 1e-06 | DC8: 1e-06 | DD8: 1e-06 | DE8: 1e-06 | DF8: 1e-06 | DG8: 1e-06 | DH8: 1e-06 | DI8: 1e-06 | DJ8: 1e-06 | DK8: 1e-06 | DL8: 1e-06 | DM8: 1e-06 | DN8: 1e-06 | DO8: 1e-06 | DP8: 1e-06 | DQ8: 1e-06 | DR8: 1e-06 | DS8: 1e-06 | DT8: 1e-06 | DU8: 1e-06 | DV8: 1e-06 | DW8: 1e-06 | DX8: 1e-06 | DY8: 1e-06 | DZ8: 1e-06 | EA8: 1e-06 | EB8: 1e-06 | EC8: 1e-06 | ED8: 1e-06 | EE8: 1e-06 | EF8: 1e-06 | EG8: 1e-06 | EH8: 1e-06 | EI8: 1e-06 | EJ8: 1e-06 | EK8: 1e-06 | EL8: 1e-06 | EM8: 1e-06 | EN8: 1e-06 | EO8: 1e-06 | EP8: 1e-06 | EQ8: 1e-06 | ER8: 1e-06 | ES8: 1e-06 | ET8: 1e-06 | EU8: 1e-06 | EV8: 1010 | EW8: 1e-06 | EX8: 1e-06 | EY8: 1e-06 | EZ8: 1e-06 | FA8: 1323 | FB8: 1118 | FC8: 1e-06 | FD8: 1e-06 | FE8: 1016 | FF8: 1e-06 | FG8: 1e-06 | FH8: 1e-06 | FI8: 1e-06 | FJ8: 1e-06 | FK8: 1601 | FL8: 1e-06 | FM8: 1e-06 | FN8: 1e-06 | FO8: 1e-06 | FP8: 1e-06 | FQ8: 1e-06 | FR8: 1e-06 | FS8: 1e-06 | FT8: 1e-06 | FU8: 1e-06 | FV8: 1e-06 | FW8: 1e-06 | FX8: 1e-06 | FY8: 1e-06 | FZ8: 1e-06 | GA8: 1e-06 | GB8: 1e-06 | GC8: 1e-06 | GD8: 1e-06 | GE8: 1e-06 | GF8: 1e-06 | GG8: 1e-06 | GH8: 1e-06 | GI8: 1e-06
A9: DG | B9: (1,2) DG 36:3 | C9: 601.52008 | D9: 2.4802 | E9: 0.0264 | F9: 2949 | G9: 6469 | H9: 1738 | I9: 3699 | J9: 2923 | K9: 1e-06 | L9: 1499 | M9: 2489 | N9: 1552 | O9: 5930 | P9: 4715 | Q9: 6220 | R9: 1e-06 | S9: 5918 | T9: 7422 | U9: 4194 | V9: 2231 | W9: 5519 | X9: 3710 | Y9: 2467 | Z9: 1131 | AA9: 1892 | AB9: 1989 | AC9: 2675 | AD9: 4321 | AE9: 4914 | AF9: 3611 | AG9: 12660 | AH9: 1097 | AI9: 6476 | AJ9: 2697 | AK9: 3479 | AL9: 15100 | AM9: 4734 | AN9: 1902 | AO9: 4498 | AP9: 3870 | AQ9: 5499 | AR9: 5473 | AS9: 8832 | AT9: 8426 | AU9: 6198 | AV9: 3198 | AW9: 3477 | AX9: 6550 | AY9: 1969 | AZ9: 3027 | BA9: 9358 | BB9: 4527 | BC9: 8839 | BD9: 4583 | BE9: 6492 | BF9: 3663 | BG9: 3963 | BH9: 8697 | BI9: 7538 | BJ9: 2780 | BK9: 4359 | BL9: 3949 | BM9: 6034 | BN9: 2982 | BO9: 7315 | BP9: 5066 | BQ9: 4362 | BR9: 7249 | BS9: 3122 | BT9: 1310 | BU9: 1290 | BV9: 1680 | BW9: 1735 | BX9: 3105 | BY9: 4312 | BZ9: 3146 | CA9: 2419 | CB9: 5333 | CC9: 3015 | CD9: 6387 | CE9: 1789 | CF9: 1e-06 | CG9: 5921 | CH9: 8761 | CI9: 11090 | CJ9: 5752 | CK9: 2799 | CL9: 2454 | CM9: 1561 | CN9: 1e-06 | CO9: 1004 | CP9: 3239 | CQ9: 1339 | CR9: 1e-06 | CS9: 3749 | CT9: 7905 | CU9: 3911 | CV9: 1292 | CW9: 8967 | CX9: 11350 | CY9: 3512 | CZ9: 1e-06 | DA9: 6150 | DB9: 1314 | DC9: 1207 | DD9: 2016 | DE9: 3910 | DF9: 4207 | DG9: 1219 | DH9: 1767 | DI9: 2157 | DJ9: 3921 | DK9: 1203 | DL9: 3286 | DM9: 8606 | DN9: 4518 | DO9: 4397 | DP9: 1e-06 | DQ9: 2235 | DR9: 1680 | DS9: 1009 | DT9: 2075 | DU9: 1966 | DV9: 3248 | DW9: 1396 | DX9: 4990 | DY9: 7000 | DZ9: 6232 | EA9: 1e-06 | EB9: 3263 | EC9: 3603 | ED9: 4038 | EE9: 2421 | EF9: 4231 | EG9: 3458 | EH9: 1407 | EI9: 5406 | EJ9: 3224 | EK9: 2816 | EL9: 6278 | EM9: 5731 | EN9: 3772 | EO9: 2319 | EP9: 5466 | EQ9: 4495 | ER9: 6696 | ES9: 10450 | ET9: 3139 | EU9: 1120 | EV9: 8190 | EW9: 6732 | EX9: 3929 | EY9: 6429 | EZ9: 7425 | FA9: 7234 | FB9: 8071 | FC9: 5906 | FD9: 3316 | FE9: 9407 | FF9: 8351 | FG9: 1877 | FH9: 1987 | FI9: 2127 | FJ9: 2049 | FK9: 8766 | FL9: 4420 | FM9: 2709 | FN9: 2884 | FO9: 1027 | FP9: 4169 | FQ9: 1307 | FR9: 1904 | FS9: 1e-06 | FT9: 1e-06 | FU9: 1e-06 | FV9: 1e-06 | FW9: 5348 | FX9: 4782 | FY9: 6336 | FZ9: 5256 | GA9: 5104 | GB9: 5290 | GC9: 3183 | GD9: 3152 | GE9: 4875 | GF9: 1096 | GG9: 1e-06 | GH9: 1e-06 | GI9: 1e-06
A10: DG | B10: (1,3) DG 24:0 | C10: 439.379 | D10: 2.406 | E10: 0.0353 | F10: 38560 | G10: 50040 | H10: 22580 | I10: 29280 | J10: 38450 | K10: 13230 | L10: 33760 | M10: 44030 | N10: 22650 | O10: 39950 | P10: 42430 | Q10: 32500 | R10: 26130 | S10: 24430 | T10: 19140 | U10: 33000 | V10: 44780 | W10: 39150 | X10: 27710 | Y10: 26030 | Z10: 47490 | AA10: 16750 | AB10: 22380 | AC10: 36040 | AD10: 42490 | AE10: 26580 | AF10: 36390 | AG10: 41380 | AH10: 19300 | AI10: 22490 | AJ10: 26230 | AK10: 35420 | AL10: 34570 | AM10: 25580 | AN10: 19640 | AO10: 48040 | AP10: 41400 | AQ10: 45280 | AR10: 32110 | AS10: 26090 | AT10: 31270 | AU10: 43350 | AV10: 36710 | AW10: 38160 | AX10: 38440 | AY10: 20880 | AZ10: 25860 | BA10: 21700 | BB10: 36670 | BC10: 79520 | BD10: 30420 | BE10: 32180 | BF10: 22160 | BG10: 27740 | BH10: 33420 | BI10: 28850 | BJ10: 33050 | BK10: 32540 | BL10: 35420 | BM10: 31680 | BN10: 25260 | BO10: 40080 | BP10: 40390 | BQ10: 24610 | BR10: 35970 | BS10: 44370 | BT10: 40830 | BU10: 15510 | BV10: 26490 | BW10: 23950 | BX10: 21860 | BY10: 48340 | BZ10: 35750 | CA10: 23590 | CB10: 30190 | CC10: 37690 | CD10: 35310 | CE10: 16250 | CF10: 1e-06 | CG10: 37520 | CH10: 35300 | CI10: 38080 | CJ10: 33910 | CK10: 20880 | CL10: 29480 | CM10: 20800 | CN10: 47680 | CO10: 58280 | CP10: 40580 | CQ10: 11370 | CR10: 24990 | CS10: 44280 | CT10: 41360 | CU10: 64900 | CV10: 40170 | CW10: 39350 | CX10: 44620 | CY10: 34550 | CZ10: 23970 | DA10: 25880 | DB10: 15790 | DC10: 25400 | DD10: 35580 | DE10: 37170 | DF10: 28970 | DG10: 22780 | DH10: 26750 | DI10: 15710 | DJ10: 46580 | DK10: 31690 | DL10: 44490 | DM10: 46170 | DN10: 26270 | DO10: 32860 | DP10: 24610 | DQ10: 24590 | DR10: 23780 | DS10: 18770 | DT10: 13250 | DU10: 22190 | DV10: 26860 | DW10: 55440 | DX10: 20600 | DY10: 46500 | DZ10: 34190 | EA10: 50310 | EB10: 30250 | EC10: 19950 | ED10: 32150 | EE10: 31850 | EF10: 41090 | EG10: 32170 | EH10: 15580 | EI10: 35580 | EJ10: 41880 | EK10: 30270 | EL10: 46870 | EM10: 39750 | EN10: 34010 | EO10: 37210 | EP10: 40740 | EQ10: 35520 | ER10: 40200 | ES10: 45360 | ET10: 25920 | EU10: 40260 | EV10: 31640 | EW10: 38620 | EX10: 31310 | EY10: 37310 | EZ10: 27740 | FA10: 40020 | FB10: 30230 | FC10: 35990 | FD10: 20560 | FE10: 25370 | FF10: 54240 | FG10: 20460 | FH10: 28180 | FI10: 16550 | FJ10: 18150 | FK10: 32930 | FL10: 44310 | FM10: 26250 | FN10: 39410 | FO10: 35420 | FP10: 43840 | FQ10: 21820 | FR10: 28280 | FS10: 64490 | FT10: 1e-06 | FU10: 62580 | FV10: 1e-06 | FW10: 36880 | FX10: 40390 | FY10: 32460 | FZ10: 34190 | GA10: 34290 | GB10: 39540 | GC10: 30550 | GD10: 32330 | GE10: 33520 | GF10: 13530 | GG10: 5807 | GH10: 1960 | GI10: 187400
A11: DG | B11: (1,3) DG 32:0 | C11: 551.50434 | D11: 2.5134 | E11: 0.0265 | F11: 1e-06 | G11: 1366.2572 | H11: 1e-06 | I11: 1e-06 | J11: 1e-06 | K11: 1e-06 | L11: 1e-06 | M11: 1e-06 | N11: 1e-06 | O11: 1e-06 | P11: 1305 | Q11: 1e-06 | R11: 1e-06 | S11: 1e-06 | T11: 1686 | U11: 1093 | V11: 1e-06 | W11: 1e-06 | X11: 1421.6565 | Y11: 1e-06 | Z11: 1e-06 | AA11: 1e-06 | AB11: 1160 | AC11: 1e-06 | AD11: 1e-06 | AE11: 1e-06 | AF11: 1852.0272 | AG11: 2908.1223 | AH11: 1e-06 | AI11: 1387 | AJ11: 1e-06 | AK11: 1e-06 | AL11: 2904.0332 | AM11: 1e-06 | AN11: 1082.201 | AO11: 1e-06 | AP11: 1e-06 | AQ11: 1187 | AR11: 1191 | AS11: 1670.9709 | AT11: 2254 | AU11: 1062.0304 | AV11: 1e-06 | AW11: 1e-06 | AX11: 4025.4241 | AY11: 1e-06 | AZ11: 1e-06 | BA11: 1e-06 | BB11: 2449.3973 | BC11: 1e-06 | BD11: 1e-06 | BE11: 1e-06 | BF11: 1e-06 | BG11: 1e-06 | BH11: 1482 | BI11: 1648 | BJ11: 1e-06 | BK11: 1e-06 | BL11: 1e-06 | BM11: 1020 | BN11: 1021 | BO11: 1e-06 | BP11: 1e-06 | BQ11: 1141.6017 | BR11: 5675.7465 | BS11: 1e-06 | BT11: 1e-06 | BU11: 1e-06 | BV11: 1e-06 | BW11: 1e-06 | BX11: 1e-06 | BY11: 1e-06 | BZ11: 1e-06 | CA11: 1e-06 | CB11: 1e-06 | CC11: 1e-06 | CD11: 2577.8514 | CE11: 1e-06 | CF11: 1e-06 | CG11: 1042 | CH11: 1e-06 | CI11: 3022.4264 | CJ11: 1e-06 | CK11: 1e-06 | CL11: 1e-06 | CM11: 1e-06 | CN11: 1e-06 | CO11: 1e-06 | CP11: 1e-06 | CQ11: 1e-06 | CR11: 1e-06 | CS11: 1e-06 | CT11: 1560 | CU11: 1447 | CV11: 1e-06 | CW11: 1197 | CX11: 2251.0192 | CY11: 1e-06 | CZ11: 1e-06 | DA11: 1e-06 | DB11: 1e-06 | DC11: 1e-06 | DD11: 1e-06 | DE11: 1e-06 | DF11: 1327 | DG11: 1e-06 | DH11: 1e-06 | DI11: 1e-06 | DJ11: 1e-06 | DK11: 1e-06 | DL11: 1e-06 | DM11: 1e-06 | DN11: 1211 | DO11: 1e-06 | DP11: 1e-06 | DQ11: 1e-06 | DR11: 1e-06 | DS11: 1e-06 | DT11: 1e-06 | DU11: 1e-06 | DV11: 1380 | DW11: 1e-06 | DX11: 1227 | DY11: 4478 | DZ11: 1e-06 | EA11: 1e-06 | EB11: 1e-06 | EC11: 1169 | ED11: 1e-06 | EE11: 1e-06 | EF11: 1249 | EG11: 1e-06 | EH11: 1e-06 | EI11: 1e-06 | EJ11: 1e-06 | EK11: 1e-06 | EL11: 2215.9897 | EM11: 1e-06 | EN11: 1e-06 | EO11: 1e-06 | EP11: 1e-06 | EQ11: 1370 | ER11: 1e-06 | ES11: 1e-06 | ET11: 1e-06 | EU11: 1e-06 | EV11: 1e-06 | EW11: 1391 | EX11: 1e-06 | EY11: 1e-06 | EZ11: 1e-06 | FA11: 2627.0754 | FB11: 1881.791 | FC11: 1e-06 | FD11: 1e-06 | FE11: 1547 | FF11: 1e-06 | FG11: 1e-06 | FH11: 1e-06 | FI11: 1669 | FJ11: 1270 | FK11: 1296.284 | FL11: 1e-06 | FM11: 1e-06 | FN11: 1e-06 | FO11: 1e-06 | FP11: 1e-06 | FQ11: 1e-06 | FR11: 1e-06 | FS11: 1e-06 | FT11: 1e-06 | FU11: 1e-06 | FV11: 1e-06 | FW11: 1e-06 | FX11: 1e-06 | FY11: 1e-06 | FZ11: 1e-06 | GA11: 1e-06 | GB11: 1e-06 | GC11: 1e-06 | GD11: 1e-06 | GE11: 1e-06 | GF11: 1e-06 | GG11: 1e-06 | GH11: 1e-06 | GI11: 1e-06
A12: DG | B12: (1,3) DG 32:1 | C12: 549.48931 | D12: 2.5255 | E12: 0.0312 | F12: 1e-06 | G12: 1299 | H12: 1e-06 | I12: 1e-06 | J12: 1e-06 | K12: 1e-06 | L12: 1e-06 | M12: 1e-06 | N12: 1e-06 | O12: 1e-06 | P12: 1e-06 | Q12: 1e-06 | R12: 1e-06 | S12: 1e-06 | T12: 1e-06 | U12: 1e-06 | V12: 1e-06 | W12: 1e-06 | X12: 1041 | Y12: 1e-06 | Z12: 1e-06 | AA12: 1e-06 | AB12: 1e-06 | AC12: 1e-06 | AD12: 1e-06 | AE12: 1e-06 | AF12: 1350 | AG12: 1807 | AH12: 1e-06 | AI12: 1e-06 | AJ12: 1e-06 | AK12: 1e-06 | AL12: 1579 | AM12: 1e-06 | AN12: 1155 | AO12: 1e-06 | AP12: 1e-06 | AQ12: 1e-06 | AR12: 1e-06 | AS12: 1206 | AT12: 1e-06 | AU12: 1145 | AV12: 1e-06 | AW12: 1e-06 | AX12: 2153 | AY12: 1e-06 | AZ12: 1e-06 | BA12: 1e-06 | BB12: 2298 | BC12: 1e-06 | BD12: 1e-06 | BE12: 1e-06 | BF12: 1e-06 | BG12: 1e-06 | BH12: 1e-06 | BI12: 1e-06 | BJ12: 1e-06 | BK12: 1e-06 | BL12: 1e-06 | BM12: 1e-06 | BN12: 1e-06 | BO12: 1e-06 | BP12: 1e-06 | BQ12: 1114 | BR12: 2125 | BS12: 1e-06 | BT12: 1e-06 | BU12: 1e-06 | BV12: 1e-06 | BW12: 1e-06 | BX12: 1e-06 | BY12: 1e-06 | BZ12: 1e-06 | CA12: 1e-06 | CB12: 1e-06 | CC12: 1e-06 | CD12: 1967 | CE12: 1e-06 | CF12: 1e-06 | CG12: 1e-06 | CH12: 1e-06 | CI12: 1092 | CJ12: 1e-06 | CK12: 1e-06 | CL12: 1e-06 | CM12: 1e-06 | CN12: 1e-06 | CO12: 1e-06 | CP12: 1e-06 | CQ12: 1e-06 | CR12: 1e-06 | CS12: 1e-06 | CT12: 1e-06 | CU12: 1e-06 | CV12: 1e-06 | CW12: 1e-06 | CX12: 1543 | CY12: 1e-06 | CZ12: 1e-06 | DA12: 1e-06 | DB12: 1e-06 | DC12: 1e-06 | DD12: 1e-06 | DE12: 1e-06 | DF12: 1e-06 | DG12: 1e-06 | DH12: 1e-06 | DI12: 1e-06 | DJ12: 1e-06 | DK12: 1e-06 | DL12: 1e-06 | DM12: 1e-06 | DN12: 1e-06 | DO12: 1e-06 | DP12: 1e-06 | DQ12: 1e-06 | DR12: 1e-06 | DS12: 1e-06 | DT12: 1e-06 | DU12: 1e-06 | DV12: 1e-06 | DW12: 1e-06 | DX12: 1e-06 | DY12: 1e-06 | DZ12: 1e-06 | EA12: 1e-06 | EB12: 1e-06 | EC12: 1e-06 | ED12: 1e-06 | EE12: 1e-06 | EF12: 1e-06 | EG12: 1e-06 | EH12: 1e-06 | EI12: 1e-06 | EJ12: 1e-06 | EK12: 1e-06 | EL12: 1254 | EM12: 1e-06 | EN12: 1e-06 | EO12: 1e-06 | EP12: 1e-06 | EQ12: 1e-06 | ER12: 1e-06 | ES12: 1e-06 | ET12: 1e-06 | EU12: 1e-06 | EV12: 1e-06 | EW12: 1e-06 | EX12: 1e-06 | EY12: 1e-06 | EZ12: 1e-06 | FA12: 1687 | FB12: 1172 | FC12: 1e-06 | FD12: 1e-06 | FE12: 1e-06 | FF12: 1e-06 | FG12: 1e-06 | FH12: 1e-06 | FI12: 1e-06 | FJ12: 1e-06 | FK12: 1154 | FL12: 1e-06 | FM12: 1e-06 | FN12: 1e-06 | FO12: 1e-06 | FP12: 1e-06 | FQ12: 1e-06 | FR12: 1e-06 | FS12: 1e-06 | FT12: 1e-06 | FU12: 1e-06 | FV12: 1e-06 | FW12: 1e-06 | FX12: 1e-06 | FY12: 1e-06 | FZ12: 1e-06 | GA12: 1e-06 | GB12: 1e-06 | GC12: 1e-06 | GD12: 1e-06 | GE12: 1e-06 | GF12: 1e-06 | GG12: 1e-06 | GH12: 1e-06 | GI12: 1e-06
A13: DG | B13: (1,3) DG 34:1 | C13: 577.51993 | D13: 2.5458 | E13: 0.0177 | F13: 1253.439 | G13: 5756.8527 | H13: 3064.9469 | I13: 2971.4806 | J13: 1572.622 | K13: 1e-06 | L13: 2552 | M13: 2306.7512 | N13: 1e-06 | O13: 4204.4313 | P13: 4133.3944 | Q13: 2502.3929 | R13: 1e-06 | S13: 4273.7254 | T13: 3536.9015 | U13: 4815.6491 | V13: 1476.8472 | W13: 3631.8229 | X13: 5010.7806 | Y13: 1288 | Z13: 1337 | AA13: 1781.9462 | AB13: 3600.2319 | AC13: 2076.3098 | AD13: 3993.8925 | AE13: 5189.3823 | AF13: 7159.7662 | AG13: 10630.707 | AH13: 1e-06 | AI13: 3074.8029 | AJ13: 1599 | AK13: 2751.0377 | AL13: 15883.241 | AM13: 3308.6204 | AN13: 3654.5402 | AO13: 1656.0089 | AP13: 3106.9953 | AQ13: 3831.68 | AR13: 2351.9763 | AS13: 8574.3359 | AT13: 3738.5454 | AU13: 4493.6366 | AV13: 1370.154 | AW13: 2808.8463 | AX13: 10439.107 | AY13: 2232.0316 | AZ13: 1762.1518 | BA13: 4604.5416 | BB13: 7194.2892 | BC13: 4468.5234 | BD13: 3301.5675 | BE13: 6563.9888 | BF13: 3347.6068 | BG13: 2452.3113 | BH13: 8445.7215 | BI13: 5071.3103 | BJ13: 4085.8471 | BK13: 2104.8192 | BL13: 4600.3755 | BM13: 3497.1993 | BN13: 3277.9854 | BO13: 4745.0955 | BP13: 2704.7648 | BQ13: 5493.4692 | BR13: 5413.4885 | BS13: 1721.1752 | BT13: 1e-06 | BU13: 1e-06 | BV13: 1885.5358 | BW13: 1615.1632 | BX13: 2165.5978 | BY13: 2732.572 | BZ13: 2549.0883 | CA13: 1e-06 | CB13: 1942.8691 | CC13: 1336.7209 | CD13: 7165.7078 | CE13: 1139 | CF13: 1e-06 | CG13: 5423.0375 | CH13: 4418.3852 | CI13: 9637.4352 | CJ13: 4037.8343 | CK13: 1291.786 | CL13: 1189.6265 | CM13: 1e-06 | CN13: 1e-06 | CO13: 1e-06 | CP13: 2511.5138 | CQ13: 1143 | CR13: 1e-06 | CS13: 3057.7678 | CT13: 6307.9089 | CU13: 4075.6189 | CV13: 1e-06 | CW13: 5677.0495 | CX13: 9727.6593 | CY13: 1080.1647 | CZ13: 1e-06 | DA13: 4278.2114 | DB13: 1879 | DC13: 1003 | DD13: 1787.7059 | DE13: 2349.2244 | DF13: 3444.6499 | DG13: 1e-06 | DH13: 1e-06 | DI13: 1221 | DJ13: 1436.9394 | DK13: 1e-06 | DL13: 1498.1155 | DM13: 5560.514 | DN13: 4819.8539 | DO13: 3154.47 | DP13: 1e-06 | DQ13: 1186.1208 | DR13: 2090 | DS13: 1e-06 | DT13: 1188.1027 | DU13: 2078 | DV13: 3045.3143 | DW13: 1095 | DX13: 4789.8607 | DY13: 4806.0964 | DZ13: 2675.4171 | EA13: 1e-06 | EB13: 1499.4768 | EC13: 3579.6468 | ED13: 1246.8003 | EE13: 1e-06 | EF13: 2563.352 | EG13: 3231.1299 | EH13: 1e-06 | EI13: 4804.4389 | EJ13: 2467.8707 | EK13: 2646.0792 | EL13: 4281.1086 | EM13: 3291.7738 | EN13: 2347.4692 | EO13: 1348 | EP13: 3775.3997 | EQ13: 2153.4231 | ER13: 3982.4866 | ES13: 5292.5189 | ET13: 1e-06 | EU13: 1e-06 | EV13: 5460.341 | EW13: 3757.4746 | EX13: 2567.1465 | EY13: 2896.0799 | EZ13: 3394.1555 | FA13: 8310.4358 | FB13: 6806.8682 | FC13: 5846.9809 | FD13: 1505.7308 | FE13: 7472.4071 | FF13: 6017.711 | FG13: 1924 | FH13: 1741 | FI13: 3914.0028 | FJ13: 2275.3914 | FK13: 7287.3967 | FL13: 2948.795 | FM13: 1825.0422 | FN13: 1325.5486 | FO13: 1e-06 | FP13: 2580.4874 | FQ13: 1459 | FR13: 1798 | FS13: 1e-06 | FT13: 1e-06 | FU13: 1e-06 | FV13: 1e-06 | FW13: 3021.2371 | FX13: 4017.8509 | FY13: 3567.9114 | FZ13: 4557.7314 | GA13: 3500.4548 | GB13: 3205.1374 | GC13: 2399.7398 | GD13: 1975.0256 | GE13: 2599.1661 | GF13: 1e-06 | GG13: 1e-06 | GH13: 1e-06 | GI13: 1e-06
A14: DG | B14: (1,3) DG 34:2 | C14: 575.50451 | D14: 2.5675 | E14: 0.0177 | F14: 1351 | G14: 4222.0863 | H14: 1750 | I14: 1110 | J14: 1349 | K14: 1e-06 | L14: 1e-06 | M14: 1610 | N14: 1e-06 | O14: 3297.3138 | P14: 2259 | Q14: 1931 | R14: 1e-06 | S14: 2649 | T14: 2494 | U14: 1961 | V14: 1270 | W14: 2637 | X14: 2714 | Y14: 1e-06 | Z14: 1e-06 | AA14: 1586 | AB14: 1397 | AC14: 1090 | AD14: 1849 | AE14: 2281 | AF14: 2244 | AG14: 4912.512 | AH14: 1e-06 | AI14: 3129.2427 | AJ14: 1e-06 | AK14: 1585 | AL14: 7290.2595 | AM14: 2344 | AN14: 2159 | AO14: 1968 | AP14: 1662 | AQ14: 3393 | AR14: 2854 | AS14: 4271.4718 | AT14: 3307 | AU14: 2781.1776 | AV14: 1704 | AW14: 2429 | AX14: 4055.2999 | AY14: 1596 | AZ14: 1212 | BA14: 3810 | BB14: 3659.6854 | BC14: 3230.704 | BD14: 1448 | BE14: 3509.896 | BF14: 2038 | BG14: 1418 | BH14: 4475 | BI14: 3900 | BJ14: 2593 | BK14: 1817 | BL14: 2128 | BM14: 2283 | BN14: 2176 | BO14: 2951.1019 | BP14: 1916 | BQ14: 4313.7503 | BR14: 4204.2007 | BS14: 2327 | BT14: 1e-06 | BU14: 1e-06 | BV14: 1175 | BW14: 1026 | BX14: 1393 | BY14: 2432 | BZ14: 1989 | CA14: 1e-06 | CB14: 2057 | CC14: 1665 | CD14: 4420.4795 | CE14: 1e-06 | CF14: 1e-06 | CG14: 2908 | CH14: 2937 | CI14: 4729.6095 | CJ14: 2451 | CK14: 1216 | CL14: 1010 | CM14: 1e-06 | CN14: 1e-06 | CO14: 1e-06 | CP14: 1711 | CQ14: 1e-06 | CR14: 1e-06 | CS14: 1249 | CT14: 3740.3805 | CU14: 2016 | CV14: 1e-06 | CW14: 3727.9099 | CX14: 5164.5135 | CY14: 1354 | CZ14: 1e-06 | DA14: 2261 | DB14: 1e-06 | DC14: 1e-06 | DD14: 1031 | DE14: 1080 | DF14: 2125 | DG14: 1e-06 | DH14: 1e-06 | DI14: 1e-06 | DJ14: 1433 | DK14: 1e-06 | DL14: 1278 | DM14: 3919.6406 | DN14: 2746 | DO14: 1460 | DP14: 1e-06 | DQ14: 1103 | DR14: 1e-06 | DS14: 1e-06 | DT14: 1136 | DU14: 1e-06 | DV14: 2074 | DW14: 1e-06 | DX14: 2899 | DY14: 3793 | DZ14: 1887 | EA14: 1e-06 | EB14: 1613 | EC14: 2792 | ED14: 1686 | EE14: 1e-06 | EF14: 2336 | EG14: 1748 | EH14: 1e-06 | EI14: 2674 | EJ14: 1062 | EK14: 1344 | EL14: 2808.8186 | EM14: 2561 | EN14: 2619 | EO14: 1e-06 | EP14: 2084 | EQ14: 1876 | ER14: 2422 | ES14: 4017.9919 | ET14: 1028 | EU14: 1e-06 | EV14: 3801.2597 | EW14: 3941.9392 | EX14: 1387 | EY14: 2831 | EZ14: 2032 | FA14: 4642.1312 | FB14: 4123.512 | FC14: 2515 | FD14: 1151 | FE14: 3724 | FF14: 3502 | FG14: 1e-06 | FH14: 1e-06 | FI14: 1979 | FJ14: 1603 | FK14: 3483.5678 | FL14: 1861 | FM14: 1246 | FN14: 1317 | FO14: 1e-06 | FP14: 1263 | FQ14: 1e-06 | FR14: 1e-06 | FS14: 1e-06 | FT14: 1e-06 | FU14: 1e-06 | FV14: 1e-06 | FW14: 2545 | FX14: 2090 | FY14: 1980 | FZ14: 2638 | GA14: 2149 | GB14: 2065 | GC14: 1796 | GD14: 1607 | GE14: 1682 | GF14: 1e-06 | GG14: 1e-06 | GH14: 1e-06 | GI14: 1e-06
... A131: SM | B131: SM 43:2,O2 | C131: 827.70236 | D131: 4.5946 | E131: 0.0265 | F131: 1081 | G131: 1e-06 | H131: 1e-06 | I131: 1e-06 | J131: 1e-06 | K131: 1e-06 | L131: 1e-06 | M131: 1e-06 | N131: 1e-06 | O131: 1089 | P131: 1e-06 | Q131: 1e-06 | R131: 1e-06 | S131: 1e-06 | T131: 1e-06 | U131: 1e-06 | V131: 1e-06 | W131: 1e-06 | X131: 1e-06 | Y131: 1e-06 | Z131: 1e-06 | AA131: 1e-06 | AB131: 1e-06 | AC131: 1e-06 | AD131: 1e-06 | AE131: 1e-06 | AF131: 1e-06 | AG131: 1e-06 | AH131: 1e-06 | AI131: 1e-06 | AJ131: 1e-06 | AK131: 1063 | AL131: 1e-06 | AM131: 1317 | AN131: 1e-06 | AO131: 1e-06 | AP131: 1e-06 | AQ131: 1e-06 | AR131: 1e-06 | AS131: 1178 | AT131: 1050 | AU131: 1e-06 | AV131: 1e-06 | AW131: 1e-06 | AX131: 1e-06 | AY131: 1e-06 | AZ131: 1e-06 | BA131: 1e-06 | BB131: 1e-06 | BC131: 2156 | BD131: 1e-06 | BE131: 1e-06 | BF131: 1e-06 | BG131: 1e-06 | BH131: 1e-06 | BI131: 1e-06 | BJ131: 1e-06 | BK131: 1e-06 | BL131: 1188 | BM131: 1297 | BN131: 2238 | BO131: 1741 | BP131: 1005 | BQ131: 1438 | BR131: 1e-06 | BS131: 1244 | BT131: 1193 | BU131: 1e-06 | BV131: 1e-06 | BW131: 1e-06 | BX131: 1e-06 | BY131: 1e-06 | BZ131: 1e-06 | CA131: 1e-06 | CB131: 1e-06 | CC131: 1e-06 | CD131: 1e-06 | CE131: 1e-06 | CF131: 1324 | CG131: 1e-06 | CH131: 1e-06 | CI131: 1219 | CJ131: 1e-06 | CK131: 1e-06 | CL131: 1e-06 | CM131: 1e-06 | CN131: 1e-06 | CO131: 1e-06 | CP131: 1e-06 | CQ131: 1e-06 | CR131: 1e-06 | CS131: 1e-06 | CT131: 1692 | CU131: 1372 | CV131: 1e-06 | CW131: 1091 | CX131: 1735 | CY131: 1e-06 | CZ131: 1e-06 | DA131: 1e-06 | DB131: 1e-06 | DC131: 1e-06 | DD131: 1e-06 | DE131: 1e-06 | DF131: 1e-06 | DG131: 1e-06 | DH131: 1e-06 | DI131: 1e-06 | DJ131: 1e-06 | DK131: 1e-06 | DL131: 1226 | DM131: 1024 | DN131: 1e-06 | DO131: 1e-06 | DP131: 1109 | DQ131: 1e-06 | DR131: 1e-06 | DS131: 1e-06 | DT131: 1e-06 | DU131: 1e-06 | DV131: 1e-06 | DW131: 1933 | DX131: 1e-06 | DY131: 1e-06 | DZ131: 1e-06 | EA131: 1682 | EB131: 1440 | EC131: 1e-06 | ED131: 1e-06 | EE131: 1e-06 | EF131: 1e-06 | EG131: 1e-06 | EH131: 1e-06 | EI131: 1326 | EJ131: 1e-06 | EK131: 2594 | EL131: 1100 | EM131: 1e-06 | EN131: 1451 | EO131: 2491 | EP131: 1013 | EQ131: 1e-06 | ER131: 1427 | ES131: 1087 | ET131: 1e-06 | EU131: 1537 | EV131: 1602 | EW131: 1043 | EX131: 1e-06 | EY131: 1404 | EZ131: 1242 | FA131: 1144 | FB131: 1310 | FC131: 1e-06 | FD131: 1e-06 | FE131: 1e-06 | FF131: 1e-06 | FG131: 1e-06 | FH131: 1e-06 | FI131: 1e-06 | FJ131: 1e-06 | FK131: 1e-06 | FL131: 1106 | FM131: 1e-06 | FN131: 1e-06 | FO131: 1e-06 | FP131: 1e-06 | FQ131: 1e-06 | FR131: 1e-06 | FS131: 1e-06 | FT131: 1e-06 | FU131: 1e-06 | FV131: 1e-06 | FW131: 1e-06 | FX131: 1e-06 | FY131: 1e-06 | FZ131: 1e-06 | GA131: 1e-06 | GB131: 1e-06 | GC131: 1e-06 | GD131: 1e-06 | GE131: 1e-06 | GF131: 1e-06 | GG131: 1e-06 | GH131: 1e-06 | GI131: 1e-06
A132: TG | B132: TG (17:0/17:1/17:0)D5 | C132: 869.8349 | F132: 18475.326 | G132: 8183.591 | H132: 3063.071 | I132: 5492.002 | J132: 1e-06 | K132: 6696.22 | L132: 8314.211 | M132: 24599.738 | N132: 3093.965 | O132: 17867.594 | P132: 14722.335 | Q132: 1e-06 | R132: 8577.061 | S132: 8241.817 | T132: 1e-06 | U132: 4810.037 | V132: 32201.607 | W132: 9162.266 | X132: 1e-06 | Y132: 6359.887 | Z132: 36275.211 | AA132: 1e-06 | AB132: 1e-06 | AC132: 1e-06 | AD132: 9460.413 | AE132: 3200.248 | AF132: 4575.847 | AG132: 10182.246 | AH132: 1e-06 | AI132: 7093.95 | AJ132: 3462.004 | AK132: 11607.652 | AL132: 7195.752 | AM132: 7868.652 | AN132: 1587.379 | AO132: 9622.116 | AP132: 6645.943 | AQ132: 1e-06 | AR132: 10782.571 | AS132: 1743.901 | AT132: 9943.472 | AU132: 16404.379 | AV132: 31036.668 | AW132: 1e-06 | AX132: 3473.201 | AY132: 11365.75 | AZ132: 3257.209 | BA132: 9327.024 | BB132: 8938.427 | BC132: 11759.991 | BD132: 18615.15 | BE132: 8108.602 | BF132: 1e-06 | BG132: 11547.309 | BH132: 1e-06 | BI132: 10084.541 | BJ132: 6435.249 | BK132: 1e-06 | BL132: 21714.648 | BM132: 14460.122 | BN132: 4758.494 | BO132: 17484.736 | BP132: 1e-06 | BQ132: 1e-06 | BR132: 6900.24 | BS132: 36724.727 | BT132: 1e-06 | BU132: 3273.471 | BV132: 6450.173 | BW132: 6814.012 | BX132: 1e-06 | BY132: 14977.562 | BZ132: 13609.848 | CA132: 1e-06 | CB132: 1e-06 | CC132: 11171.849 | CD132: 4856.746 | CE132: 1e-06 | CF132: 11515.706 | CG132: 1e-06 | CH132: 8137.521 | CI132: 9537.966 | CJ132: 9768.773 | CK132: 1e-06 | CL132: 6707.77 | CM132: 6105.587 | CN132: 5589.83 | CO132: 35272.578 | CP132: 14999.108 | CQ132: 1e-06 | CR132: 9606.62 | CS132: 1e-06 | CT132: 3299.479 | CU132: 16985.34 | CV132: 1e-06 | CW132: 1e-06 | CX132: 14585.838 | CY132: 1e-06 | CZ132: 1e-06 | DA132: 1e-06 | DB132: 4724.749 | DC132: 4593.542 | DD132: 22760.814 | DE132: 1e-06 | DF132: 6176.24 | DG132: 8853.355 | DH132: 6654.782 | DI132: 2983.358 | DJ132: 11672.288 | DK132: 14601.447 | DL132: 15799.191 | DM132: 6412.889 | DN132: 2547.667 | DO132: 1e-06 | DP132: 1e-06 | DQ132: 8010.546 | DR132: 1e-06 | DS132: 1e-06 | DT132: 1e-06 | DU132: 1e-06 | DV132: 1e-06 | DW132: 14459.919 | DX132: 1768.383 | DY132: 7684.712 | DZ132: 1e-06 | EA132: 26724.732 | EB132: 12014.514 | EC132: 1e-06 | ED132: 12288.02 | EE132: 4578.975 | EF132: 11505.01 | EG132: 3908.351 | EH132: 7491.21 | EI132: 11420.203 | EJ132: 11113.864 | EK132: 1e-06 | EL132: 14222.394 | EM132: 1e-06 | EN132: 1e-06 | EO132: 11386.103 | EP132: 14647.2 | EQ132: 12947.953 | ER132: 12292.655 | ES132: 1e-06 | ET132: 3163.152 | EU132: 20511.215 | EV132: 1e-06 | EW132: 18499.135 | EX132: 13930.077 | EY132: 13421.971 | EZ132: 1e-06 | FA132: 6587.215 | FB132: 6844.604 | FC132: 12269.393 | FD132: 1e-06 | FE132: 3661.139 | FF132: 12192.277 | FG132: 6436.246 | FH132: 7360.231 | FI132: 1e-06 | FJ132: 1590.047 | FK132: 1e-06 | FL132: 21007.135 | FM132: 1e-06 | FN132: 20927.209 | FO132: 1e-06 | FP132: 21396.75 | FQ132: 1e-06 | FR132: 3152.611 | FS132: 57960.137 | FT132: 1e-06 | FU132: 1e-06 | FV132: 1e-06 | FW132: 1e-06 | FX132: 6526.13 | FY132: 7504.144 | FZ132: 7352.538 | GA132: 6663.733 | GB132: 6073.073 | GC132: 3932.668 | GD132: 4754.803 | GE132: 5539.59 | GF132: 5022.188 | GG132: 1e-06 | GH132: 1e-06 | GI132: 37890.629
A133: TG | B133: TG 42:1 | C133: 738.6606 | F133: 1e-06 | G133: 1e-06 | H133: 1822.333 | I133: 1e-06 | J133: 1e-06 | K133: 1e-06 | L133: 1e-06 | M133: 1633.423 | N133: 1e-06 | O133: 1e-06 | P133: 1e-06 | Q133: 1e-06 | R133: 1e-06 | S133: 1e-06 | T133: 1e-06 | U133: 1e-06 | V133: 1e-06 | W133: 1e-06 | X133: 1e-06 | Y133: 1e-06 | Z133: 1e-06 | AA133: 1e-06 | AB133: 1e-06 | AC133: 1e-06 | AD133: 1e-06 | AE133: 1e-06 | AF133: 3850.377 | AG133: 1360.569 | AH133: 1e-06 | AI133: 1383.188 | AJ133: 1e-06 | AK133: 1e-06 | AL133: 1e-06 | AM133: 2655.619 | AN133: 3209.711 | AO133: 1e-06 | AP133: 1e-06 | AQ133: 3231.503 | AR133: 1e-06 | AS133: 1455.101 | AT133: 1e-06 | AU133: 1e-06 | AV133: 1e-06 | AW133: 1e-06 | AX133: 1344.967 | AY133: 2649.25 | AZ133: 1e-06 | BA133: 1e-06 | BB133: 1655.232 | BC133: 1e-06 | BD133: 1e-06 | BE133: 1e-06 | BF133: 1e-06 | BG133: 1e-06 | BH133: 1e-06 | BI133: 1e-06 | BJ133: 1190.889 | BK133: 1e-06 | BL133: 1e-06 | BM133: 1e-06 | BN133: 1e-06 | BO133: 1e-06 | BP133: 1e-06 | BQ133: 1e-06 | BR133: 1588.855 | BS133: 1e-06 | BT133: 1e-06 | BU133: 1e-06 | BV133: 1e-06 | BW133: 1e-06 | BX133: 1e-06 | BY133: 1e-06 | BZ133: 1e-06 | CA133: 1e-06 | CB133: 1e-06 | CC133: 1e-06 | CD133: 1e-06 | CE133: 1e-06 | CF133: 1e-06 | CG133: 1e-06 | CH133: 1e-06 | CI133: 1052.112 | CJ133: 1e-06 | CK133: 1e-06 | CL133: 1e-06 | CM133: 1e-06 | CN133: 1e-06 | CO133: 1e-06 | CP133: 1074.481 | CQ133: 1e-06 | CR133: 1e-06 | CS133: 1e-06 | CT133: 1039.456 | CU133: 1029.421 | CV133: 1e-06 | CW133: 1e-06 | CX133: 1e-06 | CY133: 1e-06 | CZ133: 1e-06 | DA133: 1e-06 | DB133: 1e-06 | DC133: 1e-06 | DD133: 1e-06 | DE133: 1e-06 | DF133: 1e-06 | DG133: 1e-06 | DH133: 1e-06 | DI133: 1e-06 | DJ133: 1197.062 | DK133: 1e-06 | DL133: 1e-06 | DM133: 1e-06 | DN133: 1008.155 | DO133: 1e-06 | DP133: 1e-06 | DQ133: 1e-06 | DR133: 1e-06 | DS133: 1e-06 | DT133: 1e-06 | DU133: 1e-06 | DV133: 1e-06 | DW133: 1e-06 | DX133: 1e-06 | DY133: 1e-06 | DZ133: 1e-06 | EA133: 1e-06 | EB133: 1e-06 | EC133: 1e-06 | ED133: 1e-06 | EE133: 1e-06 | EF133: 1e-06 | EG133: 1e-06 | EH133: 1e-06 | EI133: 1e-06 | EJ133: 1e-06 | EK133: 3055.154 | EL133: 1314.12 | EM133: 1e-06 | EN133: 1e-06 | EO133: 1e-06 | EP133: 1e-06 | EQ133: 1e-06 | ER133: 1e-06 | ES133: 1e-06 | ET133: 1e-06 | EU133: 1e-06 | EV133: 1e-06 | EW133: 1e-06 | EX133: 1e-06 | EY133: 1e-06 | EZ133: 1e-06 | FA133: 1e-06 | FB133: 1884.645 | FC133: 1e-06 | FD133: 1e-06 | FE133: 1e-06 | FF133: 1e-06 | FG133: 1e-06 | FH133: 1e-06 | FI133: 1e-06 | FJ133: 1e-06 | FK133: 1e-06 | FL133: 1e-06 | FM133: 1e-06 | FN133: 1e-06 | FO133: 1e-06 | FP133: 1e-06 | FQ133: 1e-06 | FR133: 1e-06 | FS133: 1e-06 | FT133: 1e-06 | FU133: 1e-06 | FV133: 1e-06 | FW133: 1e-06 | FX133: 1e-06 | FY133: 1e-06 | FZ133: 1e-06 | GA133: 1e-06 | GB133: 1e-06 | GC133: 1e-06 | GD133: 1e-06 | GE133: 1e-06 | GF133: 1e-06 | GG133: 1e-06 | GH133: 1e-06 | GI133: 1e-06
A134: TG | B134: TG 44:0 | C134: 768.7076 | F134: 1e-06 | G134: 1e-06 | H134: 6521.432 | I134: 1e-06 | J134: 1e-06 | K134: 1e-06 | L134: 1e-06 | M134: 3060.8757 | N134: 1e-06 | O134: 1e-06 | P134: 1468.1533 | Q134: 1e-06 | R134: 1e-06 | S134: 1e-06 | T134: 1e-06 | U134: 1266.887 | V134: 1e-06 | W134: 1e-06 | X134: 1252.751 | Y134: 1e-06 | Z134: 1e-06 | AA134: 1e-06 | AB134: 1e-06 | AC134: 1e-06 | AD134: 1e-06 | AE134: 1e-06 | AF134: 11687.864 | AG134: 4921.062 | AH134: 1e-06 | AI134: 4994.9572 | AJ134: 1e-06 | AK134: 4808.067 | AL134: 1736.741 | AM134: 1802.3436 | AN134: 3432.528 | AO134: 1244.138 | AP134: 1e-06 | AQ134: 3941.7418 | AR134: 2287.7236 | AS134: 4602.4893 | AT134: 5043.496 | AU134: 1e-06 | AV134: 1e-06 | AW134: 1e-06 | AX134: 3692.1944 | AY134: 7553.2306 | AZ134: 1e-06 | BA134: 1e-06 | BB134: 5484.1506 | BC134: 1e-06 | BD134: 1e-06 | BE134: 1e-06 | BF134: 1e-06 | BG134: 1e-06 | BH134: 1e-06 | BI134: 3349.482 | BJ134: 2682.0546 | BK134: 2034.903 | BL134: 1e-06 | BM134: 1e-06 | BN134: 1e-06 | BO134: 1951.046 | BP134: 1e-06 | BQ134: 1e-06 | BR134: 9519.3142 | BS134: 1e-06 | BT134: 1e-06 | BU134: 1e-06 | BV134: 2867.9861 | BW134: 1e-06 | BX134: 1e-06 | BY134: 1e-06 | BZ134: 1119.657 | CA134: 1e-06 | CB134: 1e-06 | CC134: 1e-06 | CD134: 1e-06 | CE134: 1e-06 | CF134: 1e-06 | CG134: 1e-06 | CH134: 1139.361 | CI134: 2820.6981 | CJ134: 1e-06 | CK134: 1e-06 | CL134: 1e-06 | CM134: 1e-06 | CN134: 1e-06 | CO134: 1e-06 | CP134: 2019.3835 | CQ134: 1e-06 | CR134: 1e-06 | CS134: 1e-06 | CT134: 2044.182 | CU134: 4622.592 | CV134: 1e-06 | CW134: 1e-06 | CX134: 1e-06 | CY134: 1e-06 | CZ134: 1e-06 | DA134: 1e-06 | DB134: 1e-06 | DC134: 1e-06 | DD134: 1e-06 | DE134: 1e-06 | DF134: 1e-06 | DG134: 1e-06 | DH134: 1e-06 | DI134: 1e-06 | DJ134: 3261.665 | DK134: 1e-06 | DL134: 1e-06 | DM134: 1e-06 | DN134: 1817.511 | DO134: 1e-06 | DP134: 1e-06 | DQ134: 1e-06 | DR134: 1e-06 | DS134: 1e-06 | DT134: 1e-06 | DU134: 1e-06 | DV134: 1e-06 | DW134: 1e-06 | DX134: 1e-06 | DY134: 8340.8627 | DZ134: 1e-06 | EA134: 1e-06 | EB134: 1e-06 | EC134: 1e-06 | ED134: 1e-06 | EE134: 1e-06 | EF134: 1e-06 | EG134: 1e-06 | EH134: 1e-06 | EI134: 1e-06 | EJ134: 1e-06 | EK134: 4478.763 | EL134: 7199.9898 | EM134: 1e-06 | EN134: 1e-06 | EO134: 1e-06 | EP134: 1e-06 | EQ134: 1e-06 | ER134: 1e-06 | ES134: 1e-06 | ET134: 1e-06 | EU134: 1e-06 | EV134: 1e-06 | EW134: 1339.107 | EX134: 1e-06 | EY134: 1e-06 | EZ134: 1e-06 | FA134: 2174.945 | FB134: 5322.6838 | FC134: 1e-06 | FD134: 1e-06 | FE134: 1e-06 | FF134: 1e-06 | FG134: 1e-06 | FH134: 1e-06 | FI134: 1455.759 | FJ134: 1011.415 | FK134: 1e-06 | FL134: 1e-06 | FM134: 1e-06 | FN134: 1e-06 | FO134: 1e-06 | FP134: 2120.5968 | FQ134: 1e-06 | FR134: 1e-06 | FS134: 1e-06 | FT134: 1e-06 | FU134: 1e-06 | FV134: 1e-06 | FW134: 1e-06 | FX134: 1099.6315 | FY134: 1e-06 | FZ134: 1e-06 | GA134: 1e-06 | GB134: 1e-06 | GC134: 1e-06 | GD134: 1e-06 | GE134: 1e-06 | GF134: 1e-06 | GG134: 1e-06 | GH134: 1e-06 | GI134: 1e-06
A135: TG | B135: TG 44:1 | C135: 766.6919 | F135: 1e-06 | G135: 1e-06 | H135: 1e-06 | I135: 1e-06 | J135: 1e-06 | K135: 1e-06 | L135: 1e-06 | M135: 2590.498 | N135: 1e-06 | O135: 1e-06 | P135: 1362.18 | Q135: 1e-06 | R135: 1e-06 | S135: 1e-06 | T135: 1e-06 | U135: 1e-06 | V135: 1e-06 | W135: 1e-06 | X135: 1e-06 | Y135: 1e-06 | Z135: 1e-06 | AA135: 1e-06 | AB135: 1e-06 | AC135: 1e-06 | AD135: 1e-06 | AE135: 1e-06 | AF135: 1e-06 | AG135: 1e-06 | AH135: 1e-06 | AI135: 4030.97 | AJ135: 1e-06 | AK135: 1e-06 | AL135: 1e-06 | AM135: 3006.497 | AN135: 1e-06 | AO135: 1e-06 | AP135: 1e-06 | AQ135: 4129.738 | AR135: 1907.271 | AS135: 2714.809 | AT135: 1e-06 | AU135: 1e-06 | AV135: 1e-06 | AW135: 1e-06 | AX135: 5604.07 | AY135: 4919.745 | AZ135: 1e-06 | BA135: 1e-06 | BB135: 6140.4 | BC135: 1e-06 | BD135: 1e-06 | BE135: 1e-06 | BF135: 1e-06 | BG135: 1e-06 | BH135: 1e-06 | BI135: 1e-06 | BJ135: 2472.732 | BK135: 1e-06 | BL135: 1e-06 | BM135: 1e-06 | BN135: 1e-06 | BO135: 1e-06 | BP135: 1e-06 | BQ135: 1e-06 | BR135: 9540.093 | BS135: 1e-06 | BT135: 1e-06 | BU135: 1e-06 | BV135: 1758.2 | BW135: 1e-06 | BX135: 1e-06 | BY135: 1e-06 | BZ135: 1e-06 | CA135: 1e-06 | CB135: 1e-06 | CC135: 1e-06 | CD135: 1e-06 | CE135: 1e-06 | CF135: 1e-06 | CG135: 1e-06 | CH135: 1e-06 | CI135: 3847.404 | CJ135: 1e-06 | CK135: 1e-06 | CL135: 1e-06 | CM135: 1e-06 | CN135: 1e-06 | CO135: 1e-06 | CP135: 1864.809 | CQ135: 1e-06 | CR135: 1e-06 | CS135: 1e-06 | CT135: 1e-06 | CU135: 1e-06 | CV135: 1e-06 | CW135: 1e-06 | CX135: 1e-06 | CY135: 1e-06 | CZ135: 1e-06 | DA135: 1e-06 | DB135: 1e-06 | DC135: 1e-06 | DD135: 1e-06 | DE135: 1e-06 | DF135: 1e-06 | DG135: 1e-06 | DH135: 1e-06 | DI135: 1e-06 | DJ135: 1e-06 | DK135: 1e-06 | DL135: 1e-06 | DM135: 1e-06 | DN135: 1e-06 | DO135: 1e-06 | DP135: 1e-06 | DQ135: 1e-06 | DR135: 1e-06 | DS135: 1e-06 | DT135: 1e-06 | DU135: 1e-06 | DV135: 1e-06 | DW135: 1e-06 | DX135: 1e-06 | DY135: 5060.556 | DZ135: 1e-06 | EA135: 1e-06 | EB135: 1e-06 | EC135: 1e-06 | ED135: 1e-06 | EE135: 1e-06 | EF135: 1e-06 | EG135: 1e-06 | EH135: 1e-06 | EI135: 1e-06 | EJ135: 1e-06 | EK135: 1e-06 | EL135: 5425.579 | EM135: 1e-06 | EN135: 1e-06 | EO135: 1e-06 | EP135: 1e-06 | EQ135: 1e-06 | ER135: 1e-06 | ES135: 1e-06 | ET135: 1e-06 | EU135: 1e-06 | EV135: 1e-06 | EW135: 1e-06 | EX135: 1e-06 | EY135: 1e-06 | EZ135: 1e-06 | FA135: 2121.705 | FB135: 3429.133 | FC135: 1e-06 | FD135: 1e-06 | FE135: 1e-06 | FF135: 1e-06 | FG135: 1e-06 | FH135: 1e-06 | FI135: 1e-06 | FJ135: 1e-06 | FK135: 1e-06 | FL135: 1e-06 | FM135: 1e-06 | FN135: 1e-06 | FO135: 1e-06 | FP135: 1083.702 | FQ135: 1e-06 | FR135: 1e-06 | FS135: 1e-06 | FT135: 1e-06 | FU135: 1e-06 | FV135: 1e-06 | FW135: 1e-06 | FX135: 1084.925 | FY135: 1e-06 | FZ135: 1e-06 | GA135: 1e-06 | GB135: 1e-06 | GC135: 1e-06 | GD135: 1e-06 | GE135: 1e-06 | GF135: 1e-06 | GG135: 1e-06 | GH135: 1e-06 | GI135: 1e-06
A136: TG | B136: TG 46:0 | C136: 796.7389 | F136: 1e-06 | G136: 843.40454 | H136: 2643.1895 | I136: 1e-06 | J136: 1e-06 | K136: 1e-06 | L136: 1782.865 | M136: 2456.7031 | N136: 1e-06 | O136: 1236.1479 | P136: 4356.5427 | Q136: 1e-06 | R136: 1e-06 | S136: 1e-06 | T136: 1e-06 | U136: 1e-06 | V136: 1e-06 | W136: 1e-06 | X136: 1716.3999 | Y136: 1e-06 | Z136: 1e-06 | AA136: 1e-06 | AB136: 1252.5274 | AC136: 1e-06 | AD136: 1e-06 | AE136: 1e-06 | AF136: 5461.4775 | AG136: 281.2913 | AH136: 1e-06 | AI136: 2533.6116 | AJ136: 1e-06 | AK136: 2467.9574 | AL136: 1817.4332 | AM136: 1314.3546 | AN136: 1414.5013 | AO136: 1213.0609 | AP136: 1e-06 | AQ136: 920.61657 | AR136: 2040.6433 | AS136: 1691.8399 | AT136: 191.17989 | AU136: 1246.4245 | AV136: 1e-06 | AW136: 1e-06 | AX136: 5357.7546 | AY136: 3292.3829 | AZ136: 1e-06 | BA136: 1e-06 | BB136: 2464.8769 | BC136: 1e-06 | BD136: 1e-06 | BE136: 1e-06 | BF136: 1e-06 | BG136: 699.77352 | BH136: 1e-06 | BI136: 496.54285 | BJ136: 3660.2882 | BK136: 779.02319 | BL136: 1e-06 | BM136: 1262.6819 | BN136: 1848.9297 | BO136: 1040.5239 | BP136: 1e-06 | BQ136: 850.50543 | BR136: 7227.4035 | BS136: 785.20449 | BT136: 1e-06 | BU136: 1e-06 | BV136: 2813.1496 | BW136: 1e-06 | BX136: 1e-06 | BY136: 1e-06 | BZ136: 1e-06 | CA136: 1e-06 | CB136: 1e-06 | CC136: 1e-06 | CD136: 1436.6603 | CE136: 1e-06 | CF136: 1e-06 | CG136: 1e-06 | CH136: 1334.6968 | CI136: 3800.3375 | CJ136: 1e-06 | CK136: 1e-06 | CL136: 1e-06 | CM136: 1e-06 | CN136: 1e-06 | CO136: 1e-06 | CP136: 1175.8134 | CQ136: 1e-06 | CR136: 1e-06 | CS136: 1e-06 | CT136: 1102.6911 | CU136: 1031.4142 | CV136: 1e-06 | CW136: 1e-06 | CX136: 1852.3581 | CY136: 1e-06 | CZ136: 1e-06 | DA136: 812.51351 | DB136: 1118.9424 | DC136: 1e-06 | DD136: 1e-06 | DE136: 1e-06 | DF136: 1639.4528 | DG136: 1e-06 | DH136: 1e-06 | DI136: 1e-06 | DJ136: 2154.9948 | DK136: 1e-06 | DL136: 1e-06 | DM136: 1e-06 | DN136: 2537.3882 | DO136: 1e-06 | DP136: 1e-06 | DQ136: 1e-06 | DR136: 1e-06 | DS136: 1e-06 | DT136: 1e-06 | DU136: 1e-06 | DV136: 1578.7592 | DW136: 1e-06 | DX136: 1e-06 | DY136: 4793.6003 | DZ136: 1e-06 | EA136: 1e-06 | EB136: 1e-06 | EC136: 1e-06 | ED136: 1e-06 | EE136: 1e-06 | EF136: 1e-06 | EG136: 1e-06 | EH136: 1e-06 | EI136: 1e-06 | EJ136: 1e-06 | EK136: 3378.676 | EL136: 4651.2942 | EM136: 1e-06 | EN136: 1156.6446 | EO136: 1e-06 | EP136: 1e-06 | EQ136: 1e-06 | ER136: 1e-06 | ES136: 1e-06 | ET136: 1e-06 | EU136: 1e-06 | EV136: 1e-06 | EW136: 1352.688 | EX136: 1294.6493 | EY136: 1e-06 | EZ136: 1e-06 | FA136: 2389.2872 | FB136: 3960.7357 | FC136: 1e-06 | FD136: 1e-06 | FE136: 817.6553 | FF136: 1e-06 | FG136: 1e-06 | FH136: 1066.885 | FI136: 962.29855 | FJ136: 1031.0951 | FK136: 1e-06 | FL136: 1e-06 | FM136: 1e-06 | FN136: 1e-06 | FO136: 1e-06 | FP136: 1296.0229 | FQ136: 1e-06 | FR136: 1e-06 | FS136: 1e-06 | FT136: 1e-06 | FU136: 1e-06 | FV136: 1e-06 | FW136: 1e-06 | FX136: 1223.7115 | FY136: 1e-06 | FZ136: 873.57281 | GA136: 1e-06 | GB136: 847.9517 | GC136: 1e-06 | GD136: 1e-06 | GE136: 1e-06 | GF136: 1e-06 | GG136: 1e-06 | GH136: 1e-06 | GI136: 1e-06
